Workbook

Sheet 안내
A1: QA 담양 중대재해 — 작업환경·건강 · 남다슬
A3: 메뉴 | B3: 작업환경·건강 (훑어보는 파일)
A4: 담당자 | B4: 남다슬
A5: 내 계정 | B5: QA박안전2 (재난안전과 담당자) · QA하정수2 (내 부서 건설과 담당 공무원)
A6: 이 파일 | B6: 작업환경측정과 건강검진을 봅니다. QA박안전2 계정은 모든 부서를 보고, QA하정수2 계정은 내 부서 것만 보고 등록합니다.
A7: 줄 수 | B7: 13줄
A8: 시트 | B8: 작업환경측정 → 건강검진
A9: 테스트 주소 | B9: https://safety.damyang.go.kr/login
A10: 브라우저
A11: 기기
A12: 시작한 날
A14: 이렇게 하면 됩니다
A15: ① 위 «테스트 주소»에서 받은 아이디·비밀번호로 로그인합니다. 로그인하면 통합 현황 화면으로 갑니다. 5번 틀리면 계정이 잠깁니다 — 담당 개발자에게 풀어 달라고 합니다.
A16: ② 내 계정 두 개를 창 두 개에 따로 로그인해 둡니다 — 일반 창에는 QA박안전2(재난안전과), 시크릿 창(Ctrl + Shift + N · 맥 Cmd + Shift + N)에는 QA하정수2(담당 공무원). 두 창을 나란히 두면 계정을 바꿀 필요가 없습니다.
A17: ③ «누구로» 칸에 적힌 계정의 창에서 «어디서» 메뉴로 가서 «해 볼 것»대로 눌러 봅니다.
A18: ④ «이러면 성공»과 같으면 «결과» 칸에서 성공을, 다르면 실패·오류 등을 고릅니다.
A19: ⑤ 실패·오류·문의면 «메모»에 한 줄 적고, 필요하면 «사진» 칸에 화면 캡처를 붙여넣습니다.
A21: 결과 고르는 법
A22: 결과 | B22: 이럴 때 고르세요
A23: 성공 | B23: «이러면 성공»대로 된다
A24: 실패 | B24: 되긴 하는데 설명과 다르다 — 막혀야 하는데 저장된다, 문구·숫자가 틀리다
A25: 오류 | B25: 화면이 멈추거나 깨진다, 눌러도 아무 일이 없다, 오류 창이 뜬다
A26: 보류 | B26: 앞 단계가 안 돼서 지금은 못 한다 — 메모에 이유
A27: 확인 불가 | B27: 이 환경에서는 볼 수 없다 — 예: 확인할 데이터가 없다
A28: 문의 | B28: 맞는지 헷갈린다 — 메모에 궁금한 점
A30: 사진 붙이는 법
A31: • 윈도우: Win + Shift + S → 영역 선택 → 엑셀에서 그 줄의 «사진» 칸을 누르고 Ctrl + V
A32: • 맥: Cmd + Ctrl + Shift + 4 → 영역 선택 → 엑셀에서 그 줄의 «사진» 칸을 누르고 Cmd + V
A33: • 사진이 크면 모서리를 끌어 줄이세요. 사진은 그 줄 «사진» 칸 위에 두면 됩니다 — 취합할 때 줄 번호로 찾습니다.
A34: • 사진은 떠 있는 그대로 두세요(«셀에 배치»로 넣으면 취합할 때 꺼내지 못합니다).
A36: 누구로 — 내 계정 두 개
A37: • 계정은 두 개뿐입니다. «누구로» 칸에 계정 이름과 권한이 함께 적혀 있습니다. 비밀번호는 따로 받습니다.
A38: 이름 | B38: 권한 | D38: 볼 수 있는 것 | F38: 주로 하는 것
A39: QA박안전2 | B39: 재난안전과 담당자 | D39: 모든 부서 · «내 할일»은 전체 | F39: 전 부서 등록·수정 · 확인 · 상신 · 독촉 — 대부분 이 계정
A40: QA하정수2 | B40: 담당 공무원 (내 부서: 건설과) | D40: 업무 화면은 전 부서, «내 할일»은 나에게 지정된 것만, 위험성평가 부서별 조치표·교육 이수현황은 내 부서만 | F40: 내 부서 일 · 남의 부서 것을 못 건드리는지 확인
A41: QA시스템관리 | B41: 시스템 관리자 (김유석만) | D41: 시스템 관리 메뉴 | F41: 시스템 관리 파일 · 공문 반려(결재 대행)
A43: 같은 서버를 6명이 함께 씁니다
A44: • 내가 만드는 것(교육 · 근로자 · 문서 · 위원 등)은 이름 앞에 내 이름을 붙입니다 — 예: «남다슬_집합교육». 그래야 내 것을 찾기 쉽습니다.
A45: • 다른 사람이 만든 것은 고치거나 지우지 않습니다. QA박안전2 계정에는 남의 것도 보이는데, 정상입니다.
A46: • 건수·이수율 같은 숫자는 다른 사람이 작업하는 동안 바뀔 수 있습니다. 숫자가 안 맞으면 새로고침해서 한 번 더 보고, 그래도 다르면 «실패».
...

Sheet 요약
A1: 진행 상황 — 작업환경·건강 · 남다슬
A2: 결과를 고르면 저절로 채워집니다. 남은 것 = 아직 결과를 고르지 않은 줄입니다.
A4: 시트 | B4: 전체 | C4: 성공 | D4: 실패 | E4: 오류 | F4: 보류 | G4: 확인 불가 | H4: 문의 | I4: 남은 것 | J4: 진행률
A5: 작업환경측정 | B5: =COUNTA('작업환경측정'!$A$4:$A$10) -> 7 | C5: =COUNTIF('작업환경측정'!$G$4:$G$10,"성공") -> 0 | D5: =COUNTIF('작업환경측정'!$G$4:$G$10,"실패") -> 0 | E5: =COUNTIF('작업환경측정'!$G$4:$G$10,"오류") -> 0 | F5: =COUNTIF('작업환경측정'!$G$4:$G$10,"보류") -> 0 | G5: =COUNTIF('작업환경측정'!$G$4:$G$10,"확인 불가") -> 0 | H5: =COUNTIF('작업환경측정'!$G$4:$G$10,"문의") -> 0 | I5: =COUNTBLANK('작업환경측정'!$G$4:$G$10) -> 7 | J5: =IF(B5=0,0,(B5-I5)/B5) -> 0
A6: 건강검진 | B6: =COUNTA('건강검진'!$A$4:$A$9) -> 6 | C6: =COUNTIF('건강검진'!$G$4:$G$9,"성공") -> 0 | D6: =COUNTIF('건강검진'!$G$4:$G$9,"실패") -> 0 | E6: =COUNTIF('건강검진'!$G$4:$G$9,"오류") -> 0 | F6: =COUNTIF('건강검진'!$G$4:$G$9,"보류") -> 0 | G6: =COUNTIF('건강검진'!$G$4:$G$9,"확인 불가") -> 0 | H6: =COUNTIF('건강검진'!$G$4:$G$9,"문의") -> 0 | I6: =COUNTBLANK('건강검진'!$G$4:$G$9) -> 6 | J6: =IF(B6=0,0,(B6-I6)/B6) -> 0
A7: 합계 | B7: =SUM(B5:B6) -> 13 | C7: =SUM(C5:C6) -> 0 | D7: =SUM(D5:D6) -> 0 | E7: =SUM(E5:E6) -> 0 | F7: =SUM(F5:F6) -> 0 | G7: =SUM(G5:G6) -> 0 | H7: =SUM(H5:H6) -> 0 | I7: =SUM(I5:I6) -> 13 | J7: =IF(B7=0,0,(B7-I7)/B7) -> 0

Sheet 작업환경측정
A1: 작업환경·건강 — 작업환경측정
A2: 🗂 주로 QA박안전2 창에서 합니다. 내가 만드는 측정 계획은 측정 대상을 «남다슬_…»로 쓰고, 첨부 같은 조작은 내가 만든 계획에만 합니다.
A3: 번호 | B3: 누구로 | C3: 어디서 | D3: 확인할 것 | E3: 해 볼 것 | F3: 이러면 성공 | G3: 결과 ▼ | H3: 메모 (실패·오류·문의일 때) | I3: 사진 (필요할 때 붙여넣기)
A4: 1 | B4: QA박안전2(재난안전과) | C4: 작업환경·건강 > 작업환경측정 | D4: 화면과 숫자 카드 | E4: ① 숫자 카드(전체 대상 · 측정 완료 · 미실시 · 개선 필요 · 기한 초과)를 하나씩 누른다 ② 같은 카드를 한 번 더 누른다 ③ 기준연도 · 반기 · 부서 조건을 바꿔 본다 | F4: 카드를 누르면 그 상태 줄만 남고 줄 수가 카드 숫자와 같다. 한 번 더 누르면 풀린다. 조건을 바꾸면 카드 숫자도 따라 바뀐다
A5: 2 | B5: QA박안전2(재난안전과) | C5: 작업환경·건강 > 작업환경측정 | D5: 측정 계획 등록 | E5: ① 새로고침해 조건을 처음 상태(올해 · 전체)로 돌린다 ② [＋ 측정 계획 등록] → 빈 채로 [등록] ③ [조직도]로 내 부서(건설과)를 고르고 사업장을 고른다(«등록된 사업장 없음…»이면 사업장이 있는 다른 부서를 고른다) ④ 측정 대상을 «남다슬_소음»으로 고쳐 쓰고 측정 예정일을 오늘부터 7일 뒤로 → [등록] ⑤ 같은 내용으로 한 번 더 등록해 본다 | F5: 빈 채로는 «대상 부서를 선택하세요.» 등록하면 «측정 계획이 등록되었습니다.»와 함께 목록에 «남다슬_소음» 줄이 생긴다. 같은 내용은 «같은 반기·사업장·유해인자의 측정계획이 이미 있습니다.»로 막힌다
A6: 3 | B6: QA박안전2(재난안전과) | C6: 작업환경·건강 > 작업환경측정 | D6: 상세와 결과보고서 등록 | E6: ① 2번의 «남다슬_소음» 줄을 눌러 상세를 연다 ② [증빙 등록] → 파일을 올린다(«…연계 후 제공됩니다»가 뜨면 넘어간다) → [등록] | F6: «증빙이 등록되었습니다.» 뒤 «용역 결과보고서»에 «위탁업체 결과보고서가 등록되어 있습니다.»가 보이고, «요청 · 변경 이력»에 «결과보고서 등록»이 내 QA박안전2 계정 이름으로 남는다. 목록의 결과보고서 칸은 «첨부됨»이다. 아무것도 안 남으면 «실패»
A7: 4 | B7: QA하정수2(담당 공무원) → QA박안전2(재난안전과) | C7: 작업환경·건강 > 작업환경측정 | D7: QA하정수2 계정에는 내 부서만 | E7: ① QA하정수2 창에서 목록과 부서 조건 드롭다운을 본다 ② QA박안전2 창에서 같은 화면을 본다 | F7: QA하정수2 계정에는 내 부서 줄만 있고(없으면 빈 목록) 부서 조건에도 내 부서 말고는 없다. QA박안전2 계정에는 다른 부서 줄도 보인다
A8: 5 | B8: QA하정수2(담당 공무원) | C8: 작업환경·건강 > 작업환경측정 | D8: QA하정수2 계정도 내 부서 계획을 등록한다 | E8: ① [＋ 측정 계획 등록] ② [조직도]로 내 부서를 고르고 사업장을 고른다 ③ 측정 대상을 «남다슬_분진»으로 고쳐 쓰고 측정 예정일을 오늘부터 7일 뒤로 → [등록] ④ 새 줄을 눌러 상세를 연다 | F8: 등록 버튼이 있고, 등록하면 목록에 «남다슬_분진» 줄이 생긴다. 상세에 [측정 완료 처리] · [증빙 등록]이 있고, «요청 · 변경 이력»의 «측정 계획 등록 (예정일 …)» 줄이 QA하정수2 계정 이름으로 남는다. 내 부서에 사업장이 없으면 «확인 불가»
A9: 6 | B9: QA하정수2(담당 공무원) | C9: 작업환경·건강 > 작업환경측정 | D9: 남의 부서 이름으로는 등록 못 한다 | E9: ① [＋ 측정 계획 등록] ② 대상 부서 칸과 [조직도]를 본다 ③ [조직도]에서 내 부서가 아닌 부서를 골라 사업장 · 측정 대상 «남다슬_남의부서»로 [등록]을 눌러 본다 | F9: 부서 칸이 내 부서로 고정돼 있거나, 남의 부서를 고르면 등록이 막힌다. 등록되면 «실패»(내 목록에 안 보이면 QA박안전2 창에서 «남다슬_남의부서»를 찾아 메모에 적는다)
A10: 7 | B10: QA박안전2(재난안전과) → QA하정수2(담당 공무원) | C10: 작업환경·건강 > 작업환경측정 | D10: 남의 부서 건은 주소로도 못 연다 | E10: ① QA박안전2 창에서 부서가 내 부서(건설과)와 다른 줄을 눌러 상세를 열고 주소창의 주소를 복사한다 ② QA하정수2 창 주소창에 붙여넣고 연다 | F10: «조회 범위 밖입니다 — 소속 부서 건만 볼 수 있습니다.»만 보이고 그 건의 내용은 보이지 않는다

Sheet 건강검진
A1: 작업환경·건강 — 건강검진
A2: 🗂 주로 QA박안전2 창에서 합니다. 내가 만드는 검진 계획은 위탁 검진기관을 «남다슬_…»로 쓰고, 첨부는 내가 만든 계획에만 합니다. 건강검진은 개인정보라 QA하정수2 계정에는 내 부서 것만 보여야 합니다.
A3: 번호 | B3: 누구로 | C3: 어디서 | D3: 확인할 것 | E3: 해 볼 것 | F3: 이러면 성공 | G3: 결과 ▼ | H3: 메모 (실패·오류·문의일 때) | I3: 사진 (필요할 때 붙여넣기)
A4: 8 | B4: QA박안전2(재난안전과) | C4: 작업환경·건강 > 건강검진 (일반·특수) | D4: 화면과 조건 | E4: ① 기준연도 · 검진 유형 · 부서 조건을 바꿔 본다 ② «사후관리 대상» · «기한 초과» 카드를 누르고 한 번 더 누른다 ③ 인원 카드(전체 대상자 · 검진 완료 · 미검진)를 눌러 본다 | F4: 조건대로 걸러진다. «사후관리 대상» · «기한 초과»는 누르면 그 숫자만큼 줄이 남고 다시 누르면 풀린다. 인원 카드(명)는 눌리지 않는다
A5: 9 | B5: QA박안전2(재난안전과) | C5: 작업환경·건강 > 건강검진 (일반·특수) | D5: 검진 계획 등록 | E5: ① 새로고침해 조건을 처음 상태(올해 · 전체)로 돌린다 ② [＋ 검진 계획 등록] → 빈 채로 [등록] ③ [조직도]로 내 부서(건설과)를 고르고 검진 유형 일반건강검진, 위탁 검진기관 «남다슬_검진기관», 검진 예정일 오늘부터 7일 뒤 → [등록] ④ 같은 내용으로 한 번 더 등록해 본다 | F5: 빈 채로는 «대상 부서를 선택하세요.» 등록하면 «검진 계획이 등록되었습니다.»와 함께 목록에 «남다슬_검진기관» 줄이 생긴다. 같은 내용은 «같은 부서·검진유형·예정일의 계획이 이미 있습니다.»로 막힌다
A6: 10 | B6: QA박안전2(재난안전과) | C6: 작업환경·건강 > 건강검진 (일반·특수) | D6: 실시 증빙과 상세 | E6: ① 9번 «남다슬_검진기관» 줄의 [＋ 첨부] → 파일을 올린다(«…연계 후 제공됩니다»가 뜨면 넘어간다) → [등록] ② 그 줄을 눌러 상세를 연다 | F6: «증빙이 등록되었습니다.» 뒤 목록의 결과보고서 칸이 «첨부됨»이 된다. 상세 «실시 증빙»에 «실시 증빙이 등록되어 있습니다.»가 보이고 «처리 · 변경 이력»에 «실시 증빙 등록»이 내 QA박안전2 계정 이름으로 남는다
A7: 11 | B7: QA하정수2(담당 공무원) → QA박안전2(재난안전과) | C7: 작업환경·건강 > 건강검진 (일반·특수) | D7: 계정별 차이 | E7: ① QA하정수2 창에서 목록 · 부서 조건 · 등록 버튼을 본다 ② 9번 «남다슬_검진기관» 줄의 상세를 연다 ③ QA박안전2 창에서 목록을 본다 | F7: QA하정수2 계정에는 내 부서 줄만 있고(9번 줄 포함) [＋ 검진 계획 등록]이 있다. 9번 상세에는 [검진 완료 처리] · [증빙 등록]이 있다. QA박안전2 계정에는 다른 부서 줄도 보인다
A8: 12 | B8: QA하정수2(담당 공무원) | C8: 작업환경·건강 > 건강검진 (일반·특수) | D8: 남의 부서 이름으로는 등록 못 한다 | E8: ① [＋ 검진 계획 등록] ② 대상 부서 칸과 [조직도]를 본다 ③ [조직도]에서 내 부서가 아닌 부서를 골라 위탁 검진기관 «남다슬_남의부서», 예정일 오늘부터 7일 뒤로 [등록]을 눌러 본다 | F8: 부서 칸이 내 부서로 고정돼 있거나, 남의 부서를 고르면 등록이 막힌다. 등록되면 «실패»(내 목록에 안 보이면 QA박안전2 창에서 «남다슬_남의부서»를 찾아 메모에 적는다)
A9: 13 | B9: QA박안전2(재난안전과) → QA하정수2(담당 공무원) | C9: 작업환경·건강 > 건강검진 (일반·특수) | D9: 남의 부서 검진은 주소로도 못 연다 | E9: ① QA박안전2 창에서 부서가 내 부서(건설과)와 다른 줄을 눌러 상세를 열고 주소창의 주소를 복사한다 ② QA하정수2 창 주소창에 붙여넣고 연다 | F9: «조회 범위 밖입니다 — 소속 부서 건만 볼 수 있습니다.»만 보이고 대상 인원 · 수검률 같은 내용은 보이지 않는다

Sheet _정보
A1: 형식 | B1: QA엑셀 v1.1
A2: 메뉴 | B2: 작업환경·건강
A3: 담당자 | B3: 남다슬
A4: 파일 코드 | B4: WE
A5: 종류 | B5: 스모크
A6: 생성일 | B6: 2026-09-30
A7: 결과 값 | B7: 성공,실패,오류,보류,확인 불가,문의
A8: 머리 행 | B8: 3
A9: 열 | B9: 번호,누구로,어디서,확인할,해,이러면,결과,메모,사진
