Workbook

Sheet 안내
A1: QA 담양 중대재해 — 관리대상 · 남다슬
A3: 메뉴 | B3: 관리대상 (훑어보는 파일)
A4: 담당자 | B4: 남다슬
A5: 내 계정 | B5: QA박안전2 (재난안전과 담당자) · QA하정수2 (내 부서 건설과 담당 공무원)
A6: 이 파일 | B6: 관리대상의 시설물 대장과 시설물 위험도를 봅니다. 시설물은 모든 부서가 함께 보고, 보완입력은 아직 역할 구분이 없어 누구나 저장되는 것이 정상입니다.
A7: 줄 수 | B7: 10줄
A8: 시트 | B8: 시설물 대장 → 시설물 위험도
A9: 테스트 주소 | B9: https://safety.damyang.go.kr/login
A10: 브라우저
A11: 기기
A12: 시작한 날
A14: 이렇게 하면 됩니다
A15: ① 위 «테스트 주소»에서 받은 아이디·비밀번호로 로그인합니다. 로그인하면 통합 현황 화면으로 갑니다. 5번 틀리면 계정이 잠깁니다 — 담당 개발자에게 풀어 달라고 합니다.
A16: ② 내 계정 두 개를 창 두 개에 따로 로그인해 둡니다 — 일반 창에는 QA박안전2(재난안전과), 시크릿 창(Ctrl + Shift + N · 맥 Cmd + Shift + N)에는 QA하정수2(담당 공무원). 두 창을 나란히 두면 계정을 바꿀 필요가 없습니다.
A17: ③ «누구로» 칸에 적힌 계정의 창에서 «어디서» 메뉴로 가서 «해 볼 것»대로 눌러 봅니다.
A18: ④ «이러면 성공»과 같으면 «결과» 칸에서 성공을, 다르면 실패·오류 등을 고릅니다.
A19: ⑤ 실패·오류·문의면 «메모»에 한 줄 적고, 필요하면 «사진» 칸에 화면 캡처를 붙여넣습니다.
A21: 결과 고르는 법
A22: 결과 | B22: 이럴 때 고르세요
A23: 성공 | B23: «이러면 성공»대로 된다
A24: 실패 | B24: 되긴 하는데 설명과 다르다 — 막혀야 하는데 저장된다, 문구·숫자가 틀리다
A25: 오류 | B25: 화면이 멈추거나 깨진다, 눌러도 아무 일이 없다, 오류 창이 뜬다
A26: 보류 | B26: 앞 단계가 안 돼서 지금은 못 한다 — 메모에 이유
A27: 확인 불가 | B27: 이 환경에서는 볼 수 없다 — 예: 확인할 데이터가 없다
A28: 문의 | B28: 맞는지 헷갈린다 — 메모에 궁금한 점
A30: 사진 붙이는 법
A31: • 윈도우: Win + Shift + S → 영역 선택 → 엑셀에서 그 줄의 «사진» 칸을 누르고 Ctrl + V
A32: • 맥: Cmd + Ctrl + Shift + 4 → 영역 선택 → 엑셀에서 그 줄의 «사진» 칸을 누르고 Cmd + V
A33: • 사진이 크면 모서리를 끌어 줄이세요. 사진은 그 줄 «사진» 칸 위에 두면 됩니다 — 취합할 때 줄 번호로 찾습니다.
A34: • 사진은 떠 있는 그대로 두세요(«셀에 배치»로 넣으면 취합할 때 꺼내지 못합니다).
A36: 누구로 — 내 계정 두 개
A37: • 계정은 두 개뿐입니다. «누구로» 칸에 계정 이름과 권한이 함께 적혀 있습니다. 비밀번호는 따로 받습니다.
A38: 이름 | B38: 권한 | D38: 볼 수 있는 것 | F38: 주로 하는 것
A39: QA박안전2 | B39: 재난안전과 담당자 | D39: 모든 부서 · «내 할일»은 전체 | F39: 전 부서 등록·수정 · 확인 · 상신 · 독촉 — 대부분 이 계정
A40: QA하정수2 | B40: 담당 공무원 (내 부서: 건설과) | D40: 업무 화면은 전 부서, «내 할일»은 나에게 지정된 것만, 위험성평가 부서별 조치표·교육 이수현황은 내 부서만 | F40: 내 부서 일 · 남의 부서 것을 못 건드리는지 확인
A41: QA시스템관리 | B41: 시스템 관리자 (김유석만) | D41: 시스템 관리 메뉴 | F41: 시스템 관리 파일 · 공문 반려(결재 대행)
A43: 같은 서버를 6명이 함께 씁니다
A44: • 내가 만드는 것(교육 · 근로자 · 문서 · 위원 등)은 이름 앞에 내 이름을 붙입니다 — 예: «남다슬_집합교육». 그래야 내 것을 찾기 쉽습니다.
A45: • 다른 사람이 만든 것은 고치거나 지우지 않습니다. QA박안전2 계정에는 남의 것도 보이는데, 정상입니다.
A46: • 건수·이수율 같은 숫자는 다른 사람이 작업하는 동안 바뀔 수 있습니다. 숫자가 안 맞으면 새로고침해서 한 번 더 보고, 그래도 다르면 «실패».
...

Sheet 요약
A1: 진행 상황 — 관리대상 · 남다슬
A2: 결과를 고르면 저절로 채워집니다. 남은 것 = 아직 결과를 고르지 않은 줄입니다.
A4: 시트 | B4: 전체 | C4: 성공 | D4: 실패 | E4: 오류 | F4: 보류 | G4: 확인 불가 | H4: 문의 | I4: 남은 것 | J4: 진행률
A5: 시설물 대장 | B5: =COUNTA('시설물 대장'!$A$4:$A$9) -> 6 | C5: =COUNTIF('시설물 대장'!$G$4:$G$9,"성공") -> 0 | D5: =COUNTIF('시설물 대장'!$G$4:$G$9,"실패") -> 0 | E5: =COUNTIF('시설물 대장'!$G$4:$G$9,"오류") -> 0 | F5: =COUNTIF('시설물 대장'!$G$4:$G$9,"보류") -> 0 | G5: =COUNTIF('시설물 대장'!$G$4:$G$9,"확인 불가") -> 0 | H5: =COUNTIF('시설물 대장'!$G$4:$G$9,"문의") -> 0 | I5: =COUNTBLANK('시설물 대장'!$G$4:$G$9) -> 6 | J5: =IF(B5=0,0,(B5-I5)/B5) -> 0
A6: 시설물 위험도 | B6: =COUNTA('시설물 위험도'!$A$4:$A$7) -> 4 | C6: =COUNTIF('시설물 위험도'!$G$4:$G$7,"성공") -> 0 | D6: =COUNTIF('시설물 위험도'!$G$4:$G$7,"실패") -> 0 | E6: =COUNTIF('시설물 위험도'!$G$4:$G$7,"오류") -> 0 | F6: =COUNTIF('시설물 위험도'!$G$4:$G$7,"보류") -> 0 | G6: =COUNTIF('시설물 위험도'!$G$4:$G$7,"확인 불가") -> 0 | H6: =COUNTIF('시설물 위험도'!$G$4:$G$7,"문의") -> 0 | I6: =COUNTBLANK('시설물 위험도'!$G$4:$G$7) -> 4 | J6: =IF(B6=0,0,(B6-I6)/B6) -> 0
A7: 합계 | B7: =SUM(B5:B6) -> 10 | C7: =SUM(C5:C6) -> 0 | D7: =SUM(D5:D6) -> 0 | E7: =SUM(E5:E6) -> 0 | F7: =SUM(F5:F6) -> 0 | G7: =SUM(G5:G6) -> 0 | H7: =SUM(H5:H6) -> 0 | I7: =SUM(I5:I6) -> 10 | J7: =IF(B7=0,0,(B7-I7)/B7) -> 0

Sheet 시설물 대장
A1: 관리대상 — 시설물 대장
A2: 🗂 QA박안전2 창에서 합니다. 시설물은 새로 만들 수 없어 이미 있는 시설물을 고쳐 봅니다. 다른 사람과 겹치지 않게 계정 이름 끝 숫자로 시설물을 고르고, 번호·이름·원래 값은 메모에 적고, 4번 끝에서 원래대로 되돌립니다.
A3: 번호 | B3: 누구로 | C3: 어디서 | D3: 확인할 것 | E3: 해 볼 것 | F3: 이러면 성공 | G3: 결과 ▼ | H3: 메모 (실패·오류·문의일 때) | I3: 사진 (필요할 때 붙여넣기)
A4: 1 | B4: QA박안전2(재난안전과) | C4: 관리대상 > 시설물 대장 | D4: 화면 열기 | E4: 메뉴로 들어간다 | F4: 요약 카드 4개(총 시설물 · 종별 · 30년 초과 노후 · 안전등급 확보)와 목록이 뜬다. 목록 아래 «표시 N / 전체 M건»의 M이 «총 시설물» 숫자와 같다
A5: 2 | B5: QA박안전2(재난안전과) | C5: 관리대상 > 시설물 대장 | D5: 조건 걸기 | E5: ① 구분 · 종별 · 소관 · 평가 조건과 «노후만»을 하나씩 걸어 본다 ② 검색칸에 없는 이름(zzz)을 친다 ③ 조건과 검색어를 모두 푼다 | F5: 조건대로 줄이 걸러지고 «표시 N»도 따라 바뀐다. 없는 이름이면 «조건에 맞는 시설물이 없습니다.», 모두 풀면 다시 전체가 보인다
A6: 3 | B6: QA박안전2(재난안전과) | C6: 관리대상 > 시설물 대장 | D6: 시설물 상세 | E6: 아무 줄이나 눌러 상세를 연다 → [닫기] | F6: «시설물 상세 — (시설물 이름)» 창에 FMS 기본현황 · 보완입력 · 시설물 위험도 · 개선조치 내역이 보인다
A7: 4 | B7: QA박안전2(재난안전과) | C7: 관리대상 > 시설물 대장 | D7: 보완입력 저장과 되돌리기 | E7: ① 평가 조건을 «등급 없음»으로 두고, 목록 위에서부터 세어 계정 이름 끝 숫자번째 줄을 연다(끝 숫자가 3이면 3번째 줄). 시설물 번호 · 이름과 원래 최근 점검일 · 규모 · 단위, 목록의 위험도를 메모에 적는다 ② 최근 점검일을 내일 날짜로 넣고 [보완입력 저장] ③ 점검일을 비우고 규모 -5, 단위 m로 [보완입력 저장] ④ 안전등급 D · 최근 점검일 어제 · 규모 120, 단위 m로 [보완입력 저장] → 메모한 시설물 번호를 검색칸에 붙여넣어 찾는다(검색칸은 한 글자씩 치면 끊길 수 있다 — 붙여넣는다) ⑤ 다시 상세를 열어 안전등급을 «미평가»로, 최근 점검일 · 규모 · 단위를 ①에서 메모한 원래 값(없었으면 빈칸)으로 돌려 [보완입력 저장] | F7: ②는 «점검일은 미래일 수 없습니다.», ③은 «규모 값과 단위를 올바르게 입력하세요 — 0 이상 숫자입니다.»로 막힌다. ④는 «보완입력 저장됨» 뒤 그 줄이 «D등급»과 점수 있는 위험도로 바뀐다. ⑤ 뒤에는 ①에서 본 등급 · 위험도로 돌아간다
A8: 5 | B8: QA박안전2(재난안전과) | C8: 관리대상 > 시설물 대장 | D8: 연계 · 변경 이력 | E8: ① 4번을 끝내자마자 목록 위 [연계·변경 이력 (N)]을 누른다 ② 4번에서 고친 시설물 번호로 줄을 찾는다 | F8: 목록 아래 «연계 · 변경 이력 (감사추적)» 표로 내려가고, 시설물 칸이 그 시설물 번호인 «보완입력» · «저장» 줄이 있다(4번에서 바꾼 것과 되돌린 것). 다른 사람 줄이 많아 20건 밖으로 밀렸으면(표 아래 «최근 20건 표시 / 전체 N건») «확인 불가». 목록 위에 [FMS 연계] 버튼은 없다
A9: 6 | B9: QA박안전2(재난안전과) | C9: 관리대상 > 시설물 대장 | D9: FMS 전송은 한 번 더 묻는다 | E9: ① 4번에서 고친 시설물의 상세 → [FMS 전송(수정)] ② 확인 창 내용을 읽고 [취소]한다(FMS 실연계라 [전송]은 누르지 않는다) | F9: 바로 보내지 않고 «FMS 전송 확인 — (시설물 이름)» 창이 뜬다. 창에 시설물번호(반영키)와 updateBastbMaster가 보이고, [취소]하면 상세로 돌아온다

Sheet 시설물 위험도
A1: 관리대상 — 시설물 위험도
A2: 🗂 QA박안전2 창에서 하고, 마지막 줄만 QA하정수2 창에서 합니다. 8번에서 고친 시설물은 같은 줄에서 원래대로 되돌립니다. 위험성평가로 넘어가도 행은 추가하지 않습니다 — 정기평가는 6명이 함께 쓰는 1건입니다.
A3: 번호 | B3: 누구로 | C3: 어디서 | D3: 확인할 것 | E3: 해 볼 것 | F3: 이러면 성공 | G3: 결과 ▼ | H3: 메모 (실패·오류·문의일 때) | I3: 사진 (필요할 때 붙여넣기)
A4: 7 | B4: QA박안전2(재난안전과) | C4: 관리대상 > 시설물 위험도 | D4: 순서와 산정불가 | E4: 메뉴로 들어가 목록을 위에서 아래로 훑어본다 | F4: 위험도가 높음 → 보통 → 낮음 → 산정불가 순이다. 산정불가 줄은 점수가 없고 버튼이 [보완입력]이다
A5: 8 | B5: QA박안전2(재난안전과) | C5: 관리대상 > 시설물 위험도 | D5: 보완입력 뒤 다시 계산 | E5: ① 산정불가 줄 가운데 맨 아래에서부터 세어 계정 이름 끝 숫자번째 줄의 [보완입력]을 누른다(번호 · 이름은 메모에) ② 안전등급 C만 골라 [보완입력 저장] ③ 관리대상 > 시설물 대장 메뉴에서 메모한 시설물 번호를 검색칸에 붙여넣어 상세를 열고, 안전등급을 «미평가»로 돌려 [보완입력 저장] | F5: ② 뒤 새로고침 없이 그 시설물이 점수와 함께 순위 안으로 올라가고 위 «산정 불가» 카드 숫자가 줄어든다. ③ 뒤에는 다시 «산정불가»다
A6: 9 | B6: QA박안전2(재난안전과) | C6: 관리대상 > 시설물 위험도 | D6: 위험성평가로 넘어가기 | E6: ① 점수가 있는 줄의 [근로자 위험성평가 연계](개선조치가 있는 줄은 [연계 보기])를 누른다 ② 넘어간 화면 위 안내를 읽는다 — 행은 추가하지 않는다 | F6: 정기 위험성평가 화면으로 가고 위에 «시설물 (그 이름) 에서 넘어왔습니다 — …» 안내가 있다(뒤 문장은 평가 진행 단계마다 다르다)
A7: 10 | B7: QA하정수2(담당 공무원) | C7: 관리대상 > 시설물 위험도 | D7: 담당 공무원도 시설물은 모두 본다 | E7: ① QA하정수2 창에서 시설물 위험도를 열어 필터 줄 오른쪽 «N / M건»을 본다 ② 구분 · 종별 · 소관 조건을 바꿔 본다 ③ 관리대상 > 시설물 대장에서 목록 아래 «전체 M건»을 본다 | F7: 두 화면의 M이 QA박안전2 창의 같은 화면과 같다(시설물은 아직 부서 구분이 없다 — 정상). 조건대로 바뀌고 오류가 없다

Sheet _정보
A1: 형식 | B1: QA엑셀 v1.1
A2: 메뉴 | B2: 관리대상
A3: 담당자 | B3: 남다슬
A4: 파일 코드 | B4: BS
A5: 종류 | B5: 스모크
A6: 생성일 | B6: 2026-09-30
A7: 결과 값 | B7: 성공,실패,오류,보류,확인 불가,문의
A8: 머리 행 | B8: 3
A9: 열 | B9: 번호,누구로,어디서,확인할,해,이러면,결과,메모,사진
