Workbook

Sheet 안내
A1: QA 담양 중대재해 — 안전보건교육 · 남다슬
A3: 메뉴 | B3: 안전보건교육 (자세히 보는 파일)
A4: 담당자 | B4: 남다슬
A5: 내 계정 | B5: QA박안전2 (재난안전과 담당자) · QA하정수2 (내 부서 건설과 담당 공무원)
A6: 이 파일 | B6: 근로자 명단 → 교육 등록 → 참석자 등록부 → 교육 종료 → 이수현황 → 공문까지 봅니다. 이수 기록은 참석자를 등록할 때가 아니라 [교육 종료 처리]를 눌러야 생깁니다. 내가 만든 «남다슬_…» 근로자·교육만 고치고 지웁니다.
A7: 줄 수 | B7: 58줄
A8: 시트 | B8: 1 근로자 명단 → 2 정기교육(집합) → 3 자체·채용시·기타 → 4 이수현황 → 5 공문·결재 이력 → 6 부서 담당자·다시 로그인
A9: 테스트 주소 | B9: https://safety.damyang.go.kr/login
A10: 브라우저
A11: 기기
A12: 시작한 날
A14: 이렇게 하면 됩니다
A15: ① 위 «테스트 주소»에서 받은 아이디·비밀번호로 로그인합니다. 로그인하면 통합 현황 화면으로 갑니다. 5번 틀리면 계정이 잠깁니다 — 담당 개발자에게 풀어 달라고 합니다.
A16: ② 내 계정 두 개를 창 두 개에 따로 로그인해 둡니다 — 일반 창에는 QA박안전2(재난안전과), 시크릿 창(Ctrl + Shift + N · 맥 Cmd + Shift + N)에는 QA하정수2(담당 공무원). 두 창을 나란히 두면 계정을 바꿀 필요가 없습니다.
A17: ③ «누구로» 칸에 적힌 계정의 창에서 «어디서» 메뉴로 가서 «해 볼 것»대로 눌러 봅니다.
A18: ④ «이러면 성공»과 같으면 «결과» 칸에서 성공을, 다르면 실패·오류 등을 고릅니다.
A19: ⑤ 실패·오류·문의면 «메모»에 한 줄 적고, 필요하면 «사진» 칸에 화면 캡처를 붙여넣습니다.
A21: 결과 고르는 법
A22: 결과 | B22: 이럴 때 고르세요
A23: 성공 | B23: «이러면 성공»대로 된다
A24: 실패 | B24: 되긴 하는데 설명과 다르다 — 막혀야 하는데 저장된다, 문구·숫자가 틀리다
A25: 오류 | B25: 화면이 멈추거나 깨진다, 눌러도 아무 일이 없다, 오류 창이 뜬다
A26: 보류 | B26: 앞 단계가 안 돼서 지금은 못 한다 — 메모에 이유
A27: 확인 불가 | B27: 이 환경에서는 볼 수 없다 — 예: 확인할 데이터가 없다
A28: 문의 | B28: 맞는지 헷갈린다 — 메모에 궁금한 점
A30: 사진 붙이는 법
A31: • 윈도우: Win + Shift + S → 영역 선택 → 엑셀에서 그 줄의 «사진» 칸을 누르고 Ctrl + V
A32: • 맥: Cmd + Ctrl + Shift + 4 → 영역 선택 → 엑셀에서 그 줄의 «사진» 칸을 누르고 Cmd + V
A33: • 사진이 크면 모서리를 끌어 줄이세요. 사진은 그 줄 «사진» 칸 위에 두면 됩니다 — 취합할 때 줄 번호로 찾습니다.
A34: • 사진은 떠 있는 그대로 두세요(«셀에 배치»로 넣으면 취합할 때 꺼내지 못합니다).
A36: 누구로 — 내 계정 두 개
A37: • 계정은 두 개뿐입니다. «누구로» 칸에 계정 이름과 권한이 함께 적혀 있습니다. 비밀번호는 따로 받습니다.
A38: 이름 | B38: 권한 | D38: 볼 수 있는 것 | F38: 주로 하는 것
A39: QA박안전2 | B39: 재난안전과 담당자 | D39: 모든 부서 · «내 할일»은 전체 | F39: 전 부서 등록·수정 · 확인 · 상신 · 독촉 — 대부분 이 계정
A40: QA하정수2 | B40: 담당 공무원 (내 부서: 건설과) | D40: 업무 화면은 전 부서, «내 할일»은 나에게 지정된 것만, 위험성평가 부서별 조치표·교육 이수현황은 내 부서만 | F40: 내 부서 일 · 남의 부서 것을 못 건드리는지 확인
A41: QA시스템관리 | B41: 시스템 관리자 (김유석만) | D41: 시스템 관리 메뉴 | F41: 시스템 관리 파일 · 공문 반려(결재 대행)
A43: 같은 서버를 6명이 함께 씁니다
A44: • 내가 만드는 것(교육 · 근로자 · 문서 · 위원 등)은 이름 앞에 내 이름을 붙입니다 — 예: «남다슬_집합교육». 그래야 내 것을 찾기 쉽습니다.
A45: • 다른 사람이 만든 것은 고치거나 지우지 않습니다. QA박안전2 계정에는 남의 것도 보이는데, 정상입니다.
A46: • 건수·이수율 같은 숫자는 다른 사람이 작업하는 동안 바뀔 수 있습니다. 숫자가 안 맞으면 새로고침해서 한 번 더 보고, 그래도 다르면 «실패».
...

Sheet 요약
A1: 진행 상황 — 안전보건교육 · 남다슬
A2: 결과를 고르면 저절로 채워집니다. 남은 것 = 아직 결과를 고르지 않은 줄입니다.
A4: 시트 | B4: 전체 | C4: 성공 | D4: 실패 | E4: 오류 | F4: 보류 | G4: 확인 불가 | H4: 문의 | I4: 남은 것 | J4: 진행률
A5: 1 근로자 명단 | B5: =COUNTA('1 근로자 명단'!$A$4:$A$13) -> 10 | C5: =COUNTIF('1 근로자 명단'!$G$4:$G$13,"성공") -> 0 | D5: =COUNTIF('1 근로자 명단'!$G$4:$G$13,"실패") -> 0 | E5: =COUNTIF('1 근로자 명단'!$G$4:$G$13,"오류") -> 0 | F5: =COUNTIF('1 근로자 명단'!$G$4:$G$13,"보류") -> 0 | G5: =COUNTIF('1 근로자 명단'!$G$4:$G$13,"확인 불가") -> 0 | H5: =COUNTIF('1 근로자 명단'!$G$4:$G$13,"문의") -> 0 | I5: =COUNTBLANK('1 근로자 명단'!$G$4:$G$13) -> 10 | J5: =IF(B5=0,0,(B5-I5)/B5) -> 0
A6: 2 정기교육(집합) | B6: =COUNTA('2 정기교육(집합)'!$A$4:$A$19) -> 16 | C6: =COUNTIF('2 정기교육(집합)'!$G$4:$G$19,"성공") -> 0 | D6: =COUNTIF('2 정기교육(집합)'!$G$4:$G$19,"실패") -> 0 | E6: =COUNTIF('2 정기교육(집합)'!$G$4:$G$19,"오류") -> 0 | F6: =COUNTIF('2 정기교육(집합)'!$G$4:$G$19,"보류") -> 0 | G6: =COUNTIF('2 정기교육(집합)'!$G$4:$G$19,"확인 불가") -> 0 | H6: =COUNTIF('2 정기교육(집합)'!$G$4:$G$19,"문의") -> 0 | I6: =COUNTBLANK('2 정기교육(집합)'!$G$4:$G$19) -> 16 | J6: =IF(B6=0,0,(B6-I6)/B6) -> 0
A7: 3 자체·채용시·기타 | B7: =COUNTA('3 자체·채용시·기타'!$A$4:$A$17) -> 14 | C7: =COUNTIF('3 자체·채용시·기타'!$G$4:$G$17,"성공") -> 0 | D7: =COUNTIF('3 자체·채용시·기타'!$G$4:$G$17,"실패") -> 0 | E7: =COUNTIF('3 자체·채용시·기타'!$G$4:$G$17,"오류") -> 0 | F7: =COUNTIF('3 자체·채용시·기타'!$G$4:$G$17,"보류") -> 0 | G7: =COUNTIF('3 자체·채용시·기타'!$G$4:$G$17,"확인 불가") -> 0 | H7: =COUNTIF('3 자체·채용시·기타'!$G$4:$G$17,"문의") -> 0 | I7: =COUNTBLANK('3 자체·채용시·기타'!$G$4:$G$17) -> 14 | J7: =IF(B7=0,0,(B7-I7)/B7) -> 0
A8: 4 이수현황 | B8: =COUNTA('4 이수현황'!$A$4:$A$10) -> 7 | C8: =COUNTIF('4 이수현황'!$G$4:$G$10,"성공") -> 0 | D8: =COUNTIF('4 이수현황'!$G$4:$G$10,"실패") -> 0 | E8: =COUNTIF('4 이수현황'!$G$4:$G$10,"오류") -> 0 | F8: =COUNTIF('4 이수현황'!$G$4:$G$10,"보류") -> 0 | G8: =COUNTIF('4 이수현황'!$G$4:$G$10,"확인 불가") -> 0 | H8: =COUNTIF('4 이수현황'!$G$4:$G$10,"문의") -> 0 | I8: =COUNTBLANK('4 이수현황'!$G$4:$G$10) -> 7 | J8: =IF(B8=0,0,(B8-I8)/B8) -> 0
A9: 5 공문·결재 이력 | B9: =COUNTA('5 공문·결재 이력'!$A$4:$A$11) -> 8 | C9: =COUNTIF('5 공문·결재 이력'!$G$4:$G$11,"성공") -> 0 | D9: =COUNTIF('5 공문·결재 이력'!$G$4:$G$11,"실패") -> 0 | E9: =COUNTIF('5 공문·결재 이력'!$G$4:$G$11,"오류") -> 0 | F9: =COUNTIF('5 공문·결재 이력'!$G$4:$G$11,"보류") -> 0 | G9: =COUNTIF('5 공문·결재 이력'!$G$4:$G$11,"확인 불가") -> 0 | H9: =COUNTIF('5 공문·결재 이력'!$G$4:$G$11,"문의") -> 0 | I9: =COUNTBLANK('5 공문·결재 이력'!$G$4:$G$11) -> 8 | J9: =IF(B9=0,0,(B9-I9)/B9) -> 0
A10: 6 부서 담당자·다시 로그인 | B10: =COUNTA('6 부서 담당자·다시 로그인'!$A$4:$A$6) -> 3 | C10: =COUNTIF('6 부서 담당자·다시 로그인'!$G$4:$G$6,"성공") -> 0 | D10: =COUNTIF('6 부서 담당자·다시 로그인'!$G$4:$G$6,"실패") -> 0 | E10: =COUNTIF('6 부서 담당자·다시 로그인'!$G$4:$G$6,"오류") -> 0 | F10: =COUNTIF('6 부서 담당자·다시 로그인'!$G$4:$G$6,"보류") -> 0 | G10: =COUNTIF('6 부서 담당자·다시 로그인'!$G$4:$G$6,"확인 불가") -> 0 | H10: =COUNTIF('6 부서 담당자·다시 로그인'!$G$4:$G$6,"문의") -> 0 | I10: =COUNTBLANK('6 부서 담당자·다시 로그인'!$G$4:$G$6) -> 3 | J10: =IF(B10=0,0,(B10-I10)/B10) -> 0
A11: 합계 | B11: =SUM(B5:B10) -> 58 | C11: =SUM(C5:C10) -> 0 | D11: =SUM(D5:D10) -> 0 | E11: =SUM(E5:E10) -> 0 | F11: =SUM(F5:F10) -> 0 | G11: =SUM(G5:G10) -> 0 | H11: =SUM(H5:H10) -> 0 | I11: =SUM(I5:I10) -> 58 | J11: =IF(B11=0,0,(B11-I11)/B11) -> 0

Sheet 1 근로자 명단
A1: 안전보건교육 — 1 근로자 명단
A2: 🗂 QA박안전2 창(재난안전과)과 QA하정수2 창(내 부서)을 씁니다. 여기서 만드는 «남다슬_근로자01»·«남다슬_관리감독자»와 10번에서 올리는 4명을 뒤 시트에서 계속 씁니다. 10번에서 올라가는 4명은 이름이 정해져 있어 다른 부서에도 같은 이름이 있습니다 — 고를 때는 부서 조건을 내 부서에 겁니다.
A3: 번호 | B3: 누구로 | C3: 어디서 | D3: 확인할 것 | E3: 해 볼 것 | F3: 이러면 성공 | G3: 결과 ▼ | H3: 메모 (실패·오류·문의일 때) | I3: 사진 (필요할 때 붙여넣기)
A4: 1 | B4: QA박안전2(재난안전과) | C4: 안전보건교육 > 근로자 명단 관리 | D4: 목록 조건 걸기 | E4: ① 검색·부서·구분·고용형태 조건을 하나씩 건다 ② [필터 초기화] | F4: 조건마다 건수가 바뀌고, 초기화하면 전체 건수로 돌아온다
A5: 2 | B5: QA박안전2(재난안전과) | C5: 안전보건교육 > 근로자 명단 관리 | D5: 근로자 등록 | E5: ① [＋ 직접 등록] ② 이름 «남다슬_근로자01» · 부서는 [조직도]에서 내 부서(건설과) · 구분 비사무직(현업) · 고용형태 기간제 · 채용일 오늘 · 계약기간 6 ③ [등록] | F5: «남다슬_근로자01 근로자 등록 완료»가 뜨고 목록에 부서 건설과 줄로 보인다
A6: 3 | B6: QA박안전2(재난안전과) | C6: 안전보건교육 > 근로자 명단 관리 | D6: 빈 칸이면 등록되지 않는다 | E6: [＋ 직접 등록]에서 ① 이름을 비우고 [등록] ② 이름 «남다슬_근로자03»을 넣고 채용일을 비운 뒤 [등록] ③ 채용일을 오늘로 되돌리고 고용형태 기간제·계약기간을 비운 뒤 [등록] ④ [취소] | F6: 차례로 «이름을 입력하세요.» «채용일을 입력하세요.» «계약기간을 0보다 크게 입력하세요 — …»가 뜨고 등록되지 않는다(«등록 완료»가 뜨면 실패)
A7: 4 | B7: QA박안전2(재난안전과) | C7: 안전보건교육 > 근로자 명단 관리 | D7: 관리감독자 등록 | E7: [＋ 직접 등록] → 이름 «남다슬_관리감독자» · 부서는 [조직도]에서 내 부서(건설과) · 구분 관리감독자 · 고용형태 공무원 → [등록] | F7: 목록에 생기고 지정일은 비어 있다(지정일은 다음 줄에서 따로 넣는다)
A8: 5 | B8: QA박안전2(재난안전과) | C8: 안전보건교육 > 근로자 명단 관리 | D8: 지정일 넣기 — 빈 칸·미래 날짜 | E8: 4번 줄의 [지정일 등록] ① 비운 채 [저장] ② 내일 날짜로 [저장] ③ 오늘로 [저장] | F8: ① 지정일을 넣으라는 안내가 뜨고 저장되지 않는다 ② 미래 날짜는 막힌다 — 저장되면 «실패»(미래 지정일은 이수 판정을 틀리게 한다) ③ 저장되고 지정일에 오늘이 보인다
A9: 6 | B9: QA하정수2(담당 공무원) | C9: 안전보건교육 > 근로자 명단 관리 | D9: 지정일은 재난안전과만 넣는다 | E9: ① 4번의 «남다슬_관리감독자» 줄과 다른 관리감독자 줄을 본다 ② [＋ 직접 등록]에서 이름·채용일을 넣고 구분을 관리감독자로 골라 [등록] ③ [취소] | F9: 어느 줄에도 [지정일 등록]이 없다(지정일이 빈 줄은 «지정일은 재난안전과가 등록»). 등록 창의 지정일 칸은 입력할 수 없고 [등록]은 «…관리감독자 등록은 재난안전과 담당자에게 요청하세요.»로 막힌다
A10: 7 | B10: QA하정수2(담당 공무원) | C10: 안전보건교육 > 근로자 명단 관리 | D10: 부서 담당자의 등록 창 | E10: [＋ 직접 등록]을 열어 부서 칸을 보고 [취소] | F10: 부서 칸이 내 부서(건설과)로 고정돼 있고 [조직도] 버튼 없이 «소속 부서 명단에 등록합니다.»가 보인다
A11: 8 | B11: QA박안전2(재난안전과) | C11: 안전보건교육 > 근로자 명단 관리 | D11: 이름만 고치기 | E11: ① «남다슬_근로자01» [수정] → 이름 끝에 «_수정»을 붙여 [저장] ② 다시 [수정] → 원래 이름으로 [저장] | F11: 두 번 모두 «근로자 정보 저장» — 손대지 않은 계약기간 때문에 막히지 않는다
A12: 9 | B12: QA박안전2(재난안전과) | C12: 안전보건교육 > 근로자 명단 관리 | D12: 삭제는 한 번 더 묻는다 | E12: ① «남다슬_근로자02»를 등록한다(나머지는 기본값) ② 그 줄 [삭제] → 확인 창 → [삭제] | F12: 확인 창(«…명단에서 제외합니다. 이력은 보존됩니다.»)을 거친 뒤 «근로자를 명단에서 제외했습니다.», 목록에서 사라진다
A13: 10 | B13: QA하정수2(담당 공무원) | C13: 안전보건교육 > 근로자 명단 관리 | D13: 엑셀 업로드 | E13: ① [📥 엑셀 업로드] → 서식을 내려받아 칸 순서를 본다 ② 배포받은 «근로자 업로드 예시 남다슬.xlsx»를 골라 [업로드] (한 번만 — 다시 올리면 4명이 또 생긴다) | F13: 서식 칸이 부서명·이름·구분·고용형태·채용일·계약기간개월이다. 올리면 «남다슬_근로자A~D» 4명이 내 부서(건설과)로 목록에 생긴다. 예시 파일 칸이 서식과 달라 막히면 «문의»

Sheet 2 정기교육(집합)
A1: 안전보건교육 — 2 정기교육(집합)
A2: 🗂 QA박안전2 창이 집합교육을 만들고(13·14번) → QA하정수2 창이 내 부서 참석자를 내고 → QA박안전2 창이 종료합니다. 14번 교육은 끝까지 진행 중으로 둡니다.
A3: 번호 | B3: 누구로 | C3: 어디서 | D3: 확인할 것 | E3: 해 볼 것 | F3: 이러면 성공 | G3: 결과 ▼ | H3: 메모 (실패·오류·문의일 때) | I3: 사진 (필요할 때 붙여넣기)
A4: 11 | B4: QA박안전2(재난안전과) | C4: 안전보건교육 > 현업근로자 > 정기교육 | D4: 탭 바꾸기 | E4: [집합교육] ↔ [자체교육 (부서)]를 바꾸고 조건을 몇 개 건다 → [필터 초기화] | F4: 오류 없이 바뀌고 조건대로 걸러진다
A5: 12 | B5: QA하정수2(담당 공무원) | C5: 안전보건교육 > 현업근로자 > 정기교육 | D5: 집합교육은 재난안전과만 만든다 | E5: [집합교육] 탭을 본다 | F5: [＋ 집합교육 등록]이 없고 «집합교육은 재난안전과 담당자가 등록합니다»가 보인다
A6: 13 | B6: QA박안전2(재난안전과) | C6: 안전보건교육 > 현업근로자 > 정기교육 | D6: 집합교육 등록 | E6: ① [＋ 집합교육 등록] → 빈 채로 [등록] ② 내용 «남다슬_집합교육» · 일자 오늘 · 14:00~16:00 · 강사 · 장소를 넣고 [등록] | F6: 빈 채로는 «교육 내용을 입력하세요.» 등록하면 «집합교육 등록 · 참석자 등록부 접수 개시», 카드가 생기고 시간이 2h로 계산된다
A7: 14 | B7: QA박안전2(재난안전과) | C7: 안전보건교육 > 현업근로자 > 정기교육 | D7: 여러 날 교육 | E7: [＋ 집합교육 등록]에서 ① 내용 «남다슬_집합교육_2일»을 먼저 넣고 [＋ 일자 추가]로 5일까지 늘린다 ② 한 회차의 종료 시각을 시작보다 이르게 하고 [등록] ③ [이 일자 삭제]로 2일만 남기고, 남은 회차의 시각을 바르게(종료가 시작보다 뒤) 고쳐 [등록] | F7: 5일이 되면 추가 버튼 자리에 «최대 5일»이 보인다. 종료가 시작보다 이르면 «…0h로 계산됩니다» 경고와 함께 [등록]이 «N회차의 일자·시작·종료 시각을 확인하세요…»로 막힌다. 등록하면 카드에 «…외 1일», 시간은 두 날의 합이다
A8: 15 | B8: QA박안전2(재난안전과) | C8: 안전보건교육 > 현업근로자 > 정기교육 | D8: 집합교육 첨부 칸 | E8: [＋ 집합교육 등록] 창의 첨부 영역을 보고 [취소] | F8: «참석자 명단» · «교육 자료» 두 칸이 있고 교육 사진 칸은 없다
A9: 16 | B9: QA박안전2(재난안전과) | C9: 안전보건교육 > 현업근로자 > 정기교육 | D9: 그대로 저장해도 막히지 않는다 | E9: 13번 교육 카드의 [수정] → 아무것도 안 바꾸고 [저장] | F9: 종료 시각 16:00이 채워져 있고 «교육 정보를 저장했습니다 · 교육시간 2h»가 뜬다(저장이 막히면 실패)
A10: 17 | B10: QA박안전2(재난안전과) | C10: 안전보건교육 > 현업근로자 > 정기교육 | D10: 예전에 등록된 교육의 수정 창 | E10: 서버에 처음부터 있던 집합교육(예: «2026년 8월 정기 안전보건교육») 카드의 [수정]을 열어 종료 시각만 보고 [취소] — 남의 교육이라 저장하지 않는다 | F10: 종료 시각이 비어 있지 않고 시작 시각 + 교육시간으로 채워져 있다(8월 교육이면 17:00). 그런 교육이 없으면 «확인 불가»
A11: 18 | B11: QA하정수2(담당 공무원) | C11: 안전보건교육 > 현업근로자 > 정기교육 | D11: 참석자 등록부 내기 | E11: 13번 교육 [상세 →] → [＋ 참석자 등록부 등록] ① 아무도 안 고르고 [신청 완료] ② «남다슬_근로자01» 포함 2명을 고르고 서명파일 없이 [신청 완료] ③ [＋ 서명파일 첨부] 후 실제 참석시간 3으로 [신청 완료] ④ 2로 고쳐 [신청 완료] | F11: 부서는 내 부서(건설과)로 고정. ① «근로자를 1명 이상 선택하세요.» ② «서명파일을 업로드하세요 (필수).» ③ «실제 참석시간을 0보다 크고 교육 예정시간 이하로 입력하세요.»로 막히고 ④ «건설과 · 2명 신청 완료»
A12: 19 | B12: QA하정수2(담당 공무원) | C12: 안전보건교육 > 현업근로자 > 정기교육 | D12: 같은 부서는 두 번 못 낸다 | E12: 같은 상세에서 [＋ 참석자 등록부 등록] → 1명 고르고 서명파일 첨부 → [신청 완료] | F12: «…이미 등록된 부서입니다 — 신청 취소 후 다시 등록하세요.»가 뜨고 줄이 늘지 않는다
A13: 20 | B13: QA박안전2(재난안전과) → QA하정수2(담당 공무원) | C13: 안전보건교육 > 현업근로자 > 정기교육 | D13: 남의 부서 줄은 못 건드린다 | E13: ① QA박안전2 창에서 13번 교육 상세 → [＋ 참석자 등록부 등록] → 부서 재난안전과(기본값) 그대로 1명 고르고 서명파일 첨부 → [신청 완료] ② QA하정수2 창에서 같은 상세를 새로고침 | F13: ① «재난안전과 · 1명 신청 완료» ② QA하정수2 창의 재난안전과 줄에는 [신청 취소]가 없고 내 부서 줄에만 있다
A14: 21 | B14: QA하정수2(담당 공무원) | C14: 안전보건교육 > 현업근로자 > 정기교육 | D14: 신청 취소하고 다시 내기 | E14: ① 내 부서 줄 [신청 취소] → 확인 창 → [신청 취소] ② 다시 «남다슬_근로자01» 포함 2명 · 서명파일 · 참석시간 2로 신청 | F14: 확인 창이 «신청 내역과 서명파일이 삭제됩니다.»를 알리고 «건설과 신청을 취소했습니다.» 후 줄이 빠진다. 다시 신청하면 줄이 돌아온다
A15: 22 | B15: QA박안전2(재난안전과) | C15: 안전보건교육 > 현업근로자 > 정기교육 | D15: 교육 종료 처리 | E15: 13번 교육 상세 → [교육 종료 처리] → 확인 창을 읽고 [종료 처리] | F15: 확인 창이 «신청 2개 부서 · 3명»을 알려 주고, 종료하면 «교육 종료 · 3명 카운트 완료», 상태가 완료로 바뀐다
... A19: 26 | B19: QA박안전2(재난안전과) | C19: 안전보건교육 > 현업근로자 > 정기교육 | D19: 삭제는 지울 건수를 알려 준다 | E19: ① 집합교육 «남다슬_삭제용»을 등록 ② 그 카드의 [＋ 참석자 등록부 등록]으로 재난안전과 1명 신청 ③ [삭제] → 확인 창을 읽고 [삭제] | F19: 확인 창이 «신청 1개 부서 · 1명 신청 내역이 함께 삭제됩니다.»를 알리고, 삭제하면 «교육을 삭제했습니다 · 신청 1건 · 이수기록 0건 회수»

Sheet 3 자체·채용시·기타
A1: 안전보건교육 — 3 자체·채용시·기타
A2: 🗂 자체·기타 교육은 각 부서가 등록합니다. 대상자는 1번 시트에서 만든 내 근로자를 고릅니다.
A3: 번호 | B3: 누구로 | C3: 어디서 | D3: 확인할 것 | E3: 해 볼 것 | F3: 이러면 성공 | G3: 결과 ▼ | H3: 메모 (실패·오류·문의일 때) | I3: 사진 (필요할 때 붙여넣기)
A4: 27 | B4: QA하정수2(담당 공무원) | C4: 안전보건교육 > 현업근로자 > 정기교육 | D4: 자체교육 등록 | E4: [자체교육 (부서)] → [＋ 자체교육 등록·진행] ① 아무것도 안 넣고 [진행 처리] ② 내용 «남다슬_자체교육»만 넣고 [진행 처리] ③ 시각 08:00~18:00 · 대상자 «남다슬_근로자01»·남다슬_근로자C · 증빙을 넣고 [진행 처리] | F4: ① «교육 내용을 입력하세요.» ② «교육 대상자를 1명 이상 선택하세요.» ③ «건설과 자체교육 완료 · 10h · 2명 카운트», 목록에 생긴다. 부서는 내 부서(건설과)로 고정
A5: 28 | B5: QA하정수2(담당 공무원) | C5: 안전보건교육 > 현업근로자 > 정기교육 | D5: 자체교육 첨부 칸 | E5: 자체교육 등록 창의 첨부 영역을 보고 [취소] | F5: «교육일지 및 교육사진 등» 한 칸이다
A6: 29 | B6: QA박안전2(재난안전과) | C6: 안전보건교육 > 현업근로자 > 채용시교육 | D6: 탭과 새 근로자 | E6: [전체] · [미이수] · [이수] 탭을 보고 [미이수]에서 «남다슬_근로자01»을 검색한다 | F6: 탭이 셋이고(«교육 건» 탭 없음) «남다슬_근로자01» 줄이 미이수에 있다
A7: 30 | B7: QA박안전2(재난안전과) | C7: 안전보건교육 > 현업근로자 > 채용시교육 | D7: 필요 시간 | E7: 목록의 고용형태·필요시간·상태를 본다 | F7: 필요시간이 일용·1주 이하 1h · 1개월 이하 4h · 그 밖 8h 규칙대로다(«남다슬_근로자01»은 기간제 6개월이라 8h). 상태는 미이수 · 정상 이수 · 지연 이수 중 하나다
A8: 31 | B8: QA박안전2(재난안전과) | C8: 안전보건교육 > 현업근로자 > 채용시교육 | D8: 채용시 교육 추가 | E8: [＋ 채용시 교육 추가] ① 대상자 없이 [교육기록 등록] ② 대상자 부서를 내 부서(건설과)로 거르고 «남다슬_근로자01»만 체크, 시각 09:00~17:00, 내용 «남다슬_채용시교육» → 증빙 없이 [교육기록 등록] ③ «교육일지 및 교육사진 등» 칸에 파일을 넣고 [교육기록 등록] | F8: ① «교육 대상자를 1명 이상 선택하세요.» ② «교육일지 및 교육사진 등 증빙을 첨부하세요.» ③ «1명 교육기록 등록 · 이수 완료 1명» 후 [이수] 탭으로 옮겨 가고 상태가 정상 이수다
A9: 32 | B9: QA박안전2(재난안전과) | C9: 안전보건교육 > 현업근로자 > 채용시교육 | D9: 여러 명 한 번에 | E9: [미이수] 탭 ① 아무도 체크하지 않고 [선택 교육기록 등록 (0)] ② 부서 조건을 내 부서(건설과)로 걸고 10번의 남다슬_근로자A·남다슬_근로자B을 체크 → [선택 교육기록 등록 (2)] ③ 실제 교육일을 비우고 [교육기록 등록] ④ 교육일을 오늘로, 증빙 없이 [교육기록 등록] ⑤ 증빙 파일을 골라 [교육기록 등록] | F9: ① «미이수자를 1명 이상 선택하세요.» ③ «실제 교육일을 입력하세요.» ④ «교육일지·서명부 증빙을 선택하세요.» ⑤ «2명 소급 교육기록 등록 · 이수 완료 2명 · 교육 건 2건 생성»
A10: 33 | B10: QA박안전2(재난안전과) | C10: 안전보건교육 > 현업근로자 > 채용시교육 | D10: 이수 수정·되돌리기 | E10: 31번 «남다슬_근로자01» 줄 ① [이수 수정] → 이수일을 어제로 [저장] ② 다시 [이수 수정] → [이수 기록 삭제] → 확인 창 → [이수 취소] | F10: ① «이수일을 수정했습니다 — (어제 날짜)» ② 확인 창이 회수될 시간을 알려 주고 «이수기록 1건 회수 · 미이수로 되돌렸습니다…», 다시 [미이수]에 있다
A11: 34 | B11: QA하정수2(담당 공무원) | C11: 안전보건교육 > 현업근로자 > 채용시교육 | D11: 내 부서만 보인다 | E11: 목록과 부서 조건을 본다 | F11: 내 부서(건설과) 사람만 보이고 부서 조건에도 내 부서만 있다
A12: 35 | B12: QA박안전2(재난안전과) | C12: 안전보건교육 > 관리감독자 > 채용시교육 | D12: 지정일이 없으면 판정하지 않는다 | E12: [전체] 탭과 [미이수]·[이수] 탭을 차례로 본다 | F12: 위 안내에 «지정일이 등록되지 않은 사람은 '판정 불가'…»가 있다. 지정일 없는 사람은 «판정 불가 — 지정일 미등록»이고 [미이수]·[이수] 어느 탭에도 없다(그래서 전체 숫자가 미이수 + 이수보다 크다). 4번의 «남다슬_관리감독자»는 [미이수]에 있다
A13: 36 | B13: QA박안전2(재난안전과) | C13: 안전보건교육 > 현업근로자 > 기타 교육 | D13: 기타 교육 등록 | E13: [＋ 기타 교육 등록·진행] ① 빈 채로 [진행 처리] ② 교육 분류 «작업내용 변경 시 교육» · 부서는 [조직도]에서 내 부서(건설과) · 내용 «남다슬_기타교육»을 넣고 대상자 없이 [진행 처리] ③ «남다슬_근로자01»을 체크하고 교육 시간 0.5로 [진행 처리] | F13: ① «일자·시각·시간·내용을 모두 입력하세요.» 분류를 고르면 법정 최소 교육시간(1시간 · 2시간)과 근거가 보인다. ② «대상자를 1명 이상 선택하세요.» ③ 막지 않고 «작업내용 변경 시 교육 진행 완료 · 1명 · 법정 최소 미달 1명», 카드에 «법정 최소 미달 1명»
A14: 37 | B14: QA박안전2(재난안전과) | C14: 안전보건교육 > 현업근로자 > 기타 교육 | D14: 특별교육 대상 작업 | E14: ① 분류 «특별교육» · 부서는 [조직도]에서 내 부서(건설과) · 내용 «남다슬_특별교육» · 대상자 «남다슬_근로자01» → 대상 작업 없이 [진행 처리] ② 대상 작업 두 개와 «기타 — 목록에 없어 법령 매핑이 필요한 작업»을 체크하고 그 칸을 그대로 둔 채 [진행 처리] ③ 기타 칸에 내용을 적고 [진행 처리] | F14: ① «특별교육 대상 작업을 1건 이상 선택하세요.» ② «기타 대상 작업 내용을 입력하세요.» ③ «특별교육 진행 완료 · 1명 카운트», 카드에 «대상 작업 3건». 여러 개를 함께 고를 수 있다
A15: 38 | B15: QA박안전2(재난안전과) | C15: 안전보건교육 > 관리감독자 > 기타 교육 | D15: 관리감독자 유형은 다르다 | E15: 등록 창의 교육 분류 목록과 법정 시간을 36번(현업근로자) 창과 비교하고 [취소] | F15: «건설업 기초안전보건교육»이 없고, 작업내용 변경 시 교육은 관리감독자 2시간 · 특별교육은 관리감독자 16시간 한 가지 기준이다
... A17: 40 | B17: QA박안전2(재난안전과) | C17: 안전보건교육 > 관리감독자 > 정기교육 | D17: 관리감독자 정기교육 대상자 | E17: [자체교육 (부서)] → [＋ 자체교육 등록·진행] → 부서를 [조직도]에서 내 부서(건설과)로 바꿔 대상자 목록을 보고 [취소] | F17: 관리감독자만 대상자로 나온다 — 4번의 «남다슬_관리감독자»는 있고 «남다슬_근로자01»은 없다

Sheet 4 이수현황
A1: 안전보건교육 — 4 이수현황
A2: 🗂 2·3번 시트에서 끝낸 교육이 여기 모입니다. 독촉은 내 부서 사람에게만 합니다.
A3: 번호 | B3: 누구로 | C3: 어디서 | D3: 확인할 것 | E3: 해 볼 것 | F3: 이러면 성공 | G3: 결과 ▼ | H3: 메모 (실패·오류·문의일 때) | I3: 사진 (필요할 때 붙여넣기)
A4: 41 | B4: QA박안전2(재난안전과) | C4: 안전보건교육 > 이수현황 | D4: 부서별 요약과 상세 | E4: [부서별 요약]에서 내 부서(건설과) 줄의 대상·완료 인원을 보고 [상세] | F4: 요약의 대상 인원이 상세 목록 인원과, 완료 인원이 상세의 «완료» 수와 같다
A5: 42 | B5: QA박안전2(재난안전과) | C5: 안전보건교육 > 이수현황 | D5: 대상 없는 부서 | E5: 구분 조건을 «판매»로 걸고 대상 인원이 0명인 부서 줄을 본다 → [필터 초기화] | F5: 0명인 부서의 완료율이 0%가 아니라 «대상 없음»이다. 0명인 부서가 없으면 «확인 불가»
A6: 43 | B6: QA박안전2(재난안전과) | C6: 안전보건교육 > 이수현황 | D6: 시간 계산 | E6: [대상자별 상세]에서 «남다슬_근로자01»을 검색해 필요·인정·미달·정기를 본다 | F6: 필요 12h · 인정 13h(13번 집합 3h + 27번 자체 10h) · 미달 0h(음수가 아니다) · 정기 «완료»
A7: 44 | B7: QA박안전2(재난안전과) | C7: 안전보건교육 > 이수현황 | D7: 여러 조건 | E7: [대상자별 상세]에서 부서·구분·고용형태·이수 상태를 함께 건다 → [필터 초기화] | F7: 조건대로 걸러지고 위 «조회 대상 …» 표시가 건 구분·고용형태를 보여 준다. 초기화하면 전체로 돌아온다
A8: 45 | B8: QA하정수2(담당 공무원) | C8: 안전보건교육 > 이수현황 | D8: 남의 부서 상세는 못 본다 | E8: [부서별 요약]을 본다 | F8: 내 부서 줄에만 [상세]가 있고 다른 줄은 «—»다(버튼이 있는데 누르면 거절되면 실패). 다른 부서의 합계 숫자는 보인다
A9: 46 | B9: QA박안전2(재난안전과) | C9: 안전보건교육 > 이수현황 | D9: 독촉 | E9: [대상자별 상세] ① 아무도 체크하지 않고 [일괄 독촉 (0)] ② 부서를 내 부서(건설과)로 걸고 10번의 남다슬_근로자A·남다슬_근로자B을 체크 → [일괄 독촉 (2)] → [독촉 발송] ③ [📜 독촉 이력] | F9: ① «미이수자를 1명 이상 선택하세요.» ② «1개 부서, 2명 독촉 알림 기록 완료 (실제 문자·메일 미발송)» ③ 이력에 내 부서 2명 줄이 있고 발신이 내 QA박안전2 계정 이름이다
A10: 47 | B10: QA박안전2(재난안전과) | C10: 안전보건교육 > 이수현황 | D10: 이수 확인서 | E10: 43번의 «남다슬_근로자01» 줄 [발급] | F10: 보고서·제증명 화면이 열리고 발급 대상자에 «남다슬_근로자01 · 건설과»가 채워져 있다

Sheet 5 공문·결재 이력
A1: 안전보건교육 — 5 공문·결재 이력
A2: 🗂 적힌 순서대로 합니다 — 49번(QA하정수2)은 13번 교육 공문을 올리기 전에 봅니다. 상신하면 바로 «결재완료»(내부 처리)로 끝납니다. 검토·결재에 넣을 다른 두 사람의 박안전 계정은 단체방에서 미리 정해 둡니다.
A3: 번호 | B3: 누구로 | C3: 어디서 | D3: 확인할 것 | E3: 해 볼 것 | F3: 이러면 성공 | G3: 결과 ▼ | H3: 메모 (실패·오류·문의일 때) | I3: 사진 (필요할 때 붙여넣기)
A4: 48 | B4: QA박안전2(재난안전과) | C4: 안전보건교육 > 현업근로자 > 정기교육 | D4: 끝난 교육만 공문을 쓴다 | E4: 14번(진행 중)과 13번(종료) 교육 카드를 비교한다 | F4: 진행 중인 14번 카드에는 [공문 기안]이 없고, 종료된 13번 카드에만 [공문 기안]이 있다
A5: 49 | B5: QA하정수2(담당 공무원) | C5: 안전보건교육 > 현업근로자 > 정기교육 | D5: 공문은 교육을 등록한 부서가 쓴다 | E5: ① 27번 자체교육 카드 ② 13번 집합교육 카드를 본다(누르지 않는다) | F5: 27번 카드에는 [공문 기안]이 있다. 13번 카드에는 버튼 대신 «여러 부서를 묶은 건이라 재난안전과 담당자가 기안합니다.»가 보인다
A6: 50 | B6: QA박안전2(재난안전과) | C6: 안전보건교육 > 현업근로자 > 정기교육 | D6: 결재선 — 같은 사람을 두 번 못 넣는다 | E6: 13번 교육 [공문 기안] ① 결재 [조직도]에서 단체방에서 정한 결재 담당 박안전 계정(내 번호가 아닌 것)을 고른다 ② 검토 [조직도]를 열어 내 이름과 ①의 사람을 찾는다 ③ [＋ 검토]로 빈 칸을 더하고 본문을 한 줄 쓴 뒤 [문서 미리보기 →] ④ [← 수정] → 더한 칸 [×] → [닫기](상신하지 않는다) | F6: ② 내 이름은 «기안자», ①의 사람은 «결재 지정됨»으로 흐리게 나와 고를 수 없다 ③ 결재선 아래 «결재선을 확인하세요»가 뜨고, 미리보기에는 [온나라로 결재 상신] 대신 «지정하지 않은 단계가 …건 있습니다…»가 나온다
A7: 51 | B7: QA박안전2(재난안전과) | C7: 안전보건교육 > 현업근로자 > 정기교육 | D7: 공문 쓰기 → 미리보기 → 상신 | E7: 13번 교육 [공문 기안] ① 제목을 지우고 [문서 미리보기 →] ② 제목을 «2026년 안전보건교육 실시 결과 보고 — 남다슬_집합교육»으로 다시 넣고 본문 없이 [문서 미리보기 →] ③ 본문을 직접 쓰고(삽입 조각도 눌러 본다) 붙임을 체크한다 ④ 결재선 검토·결재에 단체방에서 정한 다른 두 사람의 박안전 계정을 고른다 — 처음 채워져 있는 기본값(실제 직원)은 반드시 바꾼다 ⑤ [문서 미리보기 →] → [온나라로 결재 상신] → [상신] | F7: ① «공문 제목을 입력하세요.» ② «공문 본문을 입력하세요.» 기안 창에는 상신 버튼이 없고 붙임은 올려 둔 파일에서 체크만 한다(새로 올리는 칸 없음). 상신하면 바로 «결재완료»가 되고 «내부 처리»로 표시된다
A8: 52 | B8: QA박안전2(재난안전과) | C8: 안전보건교육 > 현업근로자 > 정기교육 | D8: 상신 뒤에는 잠긴다 | E8: ① 13번 교육 카드의 [수정]·[삭제] 자리를 본다 ② 상세 → 신청현황의 내 부서 줄을 본다 | F8: 카드에 [수정]·[삭제] 대신 잠금(🔒) 표시만 있고, 상세의 내 부서 줄도 잠겨 있다(정정까지 잠겨야 성공). [＋ 정정 등록부 추가]도 없다
A9: 53 | B9: QA박안전2(재난안전과) | C9: 안전보건교육 > 현업근로자 > 정기교육 | D9: 잠금 안내 문구 | E9: 52번에서 연 상세의 잠금 안내와 교육 카드의 잠금 버튼 설명(마우스를 올리면 나온다)을 읽는다 | F9: 잠긴 이유(공문이 결재된 교육)를 알려 준다
A10: 54 | B10: QA박안전2(재난안전과) | C10: 안전보건교육 > 현업근로자 > 채용시교육 | D10: 채용시교육 공문 | E10: [이수] 탭에서 부서 조건을 내 부서(건설과)로 걸고 32번의 남다슬_근로자A 줄 [공문 기안] → 창 제목을 보고 [닫기](상신하지 않는다) | F10: 남다슬_근로자A이 들은 교육 건의 공문 기안 창이 열린다(창 제목 끝이 «· 남다슬_근로자A»)
A11: 55 | B11: QA박안전2(재난안전과) | C11: 안전보건교육 > 결재 이력 | D11: 결재 이력 | E11: ① 검색창에 «남다슬_집합교육»을 친다 ② 그 줄의 [문서]를 누른다 | F11: 51번 공문이 결재완료 · «내부 처리»로 있고 [문서]로 열린다. 승인·반려 버튼은 없다

Sheet 6 부서 담당자·다시 로그인
A1: 안전보건교육 — 6 부서 담당자·다시 로그인
A2: 🗂 QA하정수2 창에서 내 부서 화면을 보고, 마지막으로 로그인이 끊긴 뒤 다시 들어오는 것을 봅니다.
A3: 번호 | B3: 누구로 | C3: 어디서 | D3: 확인할 것 | E3: 해 볼 것 | F3: 이러면 성공 | G3: 결과 ▼ | H3: 메모 (실패·오류·문의일 때) | I3: 사진 (필요할 때 붙여넣기)
A4: 56 | B4: QA하정수2(담당 공무원) | C4: 안전보건교육 (자체·기타·채용시 등록 창) | D4: 부서 칸 고정 | E4: ① 정기교육 [자체교육 (부서)] 등록 창 ② 기타 교육 등록 창 ③ 채용시교육 [＋ 채용시 교육 추가] 창을 차례로 열어 보고 [취소] | F4: ①② 부서가 내 부서(건설과)로 고정돼 있고 [조직도]가 없다 ③ 대상자 목록에 내 부서 사람만 있다
A5: 57 | B5: QA하정수2(담당 공무원) | C5: 대시보드 > 내 할일 | D5: 교육 할 일 카드 | E5: ① «남다슬_집합교육_2일 — 참석자 등록부 등록 필요» 카드의 [신청하러 가기] ② 뒤로 돌아와 «… — 안전보건교육 미이수 (독촉)» 카드를 찾는다 | F5: ① 목록이 아니라 14번 교육의 상세로 바로 간다 ② 46번에서 독촉한 남다슬_근로자A·남다슬_근로자B 카드가 있다
A6: 58 | B6: QA박안전2(재난안전과) | C6: 안전보건교육 > 현업근로자 > 정기교육 | D6: 로그인이 끊긴 뒤 | E6: 등록 창에 값을 적은 채 로그인 시간(30분)이 끝나기를 기다렸다가 저장을 눌러 본다 → 다시 로그인 | F6: 로그인하라는 화면으로 가고 오류 창이 뜨지 않는다. 다시 로그인하면 교육 화면을 이어서 쓸 수 있다(적던 값이 사라지는 것은 메모)

Sheet _정보
A1: 형식 | B1: QA엑셀 v1.1
A2: 메뉴 | B2: 안전보건교육
A3: 담당자 | B3: 남다슬
A4: 파일 코드 | B4: ED
A5: 종류 | B5: 상세
A6: 생성일 | B6: 2026-09-30
A7: 결과 값 | B7: 성공,실패,오류,보류,확인 불가,문의
A8: 머리 행 | B8: 3
A9: 열 | B9: 번호,누구로,어디서,확인할,해,이러면,결과,메모,사진
