Workbook

Sheet 안내
A1: QA 담양 중대재해 — 통계·보고 · 용한빛
A3: 메뉴 | B3: 통계·보고 (훑어보는 파일)
A4: 담당자 | B4: 용한빛
A5: 내 계정 | B5: QA박안전4 (재난안전과 담당자) · QA하정수4 (내 부서 담양읍 담당 공무원)
A6: 이 파일 | B6: 현황 통계 · 보고서·제증명 · 정보센터를 봅니다. 모두 QA박안전4 계정으로 합니다. 내려받기·출력은 아직 연계 전이라 안내가 뜨는 것이 정상입니다.
A7: 줄 수 | B7: 8줄
A8: 시트 | B8: 현황 통계 → 보고서·제증명 → 정보센터
A9: 테스트 주소 | B9: https://safety.damyang.go.kr/login
A10: 브라우저
A11: 기기
A12: 시작한 날
A14: 이렇게 하면 됩니다
A15: ① 위 «테스트 주소»에서 받은 아이디·비밀번호로 로그인합니다. 로그인하면 통합 현황 화면으로 갑니다. 5번 틀리면 계정이 잠깁니다 — 담당 개발자에게 풀어 달라고 합니다.
A16: ② 내 계정 두 개를 창 두 개에 따로 로그인해 둡니다 — 일반 창에는 QA박안전4(재난안전과), 시크릿 창(Ctrl + Shift + N · 맥 Cmd + Shift + N)에는 QA하정수4(담당 공무원). 두 창을 나란히 두면 계정을 바꿀 필요가 없습니다.
A17: ③ «누구로» 칸에 적힌 계정의 창에서 «어디서» 메뉴로 가서 «해 볼 것»대로 눌러 봅니다.
A18: ④ «이러면 성공»과 같으면 «결과» 칸에서 성공을, 다르면 실패·오류 등을 고릅니다.
A19: ⑤ 실패·오류·문의면 «메모»에 한 줄 적고, 필요하면 «사진» 칸에 화면 캡처를 붙여넣습니다.
A21: 결과 고르는 법
A22: 결과 | B22: 이럴 때 고르세요
A23: 성공 | B23: «이러면 성공»대로 된다
A24: 실패 | B24: 되긴 하는데 설명과 다르다 — 막혀야 하는데 저장된다, 문구·숫자가 틀리다
A25: 오류 | B25: 화면이 멈추거나 깨진다, 눌러도 아무 일이 없다, 오류 창이 뜬다
A26: 보류 | B26: 앞 단계가 안 돼서 지금은 못 한다 — 메모에 이유
A27: 확인 불가 | B27: 이 환경에서는 볼 수 없다 — 예: 확인할 데이터가 없다
A28: 문의 | B28: 맞는지 헷갈린다 — 메모에 궁금한 점
A30: 사진 붙이는 법
A31: • 윈도우: Win + Shift + S → 영역 선택 → 엑셀에서 그 줄의 «사진» 칸을 누르고 Ctrl + V
A32: • 맥: Cmd + Ctrl + Shift + 4 → 영역 선택 → 엑셀에서 그 줄의 «사진» 칸을 누르고 Cmd + V
A33: • 사진이 크면 모서리를 끌어 줄이세요. 사진은 그 줄 «사진» 칸 위에 두면 됩니다 — 취합할 때 줄 번호로 찾습니다.
A34: • 사진은 떠 있는 그대로 두세요(«셀에 배치»로 넣으면 취합할 때 꺼내지 못합니다).
A36: 누구로 — 내 계정 두 개
A37: • 계정은 두 개뿐입니다. «누구로» 칸에 계정 이름과 권한이 함께 적혀 있습니다. 비밀번호는 따로 받습니다.
A38: 이름 | B38: 권한 | D38: 볼 수 있는 것 | F38: 주로 하는 것
A39: QA박안전4 | B39: 재난안전과 담당자 | D39: 모든 부서 · «내 할일»은 전체 | F39: 전 부서 등록·수정 · 확인 · 상신 · 독촉 — 대부분 이 계정
A40: QA하정수4 | B40: 담당 공무원 (내 부서: 담양읍) | D40: 업무 화면은 전 부서, «내 할일»은 나에게 지정된 것만, 위험성평가 부서별 조치표·교육 이수현황은 내 부서만 | F40: 내 부서 일 · 남의 부서 것을 못 건드리는지 확인
A41: QA시스템관리 | B41: 시스템 관리자 (김유석만) | D41: 시스템 관리 메뉴 | F41: 시스템 관리 파일 · 공문 반려(결재 대행)
A43: 같은 서버를 6명이 함께 씁니다
A44: • 내가 만드는 것(교육 · 근로자 · 문서 · 위원 등)은 이름 앞에 내 이름을 붙입니다 — 예: «용한빛_집합교육». 그래야 내 것을 찾기 쉽습니다.
A45: • 다른 사람이 만든 것은 고치거나 지우지 않습니다. QA박안전4 계정에는 남의 것도 보이는데, 정상입니다.
A46: • 건수·이수율 같은 숫자는 다른 사람이 작업하는 동안 바뀔 수 있습니다. 숫자가 안 맞으면 새로고침해서 한 번 더 보고, 그래도 다르면 «실패».
...

Sheet 요약
A1: 진행 상황 — 통계·보고 · 용한빛
A2: 결과를 고르면 저절로 채워집니다. 남은 것 = 아직 결과를 고르지 않은 줄입니다.
A4: 시트 | B4: 전체 | C4: 성공 | D4: 실패 | E4: 오류 | F4: 보류 | G4: 확인 불가 | H4: 문의 | I4: 남은 것 | J4: 진행률
A5: 현황 통계 | B5: =COUNTA('현황 통계'!$A$4:$A$6) -> 3 | C5: =COUNTIF('현황 통계'!$G$4:$G$6,"성공") -> 0 | D5: =COUNTIF('현황 통계'!$G$4:$G$6,"실패") -> 0 | E5: =COUNTIF('현황 통계'!$G$4:$G$6,"오류") -> 0 | F5: =COUNTIF('현황 통계'!$G$4:$G$6,"보류") -> 0 | G5: =COUNTIF('현황 통계'!$G$4:$G$6,"확인 불가") -> 0 | H5: =COUNTIF('현황 통계'!$G$4:$G$6,"문의") -> 0 | I5: =COUNTBLANK('현황 통계'!$G$4:$G$6) -> 3 | J5: =IF(B5=0,0,(B5-I5)/B5) -> 0
A6: 보고서·제증명 | B6: =COUNTA('보고서·제증명'!$A$4:$A$7) -> 4 | C6: =COUNTIF('보고서·제증명'!$G$4:$G$7,"성공") -> 0 | D6: =COUNTIF('보고서·제증명'!$G$4:$G$7,"실패") -> 0 | E6: =COUNTIF('보고서·제증명'!$G$4:$G$7,"오류") -> 0 | F6: =COUNTIF('보고서·제증명'!$G$4:$G$7,"보류") -> 0 | G6: =COUNTIF('보고서·제증명'!$G$4:$G$7,"확인 불가") -> 0 | H6: =COUNTIF('보고서·제증명'!$G$4:$G$7,"문의") -> 0 | I6: =COUNTBLANK('보고서·제증명'!$G$4:$G$7) -> 4 | J6: =IF(B6=0,0,(B6-I6)/B6) -> 0
A7: 정보센터 | B7: =COUNTA('정보센터'!$A$4:$A$4) -> 1 | C7: =COUNTIF('정보센터'!$G$4:$G$4,"성공") -> 0 | D7: =COUNTIF('정보센터'!$G$4:$G$4,"실패") -> 0 | E7: =COUNTIF('정보센터'!$G$4:$G$4,"오류") -> 0 | F7: =COUNTIF('정보센터'!$G$4:$G$4,"보류") -> 0 | G7: =COUNTIF('정보센터'!$G$4:$G$4,"확인 불가") -> 0 | H7: =COUNTIF('정보센터'!$G$4:$G$4,"문의") -> 0 | I7: =COUNTBLANK('정보센터'!$G$4:$G$4) -> 1 | J7: =IF(B7=0,0,(B7-I7)/B7) -> 0
A8: 합계 | B8: =SUM(B5:B7) -> 8 | C8: =SUM(C5:C7) -> 0 | D8: =SUM(D5:D7) -> 0 | E8: =SUM(E5:E7) -> 0 | F8: =SUM(F5:F7) -> 0 | G8: =SUM(G5:G7) -> 0 | H8: =SUM(H5:H7) -> 0 | I8: =SUM(I5:I7) -> 8 | J8: =IF(B8=0,0,(B8-I8)/B8) -> 0

Sheet 현황 통계
A1: 통계·보고 — 현황 통계
A2: 🗂 QA박안전4 창에서 합니다. 숫자가 안 맞으면 새로고침 후 다시 봅니다.
A3: 번호 | B3: 누구로 | C3: 어디서 | D3: 확인할 것 | E3: 해 볼 것 | F3: 이러면 성공 | G3: 결과 ▼ | H3: 메모 (실패·오류·문의일 때) | I3: 사진 (필요할 때 붙여넣기)
A4: 1 | B4: QA박안전4(재난안전과) | C4: 통계·보고 > 현황 통계 | D4: 조건 바꾸기 | E4: 연도 · 기간 · 대메뉴 조건을 하나씩 바꾼다 | F4: 위 숫자 · 분포 · 표가 함께 바뀌고, «조회 문서 전체» 숫자와 «대메뉴별 문서 분포 (N건)»의 N이 늘 같다
A5: 2 | B5: QA박안전4(재난안전과) | C5: 통계·보고 > 현황 통계 | D5: 분야를 누르면 문서 목록으로 | E5: ① 연도 · 기간 · 대메뉴를 모두 «전체»로 둔다 ② 아래 «대메뉴별 이행 현황표»의 첫 칸에서 대메뉴 이름(예: 위험성평가)을 누른다 | F5: 업무 관리 문서 목록이 열리고 위에 «분야 위험성평가 문서 N건» 조건이 붙는다. N이 그 줄의 «전체» 칸 숫자와 같고, 조건의 ×로 풀 수 있다
A6: 3 | B6: QA박안전4(재난안전과) | C6: 통계·보고 > 현황 통계 | D6: 내려받기 · 신고 현황 | E6: ① [엑셀 다운로드] ② [신고 현황] | F6: «통계 엑셀 내려받기는 집계 원본 확정 후 제공됩니다»가 뜬다. [신고 현황]은 의견청취·건의함 화면으로 간다

Sheet 보고서·제증명
A1: 통계·보고 — 보고서·제증명
A2: 🗂 QA박안전4 창에서 합니다. 7번은 6번에서 새로 생긴 발급번호로 합니다.
A3: 번호 | B3: 누구로 | C3: 어디서 | D3: 확인할 것 | E3: 해 볼 것 | F3: 이러면 성공 | G3: 결과 ▼ | H3: 메모 (실패·오류·문의일 때) | I3: 사진 (필요할 때 붙여넣기)
A4: 4 | B4: QA박안전4(재난안전과) | C4: 통계·보고 > 보고서·제증명 | D4: 보고서 조건과 미리보기 | E4: ① 보고서 종류를 «총괄보고서» → «위험성평가 결과 보고서» → «이행사실 확인서(제증명)»로 바꾼다 ② 시작일 · 종료일을 바꾼다 ③ 종료일을 내일로 바꿔 본다 ④ 종료일을 오늘로 되돌린다 | F4: 미리보기 제목이 고른 종류와 기간으로 바뀌고 조건 칸이 겹치지 않는다. 확인서를 고르면 [온나라 결재]가 사라지고 대상 칸이 생긴다. 종료일이 내일이면 «시작일은 종료일보다 늦을 수 없고 미래일을 선택할 수 없습니다.»가 뜬다
A5: 5 | B5: QA박안전4(재난안전과) | C5: 통계·보고 > 보고서·제증명 | D5: 대상자 고르기 | E5: ① 보고서 종류 «개인 안전보건교육 이수 확인서» ② 대상자 없이 [PDF 출력] ③ [대상자 선택] → 이수현황의 [대상자별 상세] → 이수 상태 «완료» ④ 한 사람의 [발급] | F5: 대상자가 없으면 «이수현황에서 발급 대상자를 먼저 선택하세요.» [발급]을 누르면 보고서·제증명으로 돌아와 발급 대상자에 그 사람이 채워지고 미리보기 판정이 «이수 완료»다. 이수 완료자가 없으면 «확인 불가»
A6: 6 | B6: QA박안전4(재난안전과) | C6: 통계·보고 > 보고서·제증명 | D6: 출력 · 결재 | E6: ① 보고서 종류 «총괄보고서» ② [온나라 결재] ③ [PDF 출력] ④ 출력 이력에서 출력자가 내 QA박안전4 계정이고 방금 시각인 줄의 발급번호를 메모에 적는다 | F6: 둘 다 «… — 파일·결재 생성은 전자문서 연계 후 적용됩니다.»가 뜬다. [온나라 결재]는 출력 이력을 늘리지 않고, [PDF 출력]은 출력 이력에 새 발급번호 줄을 남긴다(출력자는 QA박안전4 계정)
A7: 7 | B7: QA박안전4(재난안전과) | C7: 통계·보고 > 보고서·제증명 | D7: 발급번호 확인 | E7: ① «발급번호 진위확인»에 6번에서 적은 번호를 넣고 [조회] ② 없는 번호(예: DY-1999-9999)로 [조회] | F7: 있는 번호는 «발급 이력 확인»과 보고서 종류 · 발급일 · 출력자가, 없는 번호는 «일치하는 발급 이력이 없습니다.»가 나온다

Sheet 정보센터
A1: 통계·보고 — 정보센터
A2: 🗂 QA박안전4 창에서 합니다.
A3: 번호 | B3: 누구로 | C3: 어디서 | D3: 확인할 것 | E3: 해 볼 것 | F3: 이러면 성공 | G3: 결과 ▼ | H3: 메모 (실패·오류·문의일 때) | I3: 사진 (필요할 때 붙여넣기)
A4: 8 | B4: QA박안전4(재난안전과) | C4: 통계·보고 > 정보센터 | D4: 탭과 안내 | E4: ① [공지사항] · [자료실] · [우수사례] 탭을 누른다 ② 통합검색의 [검색] ③ [자료실]의 [다운로드] | F4: 세 탭이 바뀌어 뜬다. [검색]은 «통합검색은 자료 색인 구축 후 제공됩니다», [다운로드]는 «자료 내려받기는 자료실 파일 등록 후 제공됩니다»가 뜬다

Sheet _정보
A1: 형식 | B1: QA엑셀 v1.1
A2: 메뉴 | B2: 통계·보고
A3: 담당자 | B3: 용한빛
A4: 파일 코드 | B4: ST
A5: 종류 | B5: 스모크
A6: 생성일 | B6: 2026-09-30
A7: 결과 값 | B7: 성공,실패,오류,보류,확인 불가,문의
A8: 머리 행 | B8: 3
A9: 열 | B9: 번호,누구로,어디서,확인할,해,이러면,결과,메모,사진
