Workbook

Sheet 안내
A1: QA 담양 중대재해 — 의견청취 · 용한빛
A3: 메뉴 | B3: 의견청취 (훑어보는 파일)
A4: 담당자 | B4: 용한빛
A5: 내 계정 | B5: QA박안전4 (재난안전과 담당자) · QA하정수4 (내 부서 담양읍 담당 공무원)
A6: 이 파일 | B6: 의견청취·건의함 · 산업안전보건위원회 · 협의체·점검표를 봅니다. 대부분 QA박안전4 계정으로 합니다. 이 메뉴는 아직 부서 구분이 없어 QA하정수4 계정에도 모든 자료와 버튼이 보이는 것이 정상입니다.
A7: 줄 수 | B7: 15줄
A8: 시트 | B8: 의견청취·건의함 → 산업안전보건위원회 → 협의체·점검표
A9: 테스트 주소 | B9: https://safety.damyang.go.kr/login
A10: 브라우저
A11: 기기
A12: 시작한 날
A14: 이렇게 하면 됩니다
A15: ① 위 «테스트 주소»에서 받은 아이디·비밀번호로 로그인합니다. 로그인하면 통합 현황 화면으로 갑니다. 5번 틀리면 계정이 잠깁니다 — 담당 개발자에게 풀어 달라고 합니다.
A16: ② 내 계정 두 개를 창 두 개에 따로 로그인해 둡니다 — 일반 창에는 QA박안전4(재난안전과), 시크릿 창(Ctrl + Shift + N · 맥 Cmd + Shift + N)에는 QA하정수4(담당 공무원). 두 창을 나란히 두면 계정을 바꿀 필요가 없습니다.
A17: ③ «누구로» 칸에 적힌 계정의 창에서 «어디서» 메뉴로 가서 «해 볼 것»대로 눌러 봅니다.
A18: ④ «이러면 성공»과 같으면 «결과» 칸에서 성공을, 다르면 실패·오류 등을 고릅니다.
A19: ⑤ 실패·오류·문의면 «메모»에 한 줄 적고, 필요하면 «사진» 칸에 화면 캡처를 붙여넣습니다.
A21: 결과 고르는 법
A22: 결과 | B22: 이럴 때 고르세요
A23: 성공 | B23: «이러면 성공»대로 된다
A24: 실패 | B24: 되긴 하는데 설명과 다르다 — 막혀야 하는데 저장된다, 문구·숫자가 틀리다
A25: 오류 | B25: 화면이 멈추거나 깨진다, 눌러도 아무 일이 없다, 오류 창이 뜬다
A26: 보류 | B26: 앞 단계가 안 돼서 지금은 못 한다 — 메모에 이유
A27: 확인 불가 | B27: 이 환경에서는 볼 수 없다 — 예: 확인할 데이터가 없다
A28: 문의 | B28: 맞는지 헷갈린다 — 메모에 궁금한 점
A30: 사진 붙이는 법
A31: • 윈도우: Win + Shift + S → 영역 선택 → 엑셀에서 그 줄의 «사진» 칸을 누르고 Ctrl + V
A32: • 맥: Cmd + Ctrl + Shift + 4 → 영역 선택 → 엑셀에서 그 줄의 «사진» 칸을 누르고 Cmd + V
A33: • 사진이 크면 모서리를 끌어 줄이세요. 사진은 그 줄 «사진» 칸 위에 두면 됩니다 — 취합할 때 줄 번호로 찾습니다.
A34: • 사진은 떠 있는 그대로 두세요(«셀에 배치»로 넣으면 취합할 때 꺼내지 못합니다).
A36: 누구로 — 내 계정 두 개
A37: • 계정은 두 개뿐입니다. «누구로» 칸에 계정 이름과 권한이 함께 적혀 있습니다. 비밀번호는 따로 받습니다.
A38: 이름 | B38: 권한 | D38: 볼 수 있는 것 | F38: 주로 하는 것
A39: QA박안전4 | B39: 재난안전과 담당자 | D39: 모든 부서 · «내 할일»은 전체 | F39: 전 부서 등록·수정 · 확인 · 상신 · 독촉 — 대부분 이 계정
A40: QA하정수4 | B40: 담당 공무원 (내 부서: 담양읍) | D40: 업무 화면은 전 부서, «내 할일»은 나에게 지정된 것만, 위험성평가 부서별 조치표·교육 이수현황은 내 부서만 | F40: 내 부서 일 · 남의 부서 것을 못 건드리는지 확인
A41: QA시스템관리 | B41: 시스템 관리자 (김유석만) | D41: 시스템 관리 메뉴 | F41: 시스템 관리 파일 · 공문 반려(결재 대행)
A43: 같은 서버를 6명이 함께 씁니다
A44: • 내가 만드는 것(교육 · 근로자 · 문서 · 위원 등)은 이름 앞에 내 이름을 붙입니다 — 예: «용한빛_집합교육». 그래야 내 것을 찾기 쉽습니다.
A45: • 다른 사람이 만든 것은 고치거나 지우지 않습니다. QA박안전4 계정에는 남의 것도 보이는데, 정상입니다.
A46: • 건수·이수율 같은 숫자는 다른 사람이 작업하는 동안 바뀔 수 있습니다. 숫자가 안 맞으면 새로고침해서 한 번 더 보고, 그래도 다르면 «실패».
...

Sheet 요약
A1: 진행 상황 — 의견청취 · 용한빛
A2: 결과를 고르면 저절로 채워집니다. 남은 것 = 아직 결과를 고르지 않은 줄입니다.
A4: 시트 | B4: 전체 | C4: 성공 | D4: 실패 | E4: 오류 | F4: 보류 | G4: 확인 불가 | H4: 문의 | I4: 남은 것 | J4: 진행률
A5: 의견청취·건의함 | B5: =COUNTA('의견청취·건의함'!$A$4:$A$8) -> 5 | C5: =COUNTIF('의견청취·건의함'!$G$4:$G$8,"성공") -> 0 | D5: =COUNTIF('의견청취·건의함'!$G$4:$G$8,"실패") -> 0 | E5: =COUNTIF('의견청취·건의함'!$G$4:$G$8,"오류") -> 0 | F5: =COUNTIF('의견청취·건의함'!$G$4:$G$8,"보류") -> 0 | G5: =COUNTIF('의견청취·건의함'!$G$4:$G$8,"확인 불가") -> 0 | H5: =COUNTIF('의견청취·건의함'!$G$4:$G$8,"문의") -> 0 | I5: =COUNTBLANK('의견청취·건의함'!$G$4:$G$8) -> 5 | J5: =IF(B5=0,0,(B5-I5)/B5) -> 0
A6: 산업안전보건위원회 | B6: =COUNTA('산업안전보건위원회'!$A$4:$A$7) -> 4 | C6: =COUNTIF('산업안전보건위원회'!$G$4:$G$7,"성공") -> 0 | D6: =COUNTIF('산업안전보건위원회'!$G$4:$G$7,"실패") -> 0 | E6: =COUNTIF('산업안전보건위원회'!$G$4:$G$7,"오류") -> 0 | F6: =COUNTIF('산업안전보건위원회'!$G$4:$G$7,"보류") -> 0 | G6: =COUNTIF('산업안전보건위원회'!$G$4:$G$7,"확인 불가") -> 0 | H6: =COUNTIF('산업안전보건위원회'!$G$4:$G$7,"문의") -> 0 | I6: =COUNTBLANK('산업안전보건위원회'!$G$4:$G$7) -> 4 | J6: =IF(B6=0,0,(B6-I6)/B6) -> 0
A7: 협의체·점검표 | B7: =COUNTA('협의체·점검표'!$A$4:$A$9) -> 6 | C7: =COUNTIF('협의체·점검표'!$G$4:$G$9,"성공") -> 0 | D7: =COUNTIF('협의체·점검표'!$G$4:$G$9,"실패") -> 0 | E7: =COUNTIF('협의체·점검표'!$G$4:$G$9,"오류") -> 0 | F7: =COUNTIF('협의체·점검표'!$G$4:$G$9,"보류") -> 0 | G7: =COUNTIF('협의체·점검표'!$G$4:$G$9,"확인 불가") -> 0 | H7: =COUNTIF('협의체·점검표'!$G$4:$G$9,"문의") -> 0 | I7: =COUNTBLANK('협의체·점검표'!$G$4:$G$9) -> 6 | J7: =IF(B7=0,0,(B7-I7)/B7) -> 0
A8: 합계 | B8: =SUM(B5:B7) -> 15 | C8: =SUM(C5:C7) -> 0 | D8: =SUM(D5:D7) -> 0 | E8: =SUM(E5:E7) -> 0 | F8: =SUM(F5:F7) -> 0 | G8: =SUM(G5:G7) -> 0 | H8: =SUM(H5:H7) -> 0 | I8: =SUM(I5:I7) -> 15 | J8: =IF(B8=0,0,(B8-I8)/B8) -> 0

Sheet 의견청취·건의함
A1: 의견청취 — 의견청취·건의함
A2: 🗂 QA박안전4 창에서 하고, 3번만 QA하정수4 창을 함께 씁니다. 의견 제목 앞에 내 이름을 붙이고, 처리는 내가 쓴 의견에만 합니다. 다른 사람도 같은 시간에 의견을 올리므로 숫자를 비교하기 전에 새로고침합니다.
A3: 번호 | B3: 누구로 | C3: 어디서 | D3: 확인할 것 | E3: 해 볼 것 | F3: 이러면 성공 | G3: 결과 ▼ | H3: 메모 (실패·오류·문의일 때) | I3: 사진 (필요할 때 붙여넣기)
A4: 1 | B4: QA박안전4(재난안전과) | C4: 의견청취 > 의견청취·건의함 | D4: 목록 · 상태 칩 · 검색 · 쪽 넘기기 | E4: ① 새로고침한다 ② 상태 칩(전체 · 접수대기 · 점검중 · 개선조치중 · 완료)을 하나씩 누른다 ③ 검색창에 제목 일부를 넣고 Enter ④ 아래 쪽 번호를 넘긴다 | F4: 새로고침 후 칩을 누르면 그 상태만 남고, 칩 숫자와 목록 아래 «총 N건»이 같다. 검색 · 쪽 넘기기가 된다
A5: 2 | B5: QA박안전4(재난안전과) | C5: 의견청취 > 의견청취·건의함 | D5: 의견 등록 | E5: ① [+ 의견 등록] ② 빈 칸으로 [등록하기] ③ 분류를 고르고 제목 «용한빛_계단 난간 흔들림», 상세 내용을 채워 [등록하기] ④ 검색창에 «용한빛_계단»을 넣는다 | F5: 빈 칸이면 «분류를 선택하세요»처럼 무엇을 채울지 알려 준다. 등록하면 «의견이 등록되었습니다» 후 목록에 내 의견이 «접수대기»로 보인다
A6: 3 | B6: QA하정수4(담당 공무원) → QA박안전4(재난안전과) | C6: 의견청취 > 의견청취·건의함 | D6: 담당 공무원의 의견 등록 | E6: ① QA하정수4 창에서 [+ 의견 등록] → 제목 «용한빛_하정수 의견»으로 등록 ② QA박안전4 창에서 새로고침 → 검색창에 «용한빛_하정수»를 넣는다 | F6: QA하정수4 계정에서도 등록된다(다른 부서 의견도 함께 보이는 것은 이 메뉴에 부서 구분이 없어서라 정상). QA박안전4 창에서 «용한빛_하정수 의견» 줄이 «접수대기»로 보인다
A7: 4 | B7: QA박안전4(재난안전과) | C7: 의견청취 > 의견청취·건의함 | D7: 상세 보기 | E7: ① 2번에서 쓴 내 의견 줄을 누른다 ② 목록 줄과 상세 내용을 비교한다 | F7: 상세가 열리고, 제목 · 분류 · 상태가 목록 줄과 같다
A8: 5 | B8: QA박안전4(재난안전과) | C8: 의견청취 > 의견청취·건의함 | D8: 처리 · 완료 | E8: ① 4번에서 연 내 의견 상세에서 조치 방법을 고르기 전 [저장]을 본다 ② «현장점검 실시»를 고르고 [저장] ③ [완료 처리] → 처리 결과를 적고 [완료 처리] ④ 목록에서 «완료» 칩을 누른다 | F8: 조치 방법을 고르기 전에는 [저장]이 흐리게 눌리지 않는다. 상태가 «점검중» → «완료»로 바뀌고 처리 이력에 차례로 남는다. «완료» 칩 목록에 내 의견이 있다

Sheet 산업안전보건위원회
A1: 의견청취 — 산업안전보건위원회
A2: 🗂 QA박안전4 창에서 합니다. 위원 명단은 모두가 함께 쓰는 하나뿐이라, 위원은 내 QA하정수4 계정의 사람을 넣어 시험하고 끝나면 지웁니다. 줄은 위치가 아니라 이름으로 찾습니다 — 다른 사람도 같은 시간에 줄을 넣습니다.
A3: 번호 | B3: 누구로 | C3: 어디서 | D3: 확인할 것 | E3: 해 볼 것 | F3: 이러면 성공 | G3: 결과 ▼ | H3: 메모 (실패·오류·문의일 때) | I3: 사진 (필요할 때 붙여넣기)
A4: 6 | B4: QA박안전4(재난안전과) | C4: 의견청취 > 산업안전보건위원회 | D4: 화면과 탭 | E4: [위원 구성] · [안건 부서이행] · [회의록] 탭을 차례로 누른다 | F4: 세 탭이 바뀌어 뜨고, 위에 올해 회의 개최 · 안건 이행 · 이행 지연 숫자가 보인다
A5: 7 | B5: QA박안전4(재난안전과) | C5: 의견청취 > 산업안전보건위원회 | D5: 위원 추가 · 수정 · 삭제 | E5: ① [위원 구성]의 [+ 위원 추가] ② 안 고르고 [저장] ③ [조직도]에서 QA하정수4 이름을 찾아 골라 [저장] ④ 이름이 내 QA하정수4 계정인 줄을 찾아 [수정] → 구분을 바꿔 [저장] ⑤ 같은 줄의 [삭제] → 확인 | F5: 안 고르면 «조직도에서 위원을 선택하세요». 저장 · 수정이 목록에 반영되고, 삭제 전에 «이 위원을 삭제하시겠습니까?»를 묻는다(바로 지워지면 실패). 노사 위원 수가 다르다는 참고 안내는 떠도 정상이다
A6: 8 | B6: QA박안전4(재난안전과) | C6: 의견청취 > 산업안전보건위원회 | D6: 안건 부서이행 등록 · 삭제 | E6: ① [안건 부서이행]의 [+ 안건 추가] ② 빈 채로 [저장] ③ 의결 안건 «용한빛_안건»만 적고 [저장] ④ 담당부서를 [조직도]에서 QA하정수4 골라 [저장] ⑤ 내 안건 줄의 [삭제] → 확인 | F6: 안건이 비면 «의결 안건을 입력하세요», 담당부서가 비면 «조직도에서 담당부서를 선택하세요». 저장하면 담당부서 칸에 내 부서 이름이 있는 줄이 생긴다. 삭제 전에 한 번 묻는다
A7: 9 | B7: QA박안전4(재난안전과) | C7: 의견청취 > 산업안전보건위원회 | D7: 회의록 작성 | E7: ① [회의록]의 [회의록 작성] ② 회차 칸을 지우고 [작성 완료] ③ 회차 «용한빛_수시회의», 참석자는 조직도에서 QA하정수4 누르고, 의결사항 한 줄을 적어 [작성 완료] (안건 부서이행 등록 체크는 비워 둔다) ④ [‹ 목록] | F7: 회차가 비면 «회차를 입력하세요». 작성하면 «회의록이 작성되었습니다» 후 상세가 열리고, 목록에 내 회차가 «작성» 상태로 있다

Sheet 협의체·점검표
A1: 의견청취 — 협의체·점검표
A2: 🗂 QA박안전4 창에서 합니다. 운영 주기는 서버에 하나라 같은 줄에서 처음 값으로 되돌리고, 위원은 넣었다가 지우고, 점검결과지는 내가 만든 것만 상신합니다.
A3: 번호 | B3: 누구로 | C3: 어디서 | D3: 확인할 것 | E3: 해 볼 것 | F3: 이러면 성공 | G3: 결과 ▼ | H3: 메모 (실패·오류·문의일 때) | I3: 사진 (필요할 때 붙여넣기)
A4: 10 | B4: QA박안전4(재난안전과) | C4: 의견청취 > 협의체·점검표 | D4: 화면과 탭 | E4: [협의체 운영] ↔ [점검표] | F4: 두 탭이 바뀌어 뜨고, 위에 점검결과지 · 미흡 · 결재 대기 숫자가 보인다
A5: 11 | B5: QA박안전4(재난안전과) | C5: 의견청취 > 협의체·점검표 | D5: 운영 주기 바꾸고 되돌리기 | E5: ① 새로고침 후 지금 운영 주기를 메모에 적는다 ② [주기 변경] → 다른 값으로 [저장] ③ 곧바로 다시 [주기 변경] → 처음 값으로 [저장] | F5: 저장할 때마다 «운영 주기가 변경되었습니다»가 뜨고 화면 표시가 바뀐다. 끝나면 처음 값으로 돌아와 있다. 처음 값이 다른 사람의 시험 중 값처럼 보이면(예: 수시) 표시만 확인하고 되돌리기는 건너뛴다
A6: 12 | B6: QA박안전4(재난안전과) | C6: 의견청취 > 협의체·점검표 | D6: 운영 결과 등록 · 수정 · 삭제 | E6: ① [+ 운영 결과 등록] → 빈 채로 [저장] ② 회차 «용한빛_회차»와 내용을 적어 [저장] ③ 회차가 «용한빛_회차»인 줄의 [수정] → 상태를 바꿔 [저장] ④ 같은 줄의 [삭제] → 확인 | F6: 빈 채로는 «회차를 입력하세요». «협의체 운영 결과가 등록되었습니다» 후 목록에 생기고 수정이 반영된다. 삭제 전에 한 번 묻는다
A7: 13 | B7: QA박안전4(재난안전과) | C7: 의견청취 > 협의체·점검표 | D7: 협의체 위원 추가 · 삭제 | E7: ① [협의체 운영]의 [+ 위원 추가] ② [조직도]에서 QA하정수4 골라 [저장] ③ 이름이 내 QA하정수4 계정인 줄의 [삭제] → 확인 | F7: «위원이 추가되었습니다» 후 목록에 그 줄이 생긴다. 삭제 전에 한 번 묻고, 지우면 사라진다
A8: 14 | B8: QA박안전4(재난안전과) | C8: 의견청취 > 협의체·점검표 | D8: 점검결과지 만들기 | E8: ① [점검표]의 [+ 점검결과지 생성] ② 점검일을 오늘로 두고 문항은 모두 «확인»인 채로 [점검결과지 등록] («미흡»은 개선조치가 함께 생기니 고르지 않는다) ③ 방금 생긴 줄의 [조회]로 열어 번호(CHK-…)를 메모에 적는다 | F8: «점검결과지가 등록되었습니다» 후 결과 «적합» · 온나라 결재 «미상신» 줄이 생긴다. 상세에 [수정]과 [온나라 결재 상신]이 있다
A9: 15 | B9: QA박안전4(재난안전과) | C9: 의견청취 > 협의체·점검표 | D9: 점검결과지 상신 | E9: ① 14번에서 만든 내 점검결과지 상세의 [온나라 결재 상신] ② 결재선 검토 · 결재에 다른 두 사람의 박안전 계정을 고른다 ③ [상신] → [확인] ④ [이력] | F9: 결재선을 정하는 창을 거쳐야 상신되고 바로 «결재완료»(내부 처리)가 되며 [수정] · [삭제]가 사라진다. [이력]에 결재 상신과 기안자(QA박안전4)가 남는다

Sheet _정보
A1: 형식 | B1: QA엑셀 v1.1
A2: 메뉴 | B2: 의견청취
A3: 담당자 | B3: 용한빛
A4: 파일 코드 | B4: OP
A5: 종류 | B5: 스모크
A6: 생성일 | B6: 2026-09-30
A7: 결과 값 | B7: 성공,실패,오류,보류,확인 불가,문의
A8: 머리 행 | B8: 3
A9: 열 | B9: 번호,누구로,어디서,확인할,해,이러면,결과,메모,사진
