Workbook

Sheet 안내
A1: QA 담양 중대재해 — 안전보건관리체계 · 박진우
A3: 메뉴 | B3: 안전보건관리체계 (훑어보는 파일)
A4: 담당자 | B4: 박진우
A5: 이 파일 | B5: 경영방침 · 조직 · 이행점검 · 도급관리를 봅니다. 경영방침과 이행점검 반기 마감은 결재 결과를 «회신 등록»으로 옮겨 적습니다.
A6: 줄 수 | B6: 19줄
A7: 시트 | B7: 경영방침 → 조직 → 이행점검 → 도급관리
A8: 테스트 주소 | B8: (배포 주소를 받으면 채웁니다)
A9: 브라우저
A10: 기기
A11: 시작한 날
A13: 이렇게 하면 됩니다
A14: ① 브라우저로 위 «테스트 주소»를 엽니다. 시트마다 맨 위에 «새 탭에서 시작» 또는 «같은 탭에서 이어서»가 적혀 있습니다.
A15: ② 화면 오른쪽 위 이름을 눌러 «누구로» 칸의 사람으로 바꿉니다.
A16: ③ «어디서» 메뉴로 가서 «해 볼 것»대로 눌러 봅니다.
A17: ④ «이러면 성공»과 같으면 «결과» 칸에서 성공을, 다르면 실패·오류 등을 고릅니다.
A18: ⑤ 실패·오류·문의면 «메모»에 한 줄 적고, 필요하면 «사진» 칸에 화면 캡처를 붙여넣습니다.
A20: 결과 고르는 법
A21: 결과 | B21: 이럴 때 고르세요
A22: 성공 | B22: «이러면 성공»대로 된다
A23: 실패 | B23: 되긴 하는데 설명과 다르다 — 막혀야 하는데 저장된다, 문구·숫자가 틀리다
A24: 오류 | B24: 화면이 멈추거나 깨진다, 눌러도 아무 일이 없다, 오류 창이 뜬다
A25: 보류 | B25: 앞 단계가 안 돼서 지금은 못 한다 — 메모에 이유
A26: 확인 불가 | B26: 이 환경에서는 볼 수 없다 — 예: 확인할 데이터가 없다
A27: 문의 | B27: 맞는지 헷갈린다 — 메모에 궁금한 점
A29: 사진 붙이는 법
A30: • 윈도우: Win + Shift + S → 영역 선택 → 엑셀에서 그 줄의 «사진» 칸을 누르고 Ctrl + V
A31: • 맥: Cmd + Ctrl + Shift + 4 → 영역 선택 → 엑셀에서 그 줄의 «사진» 칸을 누르고 Cmd + V
A32: • 사진이 크면 모서리를 끌어 줄이세요. 사진은 그 줄 «사진» 칸 위에 두면 됩니다 — 취합할 때 줄 번호로 찾습니다.
A33: • 사진은 떠 있는 그대로 두세요(«셀에 배치»로 넣으면 취합할 때 꺼내지 못합니다).
A35: 누구로 — 계정 바꾸는 법
A36: • 화면 오른쪽 위 이름을 누르면 사람 목록이 나옵니다. «누구로» 칸의 이름을 누르면 바뀝니다.
A37: 이름 | B37: 누구 | E37: 주로 하는 것
A38: 박안전 | B38: 재난안전과 담당자 | E38: 대부분 이 계정 — 등록·확인·공문
A39: 하정수 | B39: 물순환사업소 담당자 | E39: 자기 부서 일만 한다
A40: 정환경 | B40: 환경과 담당자 | E40: 남의 부서 것을 못 건드리는지 볼 때
A41: 오순환 | B41: 물순환사업소장 | E41: 자기 부서를 보고 재촉한다
A42: 김중대 | B42: 중대재해팀장 | E42: 공문 결재선(검토)을 볼 때
A43: 홍길동 | B43: 재난안전과장 | E43: 보기만 한다 — 등록 버튼이 없는 게 정상
A44: 김담양 | B44: 군수 | E44: 보기만 한다
A46: 알아 두면 좋은 것 (결함이 아닙니다)
...

Sheet 요약
A1: 진행 상황 — 안전보건관리체계 · 박진우
A2: 결과를 고르면 저절로 채워집니다. 남은 것 = 아직 결과를 고르지 않은 줄입니다.
A4: 시트 | B4: 전체 | C4: 성공 | D4: 실패 | E4: 오류 | F4: 보류 | G4: 확인 불가 | H4: 문의 | I4: 남은 것 | J4: 진행률
A5: 경영방침 | B5: =COUNTA('경영방침'!$A$4:$A$7) -> 4 | C5: =COUNTIF('경영방침'!$G$4:$G$7,"성공") -> 0 | D5: =COUNTIF('경영방침'!$G$4:$G$7,"실패") -> 0 | E5: =COUNTIF('경영방침'!$G$4:$G$7,"오류") -> 0 | F5: =COUNTIF('경영방침'!$G$4:$G$7,"보류") -> 0 | G5: =COUNTIF('경영방침'!$G$4:$G$7,"확인 불가") -> 0 | H5: =COUNTIF('경영방침'!$G$4:$G$7,"문의") -> 0 | I5: =COUNTBLANK('경영방침'!$G$4:$G$7) -> 4 | J5: =IF(B5=0,0,(B5-I5)/B5) -> 0
A6: 조직 | B6: =COUNTA('조직'!$A$4:$A$8) -> 5 | C6: =COUNTIF('조직'!$G$4:$G$8,"성공") -> 0 | D6: =COUNTIF('조직'!$G$4:$G$8,"실패") -> 0 | E6: =COUNTIF('조직'!$G$4:$G$8,"오류") -> 0 | F6: =COUNTIF('조직'!$G$4:$G$8,"보류") -> 0 | G6: =COUNTIF('조직'!$G$4:$G$8,"확인 불가") -> 0 | H6: =COUNTIF('조직'!$G$4:$G$8,"문의") -> 0 | I6: =COUNTBLANK('조직'!$G$4:$G$8) -> 5 | J6: =IF(B6=0,0,(B6-I6)/B6) -> 0
A7: 이행점검 | B7: =COUNTA('이행점검'!$A$4:$A$9) -> 6 | C7: =COUNTIF('이행점검'!$G$4:$G$9,"성공") -> 0 | D7: =COUNTIF('이행점검'!$G$4:$G$9,"실패") -> 0 | E7: =COUNTIF('이행점검'!$G$4:$G$9,"오류") -> 0 | F7: =COUNTIF('이행점검'!$G$4:$G$9,"보류") -> 0 | G7: =COUNTIF('이행점검'!$G$4:$G$9,"확인 불가") -> 0 | H7: =COUNTIF('이행점검'!$G$4:$G$9,"문의") -> 0 | I7: =COUNTBLANK('이행점검'!$G$4:$G$9) -> 6 | J7: =IF(B7=0,0,(B7-I7)/B7) -> 0
A8: 도급관리 | B8: =COUNTA('도급관리'!$A$4:$A$7) -> 4 | C8: =COUNTIF('도급관리'!$G$4:$G$7,"성공") -> 0 | D8: =COUNTIF('도급관리'!$G$4:$G$7,"실패") -> 0 | E8: =COUNTIF('도급관리'!$G$4:$G$7,"오류") -> 0 | F8: =COUNTIF('도급관리'!$G$4:$G$7,"보류") -> 0 | G8: =COUNTIF('도급관리'!$G$4:$G$7,"확인 불가") -> 0 | H8: =COUNTIF('도급관리'!$G$4:$G$7,"문의") -> 0 | I8: =COUNTBLANK('도급관리'!$G$4:$G$7) -> 4 | J8: =IF(B8=0,0,(B8-I8)/B8) -> 0
A9: 합계 | B9: =SUM(B5:B8) -> 19 | C9: =SUM(C5:C8) -> 0 | D9: =SUM(D5:D8) -> 0 | E9: =SUM(E5:E8) -> 0 | F9: =SUM(F5:F8) -> 0 | G9: =SUM(G5:G8) -> 0 | H9: =SUM(H5:H8) -> 0 | I9: =SUM(I5:I8) -> 19 | J9: =IF(B9=0,0,(B9-I9)/B9) -> 0

Sheet 경영방침
A1: 안전보건관리체계 — 경영방침
A2: 🗂 새 탭에서 시작하세요.
A3: 번호 | B3: 누구로 | C3: 어디서 | D3: 확인할 것 | E3: 해 볼 것 | F3: 이러면 성공 | G3: 결과 ▼ | H3: 메모 (실패·오류·문의일 때) | I3: 사진 (필요할 때 붙여넣기)
A4: 1 | B4: 박안전 | C4: 안전보건관리체계 > 경영방침 | D4: 화면과 탭 | E4: [경영방침] · [이행 점검] · [게시 현황] 탭을 누른다 | F4: 세 탭이 뜨고 방침 목록에 버전(현행 · 이력)이 보인다
A5: 2 | B5: 박안전 | C5: 안전보건관리체계 > 경영방침 | D5: 새 방침 등록 | E5: [+ 등록] → 빈 칸으로 진행 → 채워서 등록 | F5: 빈 칸이면 무엇을 채울지 알려 주고, 등록하면 새 버전이 생긴다
A6: 3 | B6: 박안전 | C6: 안전보건관리체계 > 경영방침 | D6: 상신 → 결재 결과 → 현행본 | E6: [온나라 결재 상신] → 결재선 지정 → 상신 → «결재 결과 회신 등록»으로 검토 승인 → 결재 완료 | F6: 상신 전에 결재선 창이 뜬다. 결재 완료되면 그 버전이 현행본이 된다
A7: 4 | B7: 박안전 | C7: 안전보건관리체계 > 경영방침 | D7: 게시 현황 저장 규칙 | E7: [게시 현황] → 한 부서를 «해당없음» 사유 없이 저장 → «게시»를 사진·위치 없이 저장 → 채워서 저장 | F7: 사유 없는 해당없음, 증빙·위치 없는 게시는 저장되지 않는다

Sheet 조직
A1: 안전보건관리체계 — 조직
A2: 🗂 어느 탭에서 해도 됩니다.
A3: 번호 | B3: 누구로 | C3: 어디서 | D3: 확인할 것 | E3: 해 볼 것 | F3: 이러면 성공 | G3: 결과 ▼ | H3: 메모 (실패·오류·문의일 때) | I3: 사진 (필요할 때 붙여넣기)
A4: 5 | B4: 박안전 | C4: 안전보건관리체계 > 조직 | D4: 화면 열기 | E4: 메뉴로 들어간다 | F4: 조직도 · 선임 현황 · 배치인원 점검 · 공사별 안전관리자 · 수행평가가 뜬다
A5: 6 | B5: 박안전 | C5: 안전보건관리체계 > 조직 | D5: 선임 등록 | E5: [선임 등록] → 빈 채로 [등록] → 채워서 등록 | F5: 빈 채로는 «구분을 고르세요.» 채우면 선임 현황에 추가된다
A6: 7 | B6: 박안전 | C6: 안전보건관리체계 > 조직 | D6: 공사 등록·수정 | E6: [+ 공사 직접 등록] → 빈 채로 [저장] → 채워서 저장 → 그 줄 [수정] | F6: 빈 채로는 «공사명을 입력하세요.» 저장·수정이 반영된다
A7: 8 | B7: 박안전 | C7: 안전보건관리체계 > 조직 | D7: 수행평가·후속조치 | E7: [수행평가 작성] → [임시저장] → 다시 열어 [등록] → [후속조치 등록] | F7: 임시저장한 값이 남아 있고 «등록되었습니다 — 확정 전까지 수정 가능»
A8: 9 | B8: 김담양 | C8: 안전보건관리체계 > 조직 | D8: 군수는 보기만 | E8: 조직 화면을 본다 | F8: 등록·수정 버튼이 없다

Sheet 이행점검
A1: 안전보건관리체계 — 이행점검
A2: 🗂 어느 탭에서 해도 됩니다.
A3: 번호 | B3: 누구로 | C3: 어디서 | D3: 확인할 것 | E3: 해 볼 것 | F3: 이러면 성공 | G3: 결과 ▼ | H3: 메모 (실패·오류·문의일 때) | I3: 사진 (필요할 때 붙여넣기)
A4: 10 | B4: 박안전 | C4: 안전보건관리체계 > 이행점검 | D4: 화면과 탭 | E4: [중대산업재해 이행점검] ↔ [중대시민재해 이행점검] | F4: 부서별 이행 현황 표가 뜨고 «N / 39개 등록» 같은 명단 안내가 있다
A5: 11 | B5: 박안전 | C5: 안전보건관리체계 > 이행점검 | D5: 부서 확인 등록 규칙 | E5: 한 부서 [확인 등록] → «해당없음» 사유 없이 → «이행» 증빙·위치 없이 → 채워서 저장 | F5: 사유 없는 해당없음과 증빙 없는 이행은 저장되지 않고, 채우면 표에 반영된다
A6: 12 | B6: 박안전 | C6: 안전보건관리체계 > 이행점검 | D6: 독촉 | E6: 미이행 부서의 [독촉] | F6: «…독촉 알림을 발송했습니다»
A7: 13 | B7: 박안전 | C7: 안전보건관리체계 > 이행점검 | D7: 반기 점검표 | E7: [점검표 작성] → [임시저장] → 다시 열어 [등록] | F7: 임시저장한 값이 남아 있고 «등록되었습니다…»
A8: 14 | B8: 박안전 | C8: 안전보건관리체계 > 이행점검 | D8: 반기 마감 상신 | E8: 반기를 바꾼다 → [반기 마감 · 온나라 상신] → 결재선을 비우고 [상신] → 채워서 상신 | F8: 결재선이 비면 막힌다. 제목의 반기가 고른 반기와 같다
A9: 15 | B9: 박안전 | C9: 안전보건관리체계 > 이행점검 | D9: 관계 법령 목록 안내 | E9: [관계 법령 목록이란] | F9: 목록이 아직 없다는 것과 무엇을 정해야 하는지 알려 준다

Sheet 도급관리
A1: 안전보건관리체계 — 도급관리
A2: 🗂 어느 탭에서 해도 됩니다.
A3: 번호 | B3: 누구로 | C3: 어디서 | D3: 확인할 것 | E3: 해 볼 것 | F3: 이러면 성공 | G3: 결과 ▼ | H3: 메모 (실패·오류·문의일 때) | I3: 사진 (필요할 때 붙여넣기)
A4: 16 | B4: 박안전 | C4: 안전보건관리체계 > 도급관리 | D4: 화면 열기 | E4: 메뉴로 들어간다 | F4: 사업 목록과 수급인 평가가 뜬다
A5: 17 | B5: 박안전 | C5: 안전보건관리체계 > 도급관리 | D5: 사업 등록 | E5: [+ 사업 등록] → 빈 채로 [등록] → 채워서 등록 | F5: 빈 채로는 «사업명을 입력하세요.» 채우면 목록에 추가된다
A6: 18 | B6: 박안전 | C6: 안전보건관리체계 > 도급관리 | D6: 점검표·서약서·평가 | E6: [점검표 작성] 등록 → 서약서 [첨부] → [업로드] → [평가 작성] 등록 | F6: 각각 등록되고 그 줄에 반영된다
A7: 19 | B7: 김담양 | C7: 안전보건관리체계 > 도급관리 | D7: 군수는 보기만 | E7: 도급관리 화면을 본다 | F7: 등록·작성 버튼이 없다

Sheet _정보
A1: 형식 | B1: QA엑셀 v1.1
A2: 메뉴 | B2: 안전보건관리체계
A3: 담당자 | B3: 박진우
A4: 파일 코드 | B4: SB
A5: 종류 | B5: 스모크
A6: 생성일 | B6: 2026-09-28
A7: 결과 값 | B7: 성공,실패,오류,보류,확인 불가,문의
A8: 머리 행 | B8: 3
A9: 열 | B9: 번호,누구로,어디서,확인할,해,이러면,결과,메모,사진
