Workbook

Sheet 안내
A1: QA 담양 중대재해 — 인력·예산 · 이혜린
A3: 메뉴 | B3: 인력·예산 (훑어보는 파일)
A4: 담당자 | B4: 이혜린
A5: 내 계정 | B5: QA박안전6 (재난안전과 담당자) · QA하정수6 (내 부서 문화체육과 담당 공무원)
A6: 이 파일 | B6: 인력 평가(인력 평가 · 평가 현황 · 평가 설정)와 예산 관리(예산 기준 설정 · 예산 총괄표)를 봅니다. 대부분 QA박안전6 계정으로 하고, 평가·점검표는 내 부서(문화체육과) 것만 만듭니다.
A7: 줄 수 | B7: 23줄
A8: 시트 | B8: 인력 평가 → 평가 현황·설정 → 예산 기준 설정 → 예산 총괄표
A9: 테스트 주소 | B9: https://safety.damyang.go.kr/login
A10: 브라우저
A11: 기기
A12: 시작한 날
A14: 이렇게 하면 됩니다
A15: ① 위 «테스트 주소»에서 받은 아이디·비밀번호로 로그인합니다. 로그인하면 통합 현황 화면으로 갑니다. 5번 틀리면 계정이 잠깁니다 — 담당 개발자에게 풀어 달라고 합니다.
A16: ② 내 계정 두 개를 창 두 개에 따로 로그인해 둡니다 — 일반 창에는 QA박안전6(재난안전과), 시크릿 창(Ctrl + Shift + N · 맥 Cmd + Shift + N)에는 QA하정수6(담당 공무원). 두 창을 나란히 두면 계정을 바꿀 필요가 없습니다.
A17: ③ «누구로» 칸에 적힌 계정의 창에서 «어디서» 메뉴로 가서 «해 볼 것»대로 눌러 봅니다.
A18: ④ «이러면 성공»과 같으면 «결과» 칸에서 성공을, 다르면 실패·오류 등을 고릅니다.
A19: ⑤ 실패·오류·문의면 «메모»에 한 줄 적고, 필요하면 «사진» 칸에 화면 캡처를 붙여넣습니다.
A21: 결과 고르는 법
A22: 결과 | B22: 이럴 때 고르세요
A23: 성공 | B23: «이러면 성공»대로 된다
A24: 실패 | B24: 되긴 하는데 설명과 다르다 — 막혀야 하는데 저장된다, 문구·숫자가 틀리다
A25: 오류 | B25: 화면이 멈추거나 깨진다, 눌러도 아무 일이 없다, 오류 창이 뜬다
A26: 보류 | B26: 앞 단계가 안 돼서 지금은 못 한다 — 메모에 이유
A27: 확인 불가 | B27: 이 환경에서는 볼 수 없다 — 예: 확인할 데이터가 없다
A28: 문의 | B28: 맞는지 헷갈린다 — 메모에 궁금한 점
A30: 사진 붙이는 법
A31: • 윈도우: Win + Shift + S → 영역 선택 → 엑셀에서 그 줄의 «사진» 칸을 누르고 Ctrl + V
A32: • 맥: Cmd + Ctrl + Shift + 4 → 영역 선택 → 엑셀에서 그 줄의 «사진» 칸을 누르고 Cmd + V
A33: • 사진이 크면 모서리를 끌어 줄이세요. 사진은 그 줄 «사진» 칸 위에 두면 됩니다 — 취합할 때 줄 번호로 찾습니다.
A34: • 사진은 떠 있는 그대로 두세요(«셀에 배치»로 넣으면 취합할 때 꺼내지 못합니다).
A36: 누구로 — 내 계정 두 개
A37: • 계정은 두 개뿐입니다. «누구로» 칸에 계정 이름과 권한이 함께 적혀 있습니다. 비밀번호는 따로 받습니다.
A38: 이름 | B38: 권한 | D38: 볼 수 있는 것 | F38: 주로 하는 것
A39: QA박안전6 | B39: 재난안전과 담당자 | D39: 모든 부서 · «내 할일»은 전체 | F39: 전 부서 등록·수정 · 확인 · 상신 · 독촉 — 대부분 이 계정
A40: QA하정수6 | B40: 담당 공무원 (내 부서: 문화체육과) | D40: 업무 화면은 전 부서, «내 할일»은 나에게 지정된 것만, 위험성평가 부서별 조치표·교육 이수현황은 내 부서만 | F40: 내 부서 일 · 남의 부서 것을 못 건드리는지 확인
A41: QA시스템관리 | B41: 시스템 관리자 (김유석만) | D41: 시스템 관리 메뉴 | F41: 시스템 관리 파일 · 공문 반려(결재 대행)
A43: 같은 서버를 6명이 함께 씁니다
A44: • 내가 만드는 것(교육 · 근로자 · 문서 · 위원 등)은 이름 앞에 내 이름을 붙입니다 — 예: «이혜린_집합교육». 그래야 내 것을 찾기 쉽습니다.
A45: • 다른 사람이 만든 것은 고치거나 지우지 않습니다. QA박안전6 계정에는 남의 것도 보이는데, 정상입니다.
A46: • 건수·이수율 같은 숫자는 다른 사람이 작업하는 동안 바뀔 수 있습니다. 숫자가 안 맞으면 새로고침해서 한 번 더 보고, 그래도 다르면 «실패».
...

Sheet 요약
A1: 진행 상황 — 인력·예산 · 이혜린
A2: 결과를 고르면 저절로 채워집니다. 남은 것 = 아직 결과를 고르지 않은 줄입니다.
A4: 시트 | B4: 전체 | C4: 성공 | D4: 실패 | E4: 오류 | F4: 보류 | G4: 확인 불가 | H4: 문의 | I4: 남은 것 | J4: 진행률
A5: 인력 평가 | B5: =COUNTA('인력 평가'!$A$4:$A$9) -> 6 | C5: =COUNTIF('인력 평가'!$G$4:$G$9,"성공") -> 0 | D5: =COUNTIF('인력 평가'!$G$4:$G$9,"실패") -> 0 | E5: =COUNTIF('인력 평가'!$G$4:$G$9,"오류") -> 0 | F5: =COUNTIF('인력 평가'!$G$4:$G$9,"보류") -> 0 | G5: =COUNTIF('인력 평가'!$G$4:$G$9,"확인 불가") -> 0 | H5: =COUNTIF('인력 평가'!$G$4:$G$9,"문의") -> 0 | I5: =COUNTBLANK('인력 평가'!$G$4:$G$9) -> 6 | J5: =IF(B5=0,0,(B5-I5)/B5) -> 0
A6: 평가 현황·설정 | B6: =COUNTA('평가 현황·설정'!$A$4:$A$8) -> 5 | C6: =COUNTIF('평가 현황·설정'!$G$4:$G$8,"성공") -> 0 | D6: =COUNTIF('평가 현황·설정'!$G$4:$G$8,"실패") -> 0 | E6: =COUNTIF('평가 현황·설정'!$G$4:$G$8,"오류") -> 0 | F6: =COUNTIF('평가 현황·설정'!$G$4:$G$8,"보류") -> 0 | G6: =COUNTIF('평가 현황·설정'!$G$4:$G$8,"확인 불가") -> 0 | H6: =COUNTIF('평가 현황·설정'!$G$4:$G$8,"문의") -> 0 | I6: =COUNTBLANK('평가 현황·설정'!$G$4:$G$8) -> 5 | J6: =IF(B6=0,0,(B6-I6)/B6) -> 0
A7: 예산 기준 설정 | B7: =COUNTA('예산 기준 설정'!$A$4:$A$6) -> 3 | C7: =COUNTIF('예산 기준 설정'!$G$4:$G$6,"성공") -> 0 | D7: =COUNTIF('예산 기준 설정'!$G$4:$G$6,"실패") -> 0 | E7: =COUNTIF('예산 기준 설정'!$G$4:$G$6,"오류") -> 0 | F7: =COUNTIF('예산 기준 설정'!$G$4:$G$6,"보류") -> 0 | G7: =COUNTIF('예산 기준 설정'!$G$4:$G$6,"확인 불가") -> 0 | H7: =COUNTIF('예산 기준 설정'!$G$4:$G$6,"문의") -> 0 | I7: =COUNTBLANK('예산 기준 설정'!$G$4:$G$6) -> 3 | J7: =IF(B7=0,0,(B7-I7)/B7) -> 0
A8: 예산 총괄표 | B8: =COUNTA('예산 총괄표'!$A$4:$A$12) -> 9 | C8: =COUNTIF('예산 총괄표'!$G$4:$G$12,"성공") -> 0 | D8: =COUNTIF('예산 총괄표'!$G$4:$G$12,"실패") -> 0 | E8: =COUNTIF('예산 총괄표'!$G$4:$G$12,"오류") -> 0 | F8: =COUNTIF('예산 총괄표'!$G$4:$G$12,"보류") -> 0 | G8: =COUNTIF('예산 총괄표'!$G$4:$G$12,"확인 불가") -> 0 | H8: =COUNTIF('예산 총괄표'!$G$4:$G$12,"문의") -> 0 | I8: =COUNTBLANK('예산 총괄표'!$G$4:$G$12) -> 9 | J8: =IF(B8=0,0,(B8-I8)/B8) -> 0
A9: 합계 | B9: =SUM(B5:B8) -> 23 | C9: =SUM(C5:C8) -> 0 | D9: =SUM(D5:D8) -> 0 | E9: =SUM(E5:E8) -> 0 | F9: =SUM(F5:F8) -> 0 | G9: =SUM(G5:G8) -> 0 | H9: =SUM(H5:H8) -> 0 | I9: =SUM(I5:I8) -> 23 | J9: =IF(B9=0,0,(B9-I9)/B9) -> 0

Sheet 인력 평가
A1: 인력·예산 — 인력 평가
A2: 🗂 QA박안전6 계정으로 하고, QA하정수6 줄만 시크릿 창에서 봅니다. 평가와 상신은 내 부서(문화체육과) 칸에서만 합니다 — 평가 완료와 상신 기록은 지울 수 없어 서버에 남습니다.
A3: 번호 | B3: 누구로 | C3: 어디서 | D3: 확인할 것 | E3: 해 볼 것 | F3: 이러면 성공 | G3: 결과 ▼ | H3: 메모 (실패·오류·문의일 때) | I3: 사진 (필요할 때 붙여넣기)
A4: 1 | B4: QA박안전6(재난안전과) | C4: 인력·예산 > 인력 평가 | D4: 화면 열기 | E4: ① 메뉴로 들어간다 ② 평가 결과의 평가 사이클을 다른 연도로 바꿨다가 되돌린다 ③ 부서를 몇 개 바꿔 본다 | F4: 평가개요 · 평가 결과 · 평가 이력이 보인다. 사이클·부서를 바꾸면 표 머리와 대상자 줄이 그에 맞게 바뀐다
A5: 2 | B5: QA박안전6(재난안전과) | C5: 인력·예산 > 인력 평가 | D5: 나를 평가자로 지정 | E5: ① 부서를 내 부서(문화체육과)로 바꾼다 ② 안전보건관리책임자 줄에서 평가자가 비어 있는 칸(상반기 또는 하반기)의 [평가자 선택] ③ 왼쪽에서 재난안전과를 누르고 오른쪽에서 내 QA박안전6 계정만 골라 [… 선택] (남의 계정은 고르지 않는다 — 한 번 넣으면 바꾸는 버튼이 없다) | F5: 평가자 칸에 내 QA박안전6(번호까지) 이름이 정확히 보이고 옆 [평가등록] 버튼이 눌리는 상태가 된다. 조직도에 내 계정이 없거나 박안전 계정끼리 표시 이름이 같으면 «확인 불가»
A6: 3 | B6: QA하정수6(담당 공무원) | C6: 인력·예산 > 인력 평가 | D6: 배정된 평가자만 평가한다 | E6: QA하정수6 창에서 같은 화면을 새로고침하고 부서를 내 부서(문화체육과)로 바꿔 2번 칸을 본다 | F6: 평가자 칸에 내 QA박안전6(번호까지) 이름이 보이고 [평가등록]이 흐려 눌리지 않는다
A7: 4 | B7: QA박안전6(재난안전과) | C7: 인력·예산 > 인력 평가 | D7: 임시저장과 평가 완료 | E7: ① 2번 칸의 [평가등록] ② 아무것도 고르지 않고 [임시저장] ③ 2~3개 항목만 골라 [임시저장] ④ 그 칸의 버튼을 다시 눌러 남은 항목을 고르되 한 항목만 «미흡», 나머지는 «양호»로 하고 [평가 완료] | F7: ② «판정한 항목이 없어 임시저장할 내용이 없습니다» ③ 칸의 버튼이 «진행 중 N/M»으로 바뀌고(토스트 문구는 따지지 않는다) 다시 열면 고른 값이 남아 있다 ④ 다 고르기 전에는 [평가 완료]가 눌리지 않는다. 완료하면 그 칸에 평가일자와 종합 «미흡»이 뜨고(미흡이 하나라도 있으면 미흡) 아래 평가 이력에 한 줄 생긴다
A8: 5 | B8: QA박안전6(재난안전과) | C8: 인력·예산 > 인력 평가 | D8: 평가 결과 보고 상신 | E8: ① 부서가 내 부서(문화체육과)인 채 평가개요의 [결재상신] ② 미리보기를 보고 [온나라로 결재 상신] ③ [＋ 검토]로 빈 칸을 하나 늘린 채 [상신] ④ 늘린 칸을 [×]로 지우고, 검토·결재를 [조직도] > 재난안전과에서 내 것이 아닌 박안전 계정 두 개로 고른 뒤 [상신] ⑤ [결재상신]을 다시 연다 | F8: ② 미리보기 «평가 결과 목록»에 4번 평가가 있다 ③ «지정하지 않은 단계가 N건 있습니다 — 조직도에서 결재자를 고르세요.»로 막힌다 ④ 상신되고 바로 결재완료(내부 처리)가 된다 ⑤ 이미 상신된 보고서라는 안내와 결재선(기안 → 검토 → 결재 세 계정)이 보인다
A9: 6 | B9: QA박안전6(재난안전과) | C9: 인력·예산 > 인력 평가 | D9: 평가 이력 조건 | E9: ① 사이클 · 부서 · 구분 · 결과를 하나씩 바꿔 본다 ② 이름 칸에 4번에서 평가한 부서장 이름 일부를 넣고 [검색] ③ [초기화] | F9: 조건에 맞는 줄만 남고 위 «완료된 평가 N건»이 줄 수와 같다. ②에서 4번 평가가 찾아진다. ③ 뒤 조건이 모두 «전체»로 돌아오고 이름 칸이 빈다

Sheet 평가 현황·설정
A1: 인력·예산 — 평가 현황·설정
A2: 🗂 QA박안전6 계정으로 하고, QA하정수6 줄만 시크릿 창에서 봅니다. 평가 항목은 모든 평가표가 같이 쓰므로 새로 저장하지 않고, 고친 것은 같은 줄에서 원래대로 되돌립니다.
A3: 번호 | B3: 누구로 | C3: 어디서 | D3: 확인할 것 | E3: 해 볼 것 | F3: 이러면 성공 | G3: 결과 ▼ | H3: 메모 (실패·오류·문의일 때) | I3: 사진 (필요할 때 붙여넣기)
A4: 7 | B4: QA박안전6(재난안전과) | C4: 인력·예산 > 평가 현황 | D4: 반기별 진행 현황 | E4: 연도 2026에서 ① [상반기] ② [하반기] ③ [전체]를 차례로 누르며 위 숫자 칸을 본다 | F4: 누를 때마다 평가 기간과 대상자 · 완료 · 진행 중 · 미시작 숫자가 바뀐다. «완료» 칸의 진행률(%)이 완료 ÷ 대상자와 맞다(반올림). [전체]는 평가 기간이 «2026 연간 (상·하반기 합산)»이다
A5: 8 | B5: QA박안전6(재난안전과) | C5: 인력·예산 > 평가 현황 | D5: 바로가기 | E5: ① 안전보건관리책임자 카드의 [템플릿 →] ② 뒤로 가서, 위에 마감 알림 줄이 있으면 [미시작 평가 시작 →] | F5: ① 평가 설정으로 가서 그 역할 칸이 잠깐 강조된다 ② 인력 평가로 간다. 알림 줄은 평가 기간 중 미시작이 있을 때만 나오므로, 없으면 ①만 보고 고른다
A6: 9 | B6: QA박안전6(재난안전과) | C6: 인력·예산 > 평가 설정 | D6: 항목명 없이는 추가되지 않는다 | E6: ① 안전보건관리책임자 칸의 [항목 추가] ② 항목명을 비운 채 [저장] ③ [취소] (새 항목은 저장하지 않는다 — 지우는 기능이 없어 모든 평가표에 남는다) | F6: «항목명을 입력하세요.»가 뜨고 저장되지 않는다. [취소] 뒤 항목 수가 그대로다
A7: 10 | B7: QA박안전6(재난안전과) | C7: 인력·예산 > 평가 설정 | D7: 고치면 평가 화면에 반영된다 | E7: ① 안전보건관리책임자 1번 항목 [편집] ② 평가 기준 (가이드) 맨 끝에 «이혜린_확인»을 덧붙여 [저장] (다른 사람 글자가 붙어 있으면 건드리지 않는다) ③ 인력 평가 화면의 평가 이력에서 4번에 완료한 평가 [보기] → 1번 항목 [세부평가기준]을 펼친다 ④ 평가 설정으로 돌아와 같은 항목을 [편집]해 내가 붙인 «이혜린_확인»만 지우고 [저장] | F7: ② «저장되었습니다 — 평가화면에 반영됩니다.» ③ 덧붙인 «이혜린_확인»이 보인다 ④ 내 글자가 사라진다(다른 사람 글자는 남아 있을 수 있다)
A8: 11 | B8: QA하정수6(담당 공무원) | C8: 인력·예산 > 인력 평가 | D8: 기준값 설정 메뉴는 담당 공무원에게 닫혀 있다 | E8: QA하정수6 창에서 인력·예산 메뉴를 누르고 왼쪽 메뉴 목록을 본다. 평가 설정·예산 기준 설정이 보이면 눌러 [항목 추가]·[원칙 등록·개정]을 눌러 본다(저장하지 않고 [취소]) | F8: 인력 평가 · 평가 현황 · 예산 총괄표는 있고, 평가 설정 · 예산 기준 설정은 없거나 들어가도 [항목 추가]·[원칙 등록·개정]이 막힌다. 메뉴가 보이고 버튼도 눌리면 FAIL로 두고 무엇이 눌렸는지 메모에 적는다

Sheet 예산 기준 설정
A1: 인력·예산 — 예산 기준 설정
A2: 🗂 QA박안전6 계정으로 합니다. 원칙·예산 항목·점검 대상은 모두가 같이 쓰는 기준값이라 내 이름을 붙여 만들고, 지울 수 있는 것은 같은 줄에서 지웁니다. 내 부서 점검 대상은 예산 총괄표에서 쓰므로 남겨 둡니다.
A3: 번호 | B3: 누구로 | C3: 어디서 | D3: 확인할 것 | E3: 해 볼 것 | F3: 이러면 성공 | G3: 결과 ▼ | H3: 메모 (실패·오류·문의일 때) | I3: 사진 (필요할 때 붙여넣기)
A4: 12 | B4: QA박안전6(재난안전과) | C4: 인력·예산 > 예산 기준 설정 | D4: 원칙 등록 | E4: ① [원칙 등록·개정] ② 빈 채로 [저장] ③ 제목에 «이혜린_예산 원칙»만 넣고 [저장] ④ 시행일을 2000-01-01로 넣고 [저장] (옛 날짜로 넣어야 지금 원칙을 밀어내지 않는다 — 원칙은 지우는 기능이 없다) | F4: ② «제목을 입력하세요.» ③ «시행일을 입력하세요.» ④ «원칙 문서가 개정 등록되었습니다.»가 뜨고 아래 개정 이력 표에 내 제목이 보인다(현행 원칙 칸은 다른 사람 등록에 따라 바뀔 수 있으니 판정하지 않는다)
A5: 13 | B5: QA박안전6(재난안전과) | C5: 인력·예산 > 예산 기준 설정 | D5: 예산 항목 추가·수정·삭제 | E5: ① [+ 대분류 추가] → 빈 채로 [확인] ② «이혜린_대분류»로 [확인] ③ 그 줄의 [+ 하위] → «이혜린_하위»로 [확인] ④ 하위 줄 [수정] → «이혜린_하위2»로 [확인] ⑤ «이혜린_대분류» 줄 [삭제] ⑥ «이혜린_하위2» 줄 [삭제] → «이혜린_대분류» 줄 [삭제] | F5: ① «항목명을 입력하세요.» ②~④ «저장되었습니다.»와 함께 트리에 보이고 이름이 바뀐다 ⑤ «하위 항목이 있어 삭제할 수 없습니다. 하위 항목을 먼저 삭제하세요.» ⑥ «항목이 삭제되었습니다.»와 함께 둘 다 사라진다
A6: 14 | B6: QA박안전6(재난안전과) | C6: 인력·예산 > 예산 기준 설정 | D6: 점검 대상 추가 | E6: ① 점검 대상 관리의 [+ 기관 추가] ② 아무것도 고르지 않고 [선택 추가 (0건)] ③ 검색 칸에 내 부서 이름 일부를 넣고 내 부서(문화체육과)를 체크 → [선택 추가 (1건)] ④ [+ 시설 추가] → 목록만 보고 [취소] | F6: ② «추가할 대상을 선택하세요.» ③ «1건이 추가되었습니다.»와 함께 기관 목록에 내 부서가 생긴다(이미 «등록됨»이면 ③은 건너뛴다) ④ 시설물 대장의 시설이 종·등급과 함께 보인다

Sheet 예산 총괄표
A1: 인력·예산 — 예산 총괄표
A2: 🗂 QA박안전6 계정으로 합니다. 점검표는 내 부서(문화체육과) 대상으로만 만들고, 다른 사람 점검표는 열어 보기만 합니다. 승인완료된 점검표는 지울 수 없어 서버에 남습니다.
A3: 번호 | B3: 누구로 | C3: 어디서 | D3: 확인할 것 | E3: 해 볼 것 | F3: 이러면 성공 | G3: 결과 ▼ | H3: 메모 (실패·오류·문의일 때) | I3: 사진 (필요할 때 붙여넣기)
A4: 15 | B4: QA박안전6(재난안전과) | C4: 인력·예산 > 예산 총괄표 | D4: 점검표 만들기 | E4: ① [+ 점검표 생성] ② 대상을 고르지 않고 [생성] ③ 연도 2026 · 대상구분 기관 · 대상 내 부서(문화체육과)를 고르고, 예방 항목 없이 [생성] ④ 대분류 하나를 체크하고 [생성] (대상에 내 부서가 없으면 14번을 먼저) | F4: ② «대상을 선택하세요.» ③ «예방 항목을 1개 이상 선택하세요.» ④ 대분류를 체크하면 하위가 함께 체크된다. «점검표가 생성되었습니다.»와 함께 2026년 내 부서 점검표 상세가 «작성중»으로 열린다
A5: 16 | B5: QA박안전6(재난안전과) | C5: 인력·예산 > 예산 총괄표 | D5: 같은 해·같은 대상은 하나만 | E5: ① [+ 점검표 생성] ② 15번과 같이 2026 · 기관 · 내 부서, 대분류 하나로 [생성] ③ 연도만 2025로 바꿔 [생성] | F5: ② «이미 2026년 문화체육과 점검표가 있습니다.»로 막힌다 ③ 2025년 내 부서 점검표가 «작성중»으로 만들어진다
A6: 17 | B6: QA박안전6(재난안전과) | C6: 인력·예산 > 예산 총괄표 | D6: 작성중 점검표 삭제 | E6: ① [← 목록]으로 가서 연도를 2025로 둔다 ② 16번에서 만든 2025년 내 부서 줄의 [삭제] → 확인 창에서 [취소] ③ 다시 [삭제] → [확인] | F6: 확인 창이 먼저 묻고, [취소]하면 그대로다. [확인]하면 «점검표가 삭제되었습니다.»와 함께 목록에서 사라진다
A7: 18 | B7: QA박안전6(재난안전과) | C7: 인력·예산 > 예산 총괄표 | D7: 편성액 없이는 상신되지 않는다 | E7: ① 15번의 2026년 내 부서 점검표를 [조회]로 연다 ② 편성액을 넣지 않고 [온나라 결재 상신] ③ 결재선 창에서 검토·결재를 [조직도] > 재난안전과에서 내 것이 아닌 박안전 계정 두 개로 고른 뒤 [상신] | F7: «편성액 합계가 0원인 점검표는 상신할 수 없습니다.»로 막히고 상태는 «작성중» 그대로다
A8: 19 | B8: QA박안전6(재난안전과) | C8: 인력·예산 > 예산 총괄표 | D8: 상신하면 결재가 바로 끝난다 | E8: ① 18번 점검표에서 항목마다 편성액을 넣는다 ② [온나라 결재 상신] → 결재선이 18번에 고른 그대로인지 보고(비었으면 같은 방식으로 고른다) [상신] → [확인] | F8: ① 칸마다 «저장됨» ② 문서번호가 붙고 상태가 바로 «승인완료»(내부 처리)다
A9: 20 | B9: QA박안전6(재난안전과) | C9: 인력·예산 > 예산 총괄표 | D9: 결재 상태 창 | E9: ① 같은 점검표의 결재 상태 창을 연다 ② [이력] | F9: 결재완료 · «내부 처리»로 보이고 19번 결재선이 남아 있다. 결과를 옮겨 적는 버튼은 없다. 이력에 결재 상신이 처리자(QA박안전6 계정)와 함께 있다
A10: 21 | B10: QA박안전6(재난안전과) | C10: 인력·예산 > 예산 총괄표 | D10: 승인 뒤 집행액 입력 | E10: ① 항목마다 집행액·비고를 넣는다 ② 편성액 칸을 고쳐 본다 ③ [← 목록]에서 이 점검표 줄을 본다 | F10: «승인 완료 — 집행액·비고는 계속 입력할 수 있습니다. (편성액은 잠금)»이 보인다. 집행액을 넣으면 «저장됨»과 함께 집행률·합계가 바로 바뀐다. 편성액 칸은 잠겨 있다. 목록의 이 줄은 «승인완료»이고 [삭제]가 없다
A11: 22 | B11: QA박안전6(재난안전과) | C11: 인력·예산 > 예산 총괄표 | D11: 합계와 조건 | E11: ① 연도를 2026으로 둔다 ② 대상구분(기관·시설)과 상태(작성중·결재중·승인완료·반려)를 바꿔 본다 ③ 위 총 편성액 · 총 집행액 · 집행률 카드를 표 맨 아래 합계 줄과 비교한다 | F11: 카드의 금액·집행률이 합계 줄과 같고 조건을 바꾸면 함께 바뀐다. 총 편성액 카드 아래 «2026년 점검표 N건»이 표 줄 수와 같다. 상태를 «승인완료»로 거르면 내 점검표가 있다
A12: 23 | B12: QA박안전6(재난안전과) | C12: 인력·예산 > 예산 기준 설정 | D12: 점검표가 쓰는 대상은 못 지운다 | E12: 점검 대상 관리의 기관 목록에서 내 부서(문화체육과) 줄의 [삭제] | F12: 줄에 «사용 중»이 붙어 있고 «점검표에서 사용 중인 대상은 삭제할 수 없습니다.»가 뜨며 줄이 남는다

Sheet _정보
A1: 형식 | B1: QA엑셀 v1.1
A2: 메뉴 | B2: 인력·예산
A3: 담당자 | B3: 이혜린
A4: 파일 코드 | B4: EV
A5: 종류 | B5: 스모크
A6: 생성일 | B6: 2026-09-30
A7: 결과 값 | B7: 성공,실패,오류,보류,확인 불가,문의
A8: 머리 행 | B8: 3
A9: 열 | B9: 번호,누구로,어디서,확인할,해,이러면,결과,메모,사진
