Workbook

Sheet 안내
A1: QA 담양 중대재해 — 위험성평가·교육 메뉴 · 하늘
A3: 메뉴 | B3: 위험성평가·교육 메뉴 (훑어보는 파일)
A4: 담당자 | B4: 하늘
A5: 내 계정 | B5: QA박안전7 (재난안전과 담당자) · QA하정수7 (내 부서 공간재생과 담당 공무원)
A6: 이 파일 | B6: 위험성평가 2개 · 안전보건교육 9개 메뉴를 하나씩 열어 만들기(C) · 보기(R) · 고치기(U) · 지우기(D)를 해 봅니다. 모든 데이터는 «하늘_…»으로 만들고 내 것만 고치고 지웁니다.
A7: 줄 수 | B7: 47줄
A8: 시트 | B8: 1 정기 위험성평가 → 2 수시 위험성평가 → 3 근로자 명단 → 4 정기교육(현업·관리감독자) → 5 채용시·기타 교육 → 6 이수현황·결재 이력
A9: 테스트 주소 | B9: https://safety.damyang.go.kr/login
A10: 브라우저
A11: 기기
A12: 시작한 날
A14: 이렇게 하면 됩니다
A15: ① 위 «테스트 주소»에서 받은 아이디·비밀번호로 로그인합니다. 로그인하면 통합 현황 화면으로 갑니다. 5번 틀리면 계정이 잠깁니다 — 담당 개발자에게 풀어 달라고 합니다.
A16: ② 내 계정 두 개를 창 두 개에 따로 로그인해 둡니다 — 일반 창에는 QA박안전7(재난안전과), 시크릿 창(Ctrl + Shift + N · 맥 Cmd + Shift + N)에는 QA하정수7(담당 공무원). 두 창을 나란히 두면 계정을 바꿀 필요가 없습니다.
A17: ③ «누구로» 칸에 적힌 계정의 창에서 «어디서» 메뉴로 가서 «해 볼 것»대로 눌러 봅니다.
A18: ④ «이러면 성공»과 같으면 «결과» 칸에서 성공을, 다르면 실패·오류 등을 고릅니다.
A19: ⑤ 실패·오류·문의면 «메모»에 한 줄 적고, 필요하면 «사진» 칸에 화면 캡처를 붙여넣습니다.
A21: 결과 고르는 법
A22: 결과 | B22: 이럴 때 고르세요
A23: 성공 | B23: «이러면 성공»대로 된다
A24: 실패 | B24: 되긴 하는데 설명과 다르다 — 막혀야 하는데 저장된다, 문구·숫자가 틀리다
A25: 오류 | B25: 화면이 멈추거나 깨진다, 눌러도 아무 일이 없다, 오류 창이 뜬다
A26: 보류 | B26: 앞 단계가 안 돼서 지금은 못 한다 — 메모에 이유
A27: 확인 불가 | B27: 이 환경에서는 볼 수 없다 — 예: 확인할 데이터가 없다
A28: 문의 | B28: 맞는지 헷갈린다 — 메모에 궁금한 점
A30: 사진 붙이는 법
A31: • 윈도우: Win + Shift + S → 영역 선택 → 엑셀에서 그 줄의 «사진» 칸을 누르고 Ctrl + V
A32: • 맥: Cmd + Ctrl + Shift + 4 → 영역 선택 → 엑셀에서 그 줄의 «사진» 칸을 누르고 Cmd + V
A33: • 사진이 크면 모서리를 끌어 줄이세요. 사진은 그 줄 «사진» 칸 위에 두면 됩니다 — 취합할 때 줄 번호로 찾습니다.
A34: • 사진은 떠 있는 그대로 두세요(«셀에 배치»로 넣으면 취합할 때 꺼내지 못합니다).
A36: 누구로 — 내 계정 두 개
A37: • 계정은 두 개뿐입니다. «누구로» 칸에 계정 이름과 권한이 함께 적혀 있습니다. 비밀번호는 따로 받습니다.
A38: 이름 | B38: 권한 | D38: 볼 수 있는 것 | F38: 주로 하는 것
A39: QA박안전7 | B39: 재난안전과 담당자 | D39: 모든 부서 · «내 할일»은 전체 | F39: 전 부서 등록·수정 · 확인 · 상신 · 독촉 — 대부분 이 계정
A40: QA하정수7 | B40: 담당 공무원 (내 부서: 공간재생과) | D40: 업무 화면은 전 부서, «내 할일»은 나에게 지정된 것만, 위험성평가 부서별 조치표·교육 이수현황은 내 부서만 | F40: 내 부서 일 · 남의 부서 것을 못 건드리는지 확인
A41: QA시스템관리 | B41: 시스템 관리자 (김유석만) | D41: 시스템 관리 메뉴 | F41: 시스템 관리 파일 · 공문 반려(결재 대행)
A43: 같은 서버를 6명이 함께 씁니다
A44: • 내가 만드는 것(교육 · 근로자 · 문서 · 위원 등)은 이름 앞에 내 이름을 붙입니다 — 예: «하늘_집합교육». 그래야 내 것을 찾기 쉽습니다.
A45: • 다른 사람이 만든 것은 고치거나 지우지 않습니다. QA박안전7 계정에는 남의 것도 보이는데, 정상입니다.
A46: • 건수·이수율 같은 숫자는 다른 사람이 작업하는 동안 바뀔 수 있습니다. 숫자가 안 맞으면 새로고침해서 한 번 더 보고, 그래도 다르면 «실패».
...

Sheet 요약
A1: 진행 상황 — 위험성평가·교육 메뉴 · 하늘
A2: 결과를 고르면 저절로 채워집니다. 남은 것 = 아직 결과를 고르지 않은 줄입니다.
A4: 시트 | B4: 전체 | C4: 성공 | D4: 실패 | E4: 오류 | F4: 보류 | G4: 확인 불가 | H4: 문의 | I4: 남은 것 | J4: 진행률
A5: 1 정기 위험성평가 | B5: =COUNTA('1 정기 위험성평가'!$A$4:$A$10) -> 7 | C5: =COUNTIF('1 정기 위험성평가'!$G$4:$G$10,"성공") -> 0 | D5: =COUNTIF('1 정기 위험성평가'!$G$4:$G$10,"실패") -> 0 | E5: =COUNTIF('1 정기 위험성평가'!$G$4:$G$10,"오류") -> 0 | F5: =COUNTIF('1 정기 위험성평가'!$G$4:$G$10,"보류") -> 0 | G5: =COUNTIF('1 정기 위험성평가'!$G$4:$G$10,"확인 불가") -> 0 | H5: =COUNTIF('1 정기 위험성평가'!$G$4:$G$10,"문의") -> 0 | I5: =COUNTBLANK('1 정기 위험성평가'!$G$4:$G$10) -> 7 | J5: =IF(B5=0,0,(B5-I5)/B5) -> 0
A6: 2 수시 위험성평가 | B6: =COUNTA('2 수시 위험성평가'!$A$4:$A$11) -> 8 | C6: =COUNTIF('2 수시 위험성평가'!$G$4:$G$11,"성공") -> 0 | D6: =COUNTIF('2 수시 위험성평가'!$G$4:$G$11,"실패") -> 0 | E6: =COUNTIF('2 수시 위험성평가'!$G$4:$G$11,"오류") -> 0 | F6: =COUNTIF('2 수시 위험성평가'!$G$4:$G$11,"보류") -> 0 | G6: =COUNTIF('2 수시 위험성평가'!$G$4:$G$11,"확인 불가") -> 0 | H6: =COUNTIF('2 수시 위험성평가'!$G$4:$G$11,"문의") -> 0 | I6: =COUNTBLANK('2 수시 위험성평가'!$G$4:$G$11) -> 8 | J6: =IF(B6=0,0,(B6-I6)/B6) -> 0
A7: 3 근로자 명단 | B7: =COUNTA('3 근로자 명단'!$A$4:$A$10) -> 7 | C7: =COUNTIF('3 근로자 명단'!$G$4:$G$10,"성공") -> 0 | D7: =COUNTIF('3 근로자 명단'!$G$4:$G$10,"실패") -> 0 | E7: =COUNTIF('3 근로자 명단'!$G$4:$G$10,"오류") -> 0 | F7: =COUNTIF('3 근로자 명단'!$G$4:$G$10,"보류") -> 0 | G7: =COUNTIF('3 근로자 명단'!$G$4:$G$10,"확인 불가") -> 0 | H7: =COUNTIF('3 근로자 명단'!$G$4:$G$10,"문의") -> 0 | I7: =COUNTBLANK('3 근로자 명단'!$G$4:$G$10) -> 7 | J7: =IF(B7=0,0,(B7-I7)/B7) -> 0
A8: 4 정기교육(현업·관리감독자) | B8: =COUNTA('4 정기교육(현업·관리감독자)'!$A$4:$A$14) -> 11 | C8: =COUNTIF('4 정기교육(현업·관리감독자)'!$G$4:$G$14,"성공") -> 0 | D8: =COUNTIF('4 정기교육(현업·관리감독자)'!$G$4:$G$14,"실패") -> 0 | E8: =COUNTIF('4 정기교육(현업·관리감독자)'!$G$4:$G$14,"오류") -> 0 | F8: =COUNTIF('4 정기교육(현업·관리감독자)'!$G$4:$G$14,"보류") -> 0 | G8: =COUNTIF('4 정기교육(현업·관리감독자)'!$G$4:$G$14,"확인 불가") -> 0 | H8: =COUNTIF('4 정기교육(현업·관리감독자)'!$G$4:$G$14,"문의") -> 0 | I8: =COUNTBLANK('4 정기교육(현업·관리감독자)'!$G$4:$G$14) -> 11 | J8: =IF(B8=0,0,(B8-I8)/B8) -> 0
A9: 5 채용시·기타 교육 | B9: =COUNTA('5 채용시·기타 교육'!$A$4:$A$12) -> 9 | C9: =COUNTIF('5 채용시·기타 교육'!$G$4:$G$12,"성공") -> 0 | D9: =COUNTIF('5 채용시·기타 교육'!$G$4:$G$12,"실패") -> 0 | E9: =COUNTIF('5 채용시·기타 교육'!$G$4:$G$12,"오류") -> 0 | F9: =COUNTIF('5 채용시·기타 교육'!$G$4:$G$12,"보류") -> 0 | G9: =COUNTIF('5 채용시·기타 교육'!$G$4:$G$12,"확인 불가") -> 0 | H9: =COUNTIF('5 채용시·기타 교육'!$G$4:$G$12,"문의") -> 0 | I9: =COUNTBLANK('5 채용시·기타 교육'!$G$4:$G$12) -> 9 | J9: =IF(B9=0,0,(B9-I9)/B9) -> 0
A10: 6 이수현황·결재 이력 | B10: =COUNTA('6 이수현황·결재 이력'!$A$4:$A$8) -> 5 | C10: =COUNTIF('6 이수현황·결재 이력'!$G$4:$G$8,"성공") -> 0 | D10: =COUNTIF('6 이수현황·결재 이력'!$G$4:$G$8,"실패") -> 0 | E10: =COUNTIF('6 이수현황·결재 이력'!$G$4:$G$8,"오류") -> 0 | F10: =COUNTIF('6 이수현황·결재 이력'!$G$4:$G$8,"보류") -> 0 | G10: =COUNTIF('6 이수현황·결재 이력'!$G$4:$G$8,"확인 불가") -> 0 | H10: =COUNTIF('6 이수현황·결재 이력'!$G$4:$G$8,"문의") -> 0 | I10: =COUNTBLANK('6 이수현황·결재 이력'!$G$4:$G$8) -> 5 | J10: =IF(B10=0,0,(B10-I10)/B10) -> 0
A11: 합계 | B11: =SUM(B5:B10) -> 47 | C11: =SUM(C5:C10) -> 0 | D11: =SUM(D5:D10) -> 0 | E11: =SUM(E5:E10) -> 0 | F11: =SUM(F5:F10) -> 0 | G11: =SUM(G5:G10) -> 0 | H11: =SUM(H5:H10) -> 0 | I11: =SUM(I5:I10) -> 47 | J11: =IF(B11=0,0,(B11-I11)/B11) -> 0

Sheet 1 정기 위험성평가
A1: 위험성평가·교육 메뉴 — 1 정기 위험성평가
A2: 🗂 한 해 1건을 6명이 함께 쓰는 평가라 만들기·지우기는 하지 않습니다. 보기(R)와 권한 차이만 봅니다.
A3: 번호 | B3: 누구로 | C3: 어디서 | D3: 확인할 것 | E3: 해 볼 것 | F3: 이러면 성공 | G3: 결과 ▼ | H3: 메모 (실패·오류·문의일 때) | I3: 사진 (필요할 때 붙여넣기)
A4: 1 | B4: QA박안전7(재난안전과) | C4: 위험성평가 > 정기 위험성평가 | D4: R 연도 바꾸기 | E4: 연도를 2025 → 2026 으로 바꾼다 | F4: 연도마다 요약과 표가 바뀐다. 평가가 없으면 등록되지 않았다는 안내(정상)
A5: 2 | B5: QA박안전7(재난안전과) | C5: 위험성평가 > 정기 위험성평가 | D5: R 요약 숫자 | E5: 위 요약 숫자와 아래 부서 표를 비교한다 | F5: 요약 숫자가 표 내용과 맞다
A6: 3 | B6: QA박안전7(재난안전과) | C6: 위험성평가 > 정기 위험성평가 | D6: R 탭 이동 | E6: 부서별 조치 · 이력 등 탭을 하나씩 누른다 | F6: 탭마다 내용이 바뀌고 오류가 없다
A7: 4 | B7: QA박안전7(재난안전과) | C7: 위험성평가 > 정기 위험성평가 | D7: R 부서 상세 | E7: 부서 줄 하나를 눌러 상세를 열고 닫는다 | F7: 개선조치 카드가 보이고, 닫으면 목록으로 돌아온다
A8: 5 | B8: QA박안전7(재난안전과) | C8: 위험성평가 > 정기 위험성평가 | D8: R 파일 이름 누르기 | E8: 설문조사표·보고서 파일 이름을 누른다 | F8: 파일이 열리거나 «…연계 후 제공됩니다» 안내가 뜬다
A9: 6 | B9: QA박안전7(재난안전과) | C9: 위험성평가 > 정기 위험성평가 | D9: R 만들기 창만 열기 | E9: [＋ 정기평가 생성]이 보이면 눌러 부서 목록을 보고 [취소] | F9: 부서를 고르는 창이 뜨고, 취소하면 아무것도 생기지 않는다. 이미 평가가 있으면 버튼이 없다(정상)
A10: 7 | B10: QA하정수7(담당 공무원) | C10: 위험성평가 > 정기 위험성평가 | D10: 권한 — 담당 공무원 | E10: QA하정수7 창에서 같은 메뉴를 연다 | F10: [＋ 정기평가 생성]이 없고 부서별 조치 표에 내 부서(공간재생과) 줄만 보인다

Sheet 2 수시 위험성평가
A1: 위험성평가·교육 메뉴 — 2 수시 위험성평가
A2: 🗂 내 부서 건을 만들고(C) · 보고(R) · 조치를 완료하고(U) · 검토파일을 붙였다 뗍니다. 내용 앞에 «하늘_»을 붙입니다.
A3: 번호 | B3: 누구로 | C3: 어디서 | D3: 확인할 것 | E3: 해 볼 것 | F3: 이러면 성공 | G3: 결과 ▼ | H3: 메모 (실패·오류·문의일 때) | I3: 사진 (필요할 때 붙여넣기)
A4: 8 | B4: QA하정수7(담당 공무원) | C4: 위험성평가 > 수시 위험성평가 | D4: C 빈 칸이면 막힌다 | E4: [＋ 수시평가 등록] → 아무것도 안 넣고 [등록] | F4: 필수 칸을 채우라는 안내가 뜨고 등록되지 않는다
A5: 9 | B5: QA하정수7(담당 공무원) | C5: 위험성평가 > 수시 위험성평가 | D5: C 수시평가 등록 | E5: 사유 하나 · 발생일 오늘 · 내용 «하늘_수시점검» · 유해위험요인 1건과 감소대책을 넣고 [등록] | F5: 등록되고 목록 맨 위에 생긴다. 부서는 내 부서(공간재생과)다
A6: 10 | B6: QA하정수7(담당 공무원) | C6: 위험성평가 > 수시 위험성평가 | D6: R 목록·상세 | E6: ① 검색창에 «하늘» ② 방금 건의 [조치 상세]를 연다 | F6: 내 건만 걸러지고 상세에 적은 내용이 그대로 보인다
A7: 11 | B7: QA하정수7(담당 공무원) | C7: 대시보드 > 내 할일 | D7: R 내 할일에 생긴다 | E7: 내 할일에서 방금 건의 개선조치를 찾는다 | F7: 개선조치 1건이 할 일로 떠 있다
A8: 12 | B8: QA하정수7(담당 공무원) | C8: 위험성평가 > 수시 위험성평가 | D8: U 조치 완료 | E8: [조치 상세]에서 사진·조치 내용·서명을 넣고 완료 | F8: 완료된다(수시평가는 재난안전과 확인 단계가 없다 — 정상)
A9: 13 | B9: QA박안전7(재난안전과) | C9: 위험성평가 > 수시 위험성평가 | D9: U 검토파일 붙이기 | E9: 같은 건에서 [＋ 검토파일 등록] → 파일명·검토자 이름을 넣고 등록 | F9: 상태가 «검토 완료»로 바뀐다
A10: 14 | B10: QA박안전7(재난안전과) | C10: 위험성평가 > 수시 위험성평가 | D10: D 검토파일 떼기 | E10: [해제] → 확인 창에서 [취소] → 다시 [해제] → 확인 | F10: 바로 지우지 않고 한 번 묻는다. 확인하면 검토 완료가 풀린다
A11: 15 | B11: QA하정수7(담당 공무원) | C11: 위험성평가 > 수시 위험성평가 | D11: 권한 — 검토파일은 재난안전과만 | E11: QA하정수7 창에서 같은 건을 본다 | F11: [＋ 검토파일 등록]이 없거나 눌러도 막힌다

Sheet 3 근로자 명단
A1: 위험성평가·교육 메뉴 — 3 근로자 명단
A2: 🗂 내 근로자를 만들고 고치고 지웁니다. 이름은 «하늘_…»로 만듭니다.
A3: 번호 | B3: 누구로 | C3: 어디서 | D3: 확인할 것 | E3: 해 볼 것 | F3: 이러면 성공 | G3: 결과 ▼ | H3: 메모 (실패·오류·문의일 때) | I3: 사진 (필요할 때 붙여넣기)
A4: 16 | B4: QA박안전7(재난안전과) | C4: 안전보건교육 > 교육 현황·관리 > 근로자 명단 관리 | D4: C 빈 칸이면 막힌다 | E4: [＋ 직접 등록] → 이름을 비우고 [등록] → [취소] | F4: 이름을 넣으라는 안내가 뜨고 등록되지 않는다
A5: 17 | B5: QA박안전7(재난안전과) | C5: 안전보건교육 > 교육 현황·관리 > 근로자 명단 관리 | D5: C 근로자 등록 | E5: [＋ 직접 등록] → 이름 «하늘_근로자1» · 부서 내 부서(공간재생과) · 구분 현업 · 고용형태 기간제 · 채용일 오늘 · 계약기간 6 → [등록] | F5: 등록되고 목록에 보인다
A6: 18 | B6: QA박안전7(재난안전과) | C6: 안전보건교육 > 교육 현황·관리 > 근로자 명단 관리 | D6: R 조건 걸기 | E6: 검색 «하늘» · 부서 · 구분 조건을 걸었다가 [필터 초기화] | F6: 내 근로자만 걸러지고 초기화하면 돌아온다
A7: 19 | B7: QA박안전7(재난안전과) | C7: 안전보건교육 > 교육 현황·관리 > 근로자 명단 관리 | D7: U 수정 | E7: «하늘_근로자1» [수정] → 이름 끝에 «_수정» → [저장] → 다시 원래 이름으로 [저장] | F7: 두 번 모두 저장되고 목록 이름이 바뀐다
A8: 20 | B8: QA박안전7(재난안전과) | C8: 안전보건교육 > 교육 현황·관리 > 근로자 명단 관리 | D8: C 관리감독자 등록·지정일 | E8: ① 이름 «하늘_감독자» · 구분 관리감독자로 등록 ② 그 줄 [지정일 등록] → 내일 날짜 [저장] ③ 오늘로 [저장] | F8: ② 미래 날짜는 막힌다(저장되면 «실패») ③ 지정일에 오늘이 보인다
A9: 21 | B9: QA박안전7(재난안전과) | C9: 안전보건교육 > 교육 현황·관리 > 근로자 명단 관리 | D9: D 삭제 | E9: «하늘_근로자2»를 등록한 뒤 그 줄 [삭제] → 확인 창 → [삭제] | F9: 한 번 묻고, 삭제하면 목록에서 사라진다
A10: 22 | B10: QA하정수7(담당 공무원) | C10: 안전보건교육 > 교육 현황·관리 > 근로자 명단 관리 | D10: 권한 — 담당 공무원 | E10: QA하정수7 창에서 [＋ 직접 등록]을 열고 [취소]. 관리감독자 줄의 [지정일 등록]을 찾는다 | F10: 부서가 내 부서로 고정돼 있다. [지정일 등록]은 없다(재난안전과만)

Sheet 4 정기교육(현업·관리감독자)
A1: 위험성평가·교육 메뉴 — 4 정기교육(현업·관리감독자)
A2: 🗂 내 집합교육을 만들고 → 참석자를 내고 → 고치고 → 종료하고 → 지웁니다.
A3: 번호 | B3: 누구로 | C3: 어디서 | D3: 확인할 것 | E3: 해 볼 것 | F3: 이러면 성공 | G3: 결과 ▼ | H3: 메모 (실패·오류·문의일 때) | I3: 사진 (필요할 때 붙여넣기)
A4: 23 | B4: QA박안전7(재난안전과) | C4: 안전보건교육 > 현업근로자 > 정기교육 | D4: C 빈 칸이면 막힌다 | E4: [＋ 집합교육 등록] → 빈 채로 [등록] → [취소] | F4: 교육 내용을 넣으라는 안내가 뜬다
A5: 24 | B5: QA박안전7(재난안전과) | C5: 안전보건교육 > 현업근로자 > 정기교육 | D5: C 집합교육 등록 | E5: [＋ 집합교육 등록] → 내용 «하늘_집합교육» · 오늘 · 14:00~16:00 · 강사·장소 → [등록] | F5: 카드가 생기고 시간이 2h로 계산된다
A6: 25 | B6: QA박안전7(재난안전과) | C6: 안전보건교육 > 현업근로자 > 정기교육 | D6: R 목록·상세 | E6: ① 조건 «하늘» ② 카드의 [상세 →]를 연다 ③ 뒤로 | F6: 내 교육만 걸러지고 상세가 열린다
A7: 26 | B7: QA박안전7(재난안전과) | C7: 안전보건교육 > 현업근로자 > 정기교육 | D7: U 수정 | E7: 카드 [수정] → 종료 시각 17:00 → [저장] | F7: 저장되고 시간이 3h로 바뀐다
A8: 27 | B8: QA하정수7(담당 공무원) | C8: 안전보건교육 > 현업근로자 > 정기교육 | D8: C 참석자 등록부 | E8: «하늘_집합교육» 상세 → [＋ 참석자 등록부 등록] → 3번 시트의 «하늘_근로자1» 체크 · 서명파일 첨부 → [신청 완료] | F8: 내 부서 1명 신청이 표에 생긴다
A9: 28 | B9: QA하정수7(담당 공무원) | C9: 안전보건교육 > 현업근로자 > 정기교육 | D9: C 같은 부서 두 번 | E9: 같은 상세에서 한 번 더 신청 | F9: 이미 등록된 부서라며 막힌다
A10: 29 | B10: QA하정수7(담당 공무원) | C10: 안전보건교육 > 현업근로자 > 정기교육 | D10: D 신청 취소 후 다시 | E10: 내 부서 줄 [신청 취소] → 확인 → 다시 신청 | F10: 취소하면 줄이 빠지고 다시 신청하면 돌아온다
A11: 30 | B11: QA박안전7(재난안전과) | C11: 안전보건교육 > 현업근로자 > 정기교육 | D11: U 교육 종료 | E11: 상세 → [교육 종료 처리] → 확인 | F11: 상태가 완료로 바뀌고 이수 인원이 반영된다
A12: 31 | B12: QA박안전7(재난안전과) | C12: 안전보건교육 > 현업근로자 > 정기교육 | D12: D 교육 삭제 | E12: «하늘_삭제용» 집합교육을 하나 더 등록 → [삭제] → 확인 | F12: 지울 신청·기록 건수를 알려 주고 삭제된다
A13: 32 | B13: QA하정수7(담당 공무원) | C13: 안전보건교육 > 현업근로자 > 정기교육 | D13: C 자체교육 | E13: [자체교육 (부서)] → [＋ 자체교육 등록·진행] → 내용 «하늘_자체교육» · 대상자 «하늘_근로자1» · 증빙 → [진행 처리] | F13: 부서가 내 부서로 고정되고 교육이 생긴다
A14: 33 | B14: QA박안전7(재난안전과) | C14: 안전보건교육 > 관리감독자 > 정기교육 | D14: C·D 관리감독자 정기교육 | E14: «하늘_감독자교육»을 등록 → 목록 확인 → [삭제] | F14: 등록되고 목록에 보이며 삭제된다

Sheet 5 채용시·기타 교육
A1: 위험성평가·교육 메뉴 — 5 채용시·기타 교육
A2: 🗂 채용시 이수를 넣고 고치고 지웁니다. 기타 교육을 만들고 고치고 지웁니다.
A3: 번호 | B3: 누구로 | C3: 어디서 | D3: 확인할 것 | E3: 해 볼 것 | F3: 이러면 성공 | G3: 결과 ▼ | H3: 메모 (실패·오류·문의일 때) | I3: 사진 (필요할 때 붙여넣기)
A4: 34 | B4: QA박안전7(재난안전과) | C4: 안전보건교육 > 현업근로자 > 채용시교육 | D4: R 탭 세 개 | E4: [전체] · [미이수] · [이수]를 차례로 누른다 | F4: 탭이 셋이고 «하늘_근로자1»이 미이수에 있다(4번 시트 종료 전이면)
A5: 35 | B5: QA박안전7(재난안전과) | C5: 안전보건교육 > 현업근로자 > 채용시교육 | D5: C 채용시 교육 추가 | E5: [＋ 채용시 교육 추가] → «하늘_근로자1» 체크 · 09:00~17:00 · 내용 «하늘_채용시» · 증빙 → [교육기록 등록] | F5: 이수 탭으로 옮겨 가고 상태가 이수다
A6: 36 | B6: QA박안전7(재난안전과) | C6: 안전보건교육 > 현업근로자 > 채용시교육 | D6: U 이수 수정 | E6: 그 줄 [이수 수정] → 이수일을 어제로 [저장] | F6: 이수일이 바뀐다
A7: 37 | B7: QA박안전7(재난안전과) | C7: 안전보건교육 > 현업근로자 > 채용시교육 | D7: D 이수 기록 삭제 | E7: 다시 [이수 수정] → [이수 기록 삭제] → 확인 | F7: 미이수로 돌아간다
A8: 38 | B8: QA박안전7(재난안전과) | C8: 안전보건교육 > 현업근로자 > 기타 교육 | D8: C 기타 교육 등록 | E8: [＋ 기타 교육 등록·진행] → 유형 «작업내용 변경» · 내용 «하늘_기타교육» · 대상자 «하늘_근로자1» · 시간 2 → [진행 처리] | F8: 교육이 생기고 목록에 보인다
A9: 39 | B9: QA박안전7(재난안전과) | C9: 안전보건교육 > 현업근로자 > 기타 교육 | D9: U 수정 | E9: 그 카드 [수정] → 시간 3 → [저장] | F9: 저장되고 이수 기록 시간도 바뀐다
A10: 40 | B10: QA박안전7(재난안전과) | C10: 안전보건교육 > 현업근로자 > 기타 교육 | D10: D 삭제 | E10: 그 카드 [삭제] → 확인 | F10: 회수되는 이수시간을 알려 주고 삭제된다
A11: 41 | B11: QA박안전7(재난안전과) | C11: 안전보건교육 > 관리감독자 > 기타 교육 | D11: R 유형 차이 | E11: 유형 목록을 현업근로자 기타 교육과 비교한다 | F11: 관리감독자 쪽에는 건설업 기초가 없다
A12: 42 | B12: QA박안전7(재난안전과) | C12: 안전보건교육 > 관리감독자 > 채용시교육 | D12: R 판정 불가 | E12: 탭을 차례로 본다 | F12: 지정일이 없는 사람은 어느 탭에도 없고 판정 불가라고 알려 준다

Sheet 6 이수현황·결재 이력
A1: 위험성평가·교육 메뉴 — 6 이수현황·결재 이력
A2: 🗂 만든 결과가 현황에 반영됐는지 보고, 공문을 올렸다가 확인합니다.
A3: 번호 | B3: 누구로 | C3: 어디서 | D3: 확인할 것 | E3: 해 볼 것 | F3: 이러면 성공 | G3: 결과 ▼ | H3: 메모 (실패·오류·문의일 때) | I3: 사진 (필요할 때 붙여넣기)
A4: 43 | B4: QA박안전7(재난안전과) | C4: 안전보건교육 > 교육 현황·관리 > 이수현황 | D4: R 요약·상세 | E4: ① 부서별 요약에서 내 부서 줄 ② [대상자별 상세]에서 «하늘» 검색 | F4: 4·5번 시트에서 넣은 이수 기록이 반영돼 있다
A5: 44 | B5: QA하정수7(담당 공무원) | C5: 안전보건교육 > 교육 현황·관리 > 이수현황 | D5: 권한 — 남의 부서 | E5: QA하정수7 창에서 같은 메뉴 | F5: 내 부서 것만 보이고 부서 조건에도 다른 부서가 없다
A6: 45 | B6: QA박안전7(재난안전과) | C6: 안전보건교육 > 현업근로자 > 정기교육 | D6: C 공문 상신 | E6: 종료한 «하늘_집합교육»의 [공문 기안] → 본문 직접 작성 → 결재선 검토·결재에 다른 사람의 박안전 계정 둘 → [문서 미리보기 →] → 상신 | F6: 바로 결재완료(내부 처리)가 되고 교육이 잠긴다
A7: 46 | B7: QA박안전7(재난안전과) | C7: 안전보건교육 > 현업근로자 > 정기교육 | D7: U 잠긴 뒤 | E7: 그 교육의 [수정]·[삭제]·신청 취소를 찾는다 | F7: 모두 잠겨 있다(잠금 표시)
A8: 47 | B8: QA박안전7(재난안전과) | C8: 안전보건교육 > 교육 현황·관리 > 결재 이력 | D8: R 결재 이력 | E8: 검색 «하늘_집합교육» → [문서] | F8: 방금 공문이 결재완료로 있고 [문서]로 열린다

Sheet _정보
A1: 형식 | B1: QA엑셀 v1.1
A2: 메뉴 | B2: 위험성평가·교육 메뉴
A3: 담당자 | B3: 하늘
A4: 파일 코드 | B4: MN
A5: 종류 | B5: 스모크
A6: 생성일 | B6: 2026-09-30
A7: 결과 값 | B7: 성공,실패,오류,보류,확인 불가,문의
A8: 머리 행 | B8: 3
A9: 열 | B9: 번호,누구로,어디서,확인할,해,이러면,결과,메모,사진
