Workbook

Sheet 안내
A1: QA 담양 중대재해 — 업무 관리 · 김유석
A3: 메뉴 | B3: 업무 관리 (훑어보는 파일)
A4: 담당자 | B4: 김유석
A5: 내 계정 | B5: QA박안전5 (재난안전과 담당자) · QA하정수5 (내 부서 보건소 담당 공무원)
A6: 이 파일 | B6: 이행 관리(할 일마다 서류가 있는지)와 문서 목록을 봅니다. 기준연도는 2025년이 기본이고, 서류를 올리고 확인·삭제하는 일은 내가 올린 «김유석_2025 점검 결과» 서류로만 합니다.
A7: 줄 수 | B7: 12줄
A8: 시트 | B8: 이행 관리 → 문서 목록
A9: 테스트 주소 | B9: https://safety.damyang.go.kr/login
A10: 브라우저
A11: 기기
A12: 시작한 날
A14: 이렇게 하면 됩니다
A15: ① 위 «테스트 주소»에서 받은 아이디·비밀번호로 로그인합니다. 로그인하면 통합 현황 화면으로 갑니다. 5번 틀리면 계정이 잠깁니다 — 담당 개발자에게 풀어 달라고 합니다.
A16: ② 내 계정 두 개를 창 두 개에 따로 로그인해 둡니다 — 일반 창에는 QA박안전5(재난안전과), 시크릿 창(Ctrl + Shift + N · 맥 Cmd + Shift + N)에는 QA하정수5(담당 공무원). 두 창을 나란히 두면 계정을 바꿀 필요가 없습니다.
A17: ③ «누구로» 칸에 적힌 계정의 창에서 «어디서» 메뉴로 가서 «해 볼 것»대로 눌러 봅니다.
A18: ④ «이러면 성공»과 같으면 «결과» 칸에서 성공을, 다르면 실패·오류 등을 고릅니다.
A19: ⑤ 실패·오류·문의면 «메모»에 한 줄 적고, 필요하면 «사진» 칸에 화면 캡처를 붙여넣습니다.
A21: 결과 고르는 법
A22: 결과 | B22: 이럴 때 고르세요
A23: 성공 | B23: «이러면 성공»대로 된다
A24: 실패 | B24: 되긴 하는데 설명과 다르다 — 막혀야 하는데 저장된다, 문구·숫자가 틀리다
A25: 오류 | B25: 화면이 멈추거나 깨진다, 눌러도 아무 일이 없다, 오류 창이 뜬다
A26: 보류 | B26: 앞 단계가 안 돼서 지금은 못 한다 — 메모에 이유
A27: 확인 불가 | B27: 이 환경에서는 볼 수 없다 — 예: 확인할 데이터가 없다
A28: 문의 | B28: 맞는지 헷갈린다 — 메모에 궁금한 점
A30: 사진 붙이는 법
A31: • 윈도우: Win + Shift + S → 영역 선택 → 엑셀에서 그 줄의 «사진» 칸을 누르고 Ctrl + V
A32: • 맥: Cmd + Ctrl + Shift + 4 → 영역 선택 → 엑셀에서 그 줄의 «사진» 칸을 누르고 Cmd + V
A33: • 사진이 크면 모서리를 끌어 줄이세요. 사진은 그 줄 «사진» 칸 위에 두면 됩니다 — 취합할 때 줄 번호로 찾습니다.
A34: • 사진은 떠 있는 그대로 두세요(«셀에 배치»로 넣으면 취합할 때 꺼내지 못합니다).
A36: 누구로 — 내 계정 두 개
A37: • 계정은 두 개뿐입니다. «누구로» 칸에 계정 이름과 권한이 함께 적혀 있습니다. 비밀번호는 따로 받습니다.
A38: 이름 | B38: 권한 | D38: 볼 수 있는 것 | F38: 주로 하는 것
A39: QA박안전5 | B39: 재난안전과 담당자 | D39: 모든 부서 · «내 할일»은 전체 | F39: 전 부서 등록·수정 · 확인 · 상신 · 독촉 — 대부분 이 계정
A40: QA하정수5 | B40: 담당 공무원 (내 부서: 보건소) | D40: 업무 화면은 전 부서, «내 할일»은 나에게 지정된 것만, 위험성평가 부서별 조치표·교육 이수현황은 내 부서만 | F40: 내 부서 일 · 남의 부서 것을 못 건드리는지 확인
A41: QA시스템관리 | B41: 시스템 관리자 (김유석만) | D41: 시스템 관리 메뉴 | F41: 시스템 관리 파일 · 공문 반려(결재 대행)
A43: 같은 서버를 6명이 함께 씁니다
A44: • 내가 만드는 것(교육 · 근로자 · 문서 · 위원 등)은 이름 앞에 내 이름을 붙입니다 — 예: «김유석_집합교육». 그래야 내 것을 찾기 쉽습니다.
A45: • 다른 사람이 만든 것은 고치거나 지우지 않습니다. QA박안전5 계정에는 남의 것도 보이는데, 정상입니다.
A46: • 건수·이수율 같은 숫자는 다른 사람이 작업하는 동안 바뀔 수 있습니다. 숫자가 안 맞으면 새로고침해서 한 번 더 보고, 그래도 다르면 «실패».
...

Sheet 요약
A1: 진행 상황 — 업무 관리 · 김유석
A2: 결과를 고르면 저절로 채워집니다. 남은 것 = 아직 결과를 고르지 않은 줄입니다.
A4: 시트 | B4: 전체 | C4: 성공 | D4: 실패 | E4: 오류 | F4: 보류 | G4: 확인 불가 | H4: 문의 | I4: 남은 것 | J4: 진행률
A5: 이행 관리 | B5: =COUNTA('이행 관리'!$A$4:$A$9) -> 6 | C5: =COUNTIF('이행 관리'!$G$4:$G$9,"성공") -> 0 | D5: =COUNTIF('이행 관리'!$G$4:$G$9,"실패") -> 0 | E5: =COUNTIF('이행 관리'!$G$4:$G$9,"오류") -> 0 | F5: =COUNTIF('이행 관리'!$G$4:$G$9,"보류") -> 0 | G5: =COUNTIF('이행 관리'!$G$4:$G$9,"확인 불가") -> 0 | H5: =COUNTIF('이행 관리'!$G$4:$G$9,"문의") -> 0 | I5: =COUNTBLANK('이행 관리'!$G$4:$G$9) -> 6 | J5: =IF(B5=0,0,(B5-I5)/B5) -> 0
A6: 문서 목록 | B6: =COUNTA('문서 목록'!$A$4:$A$9) -> 6 | C6: =COUNTIF('문서 목록'!$G$4:$G$9,"성공") -> 0 | D6: =COUNTIF('문서 목록'!$G$4:$G$9,"실패") -> 0 | E6: =COUNTIF('문서 목록'!$G$4:$G$9,"오류") -> 0 | F6: =COUNTIF('문서 목록'!$G$4:$G$9,"보류") -> 0 | G6: =COUNTIF('문서 목록'!$G$4:$G$9,"확인 불가") -> 0 | H6: =COUNTIF('문서 목록'!$G$4:$G$9,"문의") -> 0 | I6: =COUNTBLANK('문서 목록'!$G$4:$G$9) -> 6 | J6: =IF(B6=0,0,(B6-I6)/B6) -> 0
A7: 합계 | B7: =SUM(B5:B6) -> 12 | C7: =SUM(C5:C6) -> 0 | D7: =SUM(D5:D6) -> 0 | E7: =SUM(E5:E6) -> 0 | F7: =SUM(F5:F6) -> 0 | G7: =SUM(G5:G6) -> 0 | H7: =SUM(H5:H6) -> 0 | I7: =SUM(I5:I6) -> 12 | J7: =IF(B7=0,0,(B7-I7)/B7) -> 0

Sheet 이행 관리
A1: 업무 관리 — 이행 관리
A2: 🗂 주로 QA박안전5 창에서 합니다. 4번에서 올린 내 서류로 5·6번을 이어서 하고, 다른 사람이 올린 서류는 확인·반려하지 않습니다.
A3: 번호 | B3: 누구로 | C3: 어디서 | D3: 확인할 것 | E3: 해 볼 것 | F3: 이러면 성공 | G3: 결과 ▼ | H3: 메모 (실패·오류·문의일 때) | I3: 사진 (필요할 때 붙여넣기)
A4: 1 | B4: QA박안전5(재난안전과) | C4: 업무 관리 > 이행 관리 | D4: 첫 화면과 단위 바꾸기 | E4: ① 메뉴로 들어가 기준연도를 본다 ② 군 단위 · 부서 단위 · 관리대상 단위 탭을 차례로 누른다 ③ [누락 점검] 탭을 누른다 | F4: 왼쪽 메뉴 이름이 «이행 관리»다(«법정 업무 현황»이면 «실패» — 2026-09-28 «이행 관리»로 확정). 기준연도가 2025다. 탭마다 표가 바뀐다. 군 단위·누락 점검 탭의 숫자와 목록 위 «…개» 숫자가 같다(다르면 새로고침 뒤 다시 본다)
A5: 2 | B5: QA박안전5(재난안전과) | C5: 업무 관리 > 이행 관리 | D5: 상태 칩과 엑셀 내려받기 | E5: ① 군 단위에서 숫자가 0이 아닌 상태 칩(예: 미이행)을 누른다 ② [엑셀 내려받기] | F5: 칩의 숫자와 목록 위 «…개 할 일»이 같다. «…csv 내려받기 (…행)» 알림의 행 수도 같은 숫자다
A6: 3 | B6: QA박안전5(재난안전과) | C6: 업무 관리 > 이행 관리 | D6: 할 일 상세와 쪽 넘기기 | E6: ① 서류가 10건 넘는 할 일 줄을 누른다 ② 아래 문서 목록에서 [›]로 다음 쪽 ③ 쪽 번호 칸에 마지막 쪽보다 큰 수를 치고 Enter ④ [‹ 단계별 이행현황으로] | F6: 상세가 열리고 쪽이 넘어간다. 너무 큰 쪽 번호는 마지막 쪽으로 가고 빈 화면이 되지 않는다. 돌아가면 보던 목록이 나온다
A7: 4 | B7: QA박안전5(재난안전과) | C7: 업무 관리 > 이행 관리 | D7: 서류 올리기 | E7: ① [누락 점검] 탭에서 서류가 0건인 할 일 하나를 고른다 — 목록 맨 위 말고 중간쯤을 골라 다른 사람과 겹치지 않게 하고 이름을 적어 둔다 ② 기준연도 2025 그대로 [＋ 서류 올리기] → 빈 채로 [다음 — 무슨 일인지 고르기 →] ③ 파일 1개, 문서명 «김유석_2025 점검 결과», 보고일자(2025년 안), «내부 문서», 담당부서·담당자(조직도에서 재난안전과 한 사람)를 채우고 다음 ④ 할 일을 고르지 않고 [다음 — 확인 →] ⑤ ①의 할 일을 검색해 고르고 [이대로 등록] ⑥ 결과 창은 [닫기] (되돌리기는 누르지 않는다 — 이 서류를 아래 줄에서 쓴다) | F7: 빈 칸마다 빨간 안내와 «…확인해 주세요.»가 뜬다. 할 일 없이는 «이 문서가 증빙하는 업무단계를 하나 이상 선택해야 합니다.» 등록하면 결과 창에 만든 문서 링크와 [방금 만든 1건 되돌리기]가 있다
A8: 5 | B8: QA박안전5(재난안전과) | C8: 업무 관리 > 이행 관리 | D8: 서류 확인 — 반려·완료·되돌리기 | E8: ① 문서 목록 검색창에 «김유석_2025» → 4번 문서를 열고 위의 할 일 이름을 누른다. 할 일 상세의 문서 목록에 내 서류 한 건만 있을 때만 이어서 한다(다른 사람 서류도 있으면 «확인 불가») ② [확인하기] → [확인 반려] → 사유 없이 [확인 반려] ③ 사유를 적고 [확인 반려] ④ [확인하기] → [완료 처리] ⑤ [확인 되돌리기] → [완료 되돌리기] | F8: 사유 없이는 «반려 사유를 입력해야 저장됩니다.» 반려하면 상세에 «확인 반려 — (적은 사유)»가 보인다. 완료 처리하면 «완료 확인됨»과 확인한 사람(QA박안전5 계정)이 보이고, 되돌리면 다시 [확인하기]가 나오며 상태가 처음(진행중)으로 돌아간다
A9: 6 | B9: QA하정수5(담당 공무원) | C9: 업무 관리 > 이행 관리 | D9: 담당 공무원은 확인·비해당을 못 한다 | E9: ① QA하정수5 창에서 메뉴로 들어가 첫 화면을 본다 ② QA박안전5 창에 열려 있는 5번 할 일 상세의 주소(끝에 «stage=…»가 붙어 있다)를 복사해 QA하정수5 창 주소창에 붙여 넣고 Enter | F9: 첫 화면은 «부서 단위»에 내 부서(보건소) 조건이 걸려 내 부서 줄만 보인다. 할 일 상세에는 [확인하기]·[확인 반려]·[비해당 — 사유 기재]가 없다([＋ 서류 올리기]는 있다)

Sheet 문서 목록
A1: 업무 관리 — 문서 목록
A2: 🗂 주로 QA박안전5 창에서 합니다. 미분류 문서는 실제 원장 문서라 분류를 저장하지 않고, 11번에서 내가 만든 서류를 지워 처음 상태로 돌려 둡니다.
A3: 번호 | B3: 누구로 | C3: 어디서 | D3: 확인할 것 | E3: 해 볼 것 | F3: 이러면 성공 | G3: 결과 ▼ | H3: 메모 (실패·오류·문의일 때) | I3: 사진 (필요할 때 붙여넣기)
A4: 7 | B4: QA박안전5(재난안전과) | C4: 업무 관리 > 문서 목록 | D4: 조건 걸기 | E4: ① 연도 칩 하나를 누르고 검색창에 낱말을 친다 ② [업무단계 고르기]에서 할 일 2개 → [적용] ③ 새로고침 ④ [필터 초기화] | F4: 조건대로 목록이 줄고, 새로고침 뒤에도 연도·검색어·할 일 2개가 남는다. 초기화하면 풀리고 연도는 기본(2025)으로 돌아간다
A5: 8 | B5: QA박안전5(재난안전과) | C5: 업무 관리 > 문서 목록 | D5: 문서 상세 | E5: ① 할 일이 붙은 2025 문서 하나를 연다 ② 위의 할 일 이름을 누른다 | F5: 문서번호 · 수발신 · 담당부서 · 데이터 구분(«문서 원장 실측»)과 연결된 할 일이 보인다. 할 일을 누르면 이행 관리의 그 할 일 상세로 간다
A6: 9 | B6: QA박안전5(재난안전과) → QA하정수5(담당 공무원) | C6: 업무 관리 > 문서 목록 | D6: 미분류 문서 — 분류 붙이기 | E6: ① «미분류» 칩이 붙은 문서 하나를 열고 문서명을 적어 둔다 ② [업무단계 지정] → 아무것도 고르지 않고 [저장] → [취소] (할 일을 골라 저장하지 않는다 — 실제 원장 문서라 되돌릴 수 없다) ③ QA하정수5 창의 문서 목록에서 ①의 문서명을 검색해 연다 | F6: 상세 오른쪽에 «분류 붙이기»와 [업무단계 지정]이 있다. 빈 저장은 «업무단계를 하나 이상 선택해야 저장됩니다.»로 막힌다. QA하정수5 계정에는 버튼 대신 «조회 전용 — 원장 교정은 주관부서(재난안전과) 담당자가 수행합니다.»가 보인다. 미분류 문서가 없으면 «확인 불가» (실제 분류 저장은 원장을 바꾸므로 이 시트에서 확인하지 않는다)
A7: 10 | B7: QA박안전5(재난안전과) | C7: 업무 관리 > 문서 목록 | D7: 올해로 이어받기 | E7: ① 검색창에 «김유석_2025» → 4번 문서를 연다 ② [📄 올해 문서로 등록] ③ 새 문서의 «가져온 원본»을 눌러 원본으로 돌아간다 ④ [만든 문서 보기] | F7: «…년 문서로 등록했습니다»가 뜨고 올해 문서 «김유석_(올해 연도) 점검 결과»가 생긴다. 원본에는 [📄 올해 문서로 등록] 대신 «이어받기 완료»와 [만든 문서 보기]가 있고, [만든 문서 보기]를 누르면 방금 만든 문서가 열린다
A8: 11 | B8: QA박안전5(재난안전과) | C8: 업무 관리 > 문서 목록 | D8: 내가 만든 서류 지우기 | E8: ① 연도 칩 «전체»에서 검색창에 김유석 → 10번에서 만든 올해 문서를 열고 [문서 삭제] → [삭제] ② 4번 문서(«김유석_2025 점검 결과»)도 같은 방법으로 지운다 ③ 이행 관리 [누락 점검] 탭에서 4번의 할 일을 찾는다 | F8: 삭제 창이 회수될 할 일 연결을 먼저 알려 주고, 지우면 «문서를 삭제했습니다 — 할 일 연결 1건이 함께 회수되었습니다.» 두 문서가 목록에서 사라지고 4번의 할 일이 다시 누락 점검에 나온다(그 사이 다른 사람이 같은 할 일에 서류를 올렸으면 다시 나오지 않을 수 있다 — 그 경우 문서 목록에서 내 두 문서가 사라졌는지만 본다)
A9: 12 | B9: QA박안전5(재난안전과) | C9: 업무 관리 왼쪽 메뉴 | D9: 메뉴 구성 | E9: 업무 관리의 왼쪽 메뉴를 본다 | F9: 이행 관리와 문서 목록 둘뿐이고 기준문서함은 없다

Sheet _정보
A1: 형식 | B1: QA엑셀 v1.1
A2: 메뉴 | B2: 업무 관리
A3: 담당자 | B3: 김유석
A4: 파일 코드 | B4: CP
A5: 종류 | B5: 스모크
A6: 생성일 | B6: 2026-09-30
A7: 결과 값 | B7: 성공,실패,오류,보류,확인 불가,문의
A8: 머리 행 | B8: 3
A9: 열 | B9: 번호,누구로,어디서,확인할,해,이러면,결과,메모,사진
