Workbook

Sheet 안내
A1: QA 담양 중대재해 — 시스템 관리 · 김유석
A3: 메뉴 | B3: 시스템 관리 (훑어보는 파일)
A4: 담당자 | B4: 김유석
A5: 내 계정 | B5: QA박안전5 (재난안전과 담당자) · QA하정수5 (내 부서 보건소 담당 공무원)
A6: 이 파일 | B6: 시스템 관리 권한을 받은 QA박안전5 계정으로 합니다 — 그 창 맨 위에 «시스템 관리»가 없으면 QA박안전5 줄은 모두 «확인 불가». 여기 설정은 다른 사람 화면에 바로 영향을 주므로 내가 만든 «김유석_…» 항목만 바꾸고, 기존 값을 바꿨으면 같은 줄에서 되돌립니다.
A7: 줄 수 | B7: 11줄
A8: 시트 | B8: 사용자·권한 → 기준정보 → 연계·알림
A9: 테스트 주소 | B9: https://safety.damyang.go.kr/login
A10: 브라우저
A11: 기기
A12: 시작한 날
A14: 이렇게 하면 됩니다
A15: ① 위 «테스트 주소»에서 받은 아이디·비밀번호로 로그인합니다. 로그인하면 통합 현황 화면으로 갑니다. 5번 틀리면 계정이 잠깁니다 — 담당 개발자에게 풀어 달라고 합니다.
A16: ② 내 계정 두 개를 창 두 개에 따로 로그인해 둡니다 — 일반 창에는 QA박안전5(재난안전과), 시크릿 창(Ctrl + Shift + N · 맥 Cmd + Shift + N)에는 QA하정수5(담당 공무원). 두 창을 나란히 두면 계정을 바꿀 필요가 없습니다.
A17: ③ «누구로» 칸에 적힌 계정의 창에서 «어디서» 메뉴로 가서 «해 볼 것»대로 눌러 봅니다.
A18: ④ «이러면 성공»과 같으면 «결과» 칸에서 성공을, 다르면 실패·오류 등을 고릅니다.
A19: ⑤ 실패·오류·문의면 «메모»에 한 줄 적고, 필요하면 «사진» 칸에 화면 캡처를 붙여넣습니다.
A21: 결과 고르는 법
A22: 결과 | B22: 이럴 때 고르세요
A23: 성공 | B23: «이러면 성공»대로 된다
A24: 실패 | B24: 되긴 하는데 설명과 다르다 — 막혀야 하는데 저장된다, 문구·숫자가 틀리다
A25: 오류 | B25: 화면이 멈추거나 깨진다, 눌러도 아무 일이 없다, 오류 창이 뜬다
A26: 보류 | B26: 앞 단계가 안 돼서 지금은 못 한다 — 메모에 이유
A27: 확인 불가 | B27: 이 환경에서는 볼 수 없다 — 예: 확인할 데이터가 없다
A28: 문의 | B28: 맞는지 헷갈린다 — 메모에 궁금한 점
A30: 사진 붙이는 법
A31: • 윈도우: Win + Shift + S → 영역 선택 → 엑셀에서 그 줄의 «사진» 칸을 누르고 Ctrl + V
A32: • 맥: Cmd + Ctrl + Shift + 4 → 영역 선택 → 엑셀에서 그 줄의 «사진» 칸을 누르고 Cmd + V
A33: • 사진이 크면 모서리를 끌어 줄이세요. 사진은 그 줄 «사진» 칸 위에 두면 됩니다 — 취합할 때 줄 번호로 찾습니다.
A34: • 사진은 떠 있는 그대로 두세요(«셀에 배치»로 넣으면 취합할 때 꺼내지 못합니다).
A36: 누구로 — 내 계정 두 개
A37: • 계정은 두 개뿐입니다. «누구로» 칸에 계정 이름과 권한이 함께 적혀 있습니다. 비밀번호는 따로 받습니다.
A38: 이름 | B38: 권한 | D38: 볼 수 있는 것 | F38: 주로 하는 것
A39: QA박안전5 | B39: 재난안전과 담당자 | D39: 모든 부서 · «내 할일»은 전체 | F39: 전 부서 등록·수정 · 확인 · 상신 · 독촉 — 대부분 이 계정
A40: QA하정수5 | B40: 담당 공무원 (내 부서: 보건소) | D40: 업무 화면은 전 부서, «내 할일»은 나에게 지정된 것만, 위험성평가 부서별 조치표·교육 이수현황은 내 부서만 | F40: 내 부서 일 · 남의 부서 것을 못 건드리는지 확인
A41: QA시스템관리 | B41: 시스템 관리자 (김유석만) | D41: 시스템 관리 메뉴 | F41: 시스템 관리 파일 · 공문 반려(결재 대행)
A43: 같은 서버를 6명이 함께 씁니다
A44: • 내가 만드는 것(교육 · 근로자 · 문서 · 위원 등)은 이름 앞에 내 이름을 붙입니다 — 예: «김유석_집합교육». 그래야 내 것을 찾기 쉽습니다.
A45: • 다른 사람이 만든 것은 고치거나 지우지 않습니다. QA박안전5 계정에는 남의 것도 보이는데, 정상입니다.
A46: • 건수·이수율 같은 숫자는 다른 사람이 작업하는 동안 바뀔 수 있습니다. 숫자가 안 맞으면 새로고침해서 한 번 더 보고, 그래도 다르면 «실패».
...

Sheet 요약
A1: 진행 상황 — 시스템 관리 · 김유석
A2: 결과를 고르면 저절로 채워집니다. 남은 것 = 아직 결과를 고르지 않은 줄입니다.
A4: 시트 | B4: 전체 | C4: 성공 | D4: 실패 | E4: 오류 | F4: 보류 | G4: 확인 불가 | H4: 문의 | I4: 남은 것 | J4: 진행률
A5: 사용자·권한 | B5: =COUNTA('사용자·권한'!$A$4:$A$8) -> 5 | C5: =COUNTIF('사용자·권한'!$G$4:$G$8,"성공") -> 0 | D5: =COUNTIF('사용자·권한'!$G$4:$G$8,"실패") -> 0 | E5: =COUNTIF('사용자·권한'!$G$4:$G$8,"오류") -> 0 | F5: =COUNTIF('사용자·권한'!$G$4:$G$8,"보류") -> 0 | G5: =COUNTIF('사용자·권한'!$G$4:$G$8,"확인 불가") -> 0 | H5: =COUNTIF('사용자·권한'!$G$4:$G$8,"문의") -> 0 | I5: =COUNTBLANK('사용자·권한'!$G$4:$G$8) -> 5 | J5: =IF(B5=0,0,(B5-I5)/B5) -> 0
A6: 기준정보 | B6: =COUNTA('기준정보'!$A$4:$A$6) -> 3 | C6: =COUNTIF('기준정보'!$G$4:$G$6,"성공") -> 0 | D6: =COUNTIF('기준정보'!$G$4:$G$6,"실패") -> 0 | E6: =COUNTIF('기준정보'!$G$4:$G$6,"오류") -> 0 | F6: =COUNTIF('기준정보'!$G$4:$G$6,"보류") -> 0 | G6: =COUNTIF('기준정보'!$G$4:$G$6,"확인 불가") -> 0 | H6: =COUNTIF('기준정보'!$G$4:$G$6,"문의") -> 0 | I6: =COUNTBLANK('기준정보'!$G$4:$G$6) -> 3 | J6: =IF(B6=0,0,(B6-I6)/B6) -> 0
A7: 연계·알림 | B7: =COUNTA('연계·알림'!$A$4:$A$6) -> 3 | C7: =COUNTIF('연계·알림'!$G$4:$G$6,"성공") -> 0 | D7: =COUNTIF('연계·알림'!$G$4:$G$6,"실패") -> 0 | E7: =COUNTIF('연계·알림'!$G$4:$G$6,"오류") -> 0 | F7: =COUNTIF('연계·알림'!$G$4:$G$6,"보류") -> 0 | G7: =COUNTIF('연계·알림'!$G$4:$G$6,"확인 불가") -> 0 | H7: =COUNTIF('연계·알림'!$G$4:$G$6,"문의") -> 0 | I7: =COUNTBLANK('연계·알림'!$G$4:$G$6) -> 3 | J7: =IF(B7=0,0,(B7-I7)/B7) -> 0
A8: 합계 | B8: =SUM(B5:B7) -> 11 | C8: =SUM(C5:C7) -> 0 | D8: =SUM(D5:D7) -> 0 | E8: =SUM(E5:E7) -> 0 | F8: =SUM(F5:F7) -> 0 | G8: =SUM(G5:G7) -> 0 | H8: =SUM(H5:H7) -> 0 | I8: =SUM(I5:I7) -> 11 | J8: =IF(B8=0,0,(B8-I8)/B8) -> 0

Sheet 사용자·권한
A1: 시스템 관리 — 사용자·권한
A2: 🗂 QA시스템관리 계정으로 합니다. 내가 만든 등급 말고는 저장하지 않습니다.
A3: 번호 | B3: 누구로 | C3: 어디서 | D3: 확인할 것 | E3: 해 볼 것 | F3: 이러면 성공 | G3: 결과 ▼ | H3: 메모 (실패·오류·문의일 때) | I3: 사진 (필요할 때 붙여넣기)
A4: 1 | B4: QA시스템관리(시스템 관리) → QA하정수5(담당 공무원) | C4: 시스템 관리 (8개 화면) | D4: 누구에게 메뉴가 보이나 | E4: ① QA박안전5 창에서 맨 위 «시스템 관리»를 누르고 왼쪽 메뉴 8개를 차례로 연다 ② QA하정수5 창에서 맨 위 메뉴와 [전체메뉴]를 본다 | F4: QA박안전5 계정: 8개 화면이 오류 없이 뜬다. QA하정수5 계정: «시스템 관리»가 맨 위 메뉴에도 전체메뉴에도 없다
A5: 2 | B5: QA시스템관리(시스템 관리) | C5: 시스템 관리 > 사용자 관리 | D5: 사용자 목록 | E5: ① 사용자 목록 검색창에 내 부서 이름(보건소)을 치고 [검색] ② 검색을 지우고 내 계정(QA박안전5) 줄의 [접근 메뉴] | F5: 검색대로 걸러져 QA하정수5 계정이 나온다. [접근 메뉴] 창에 «접근 가능 …개 / 전체 …개 메뉴»와 메뉴별 보기·수정·근거가 보인다
A6: 3 | B6: QA시스템관리(시스템 관리) | C6: 시스템 관리 > 사용자 관리 | D6: 조직 직접 등록 | E6: ① [+ 부서 직접 등록] → 빈 채로 [저장] ② 부서명 «김유석_QA조직», 유형 «임시조직»으로 [저장] ③ 그 줄의 [수정] → 부서명을 «김유석_QA조직2»로 [저장] ④ 그 줄의 [사용 중지] | F6: 빈 채로는 «부서명을 입력하세요.» 저장하면 «조직을 직접 등록했습니다.», 수정하면 «조직 정보를 수정했습니다.»가 뜨고 표에 반영된다. 사용 중지하면 «참조를 보존하고 조직을 사용 중지했습니다.»와 상태 «사용 중지». 출처가 «연계»인 줄에는 «읽기 전용»만 있다
A7: 4 | B7: QA시스템관리(시스템 관리) | C7: 시스템 관리 > 권한 관리 | D7: 권한 등급 | E7: ① 왼쪽 등급을 하나씩 눌러 본다(바꾸지 않는다) ② [+ 등급 추가] → 등급명을 비운 채 [저장] ③ 등급명 «김유석_QA등급»으로 [저장] (전체 권한·구성원 자동은 체크하지 않고 구성원도 넣지 않는다) ④ 만든 등급의 [등급 삭제] → 확인 | F7: 등급마다 구성원·적용 메뉴가 보이고, «시스템 관리자»에는 «보호» 표시가 있고 [등급 삭제]가 없다. 빈 등급명은 «등급명을 입력하세요.» 저장하면 «등급이 추가되었습니다.», 삭제하면 «등급이 삭제되었습니다.»가 뜨고 목록에서 사라진다
A8: 5 | B8: QA시스템관리(시스템 관리) | C8: 시스템 관리 > 메뉴 관리 | D8: 메뉴 트리 | E8: ① 왼쪽 메뉴 몇 개를 눌러 오른쪽 접근 권한을 본다 ② 시스템 관리 메뉴 하나를 누른다 ③ 메뉴명 검색창에 «문서» ([저장]·사용 여부 스위치·[다른 메뉴 설정 복사]는 누르지 않는다) | F8: 메뉴가 대메뉴 순서대로 보이고 누르면 권한 목록이 나온다. 시스템 관리 메뉴는 시스템 관리자만 접근한다는 안내가 나온다. 메뉴에서 뺀 화면(예: 문서 상세)에는 «메뉴 제외» 표시가 붙어 있다

Sheet 기준정보
A1: 시스템 관리 — 기준정보
A2: 🗂 사업장·양식은 «김유석_…»으로 만든 것만 바꿉니다. 사업장 사용 중지는 정한 시간에 하고 바로 되돌립니다(모두의 화면이 바뀝니다).
A3: 번호 | B3: 누구로 | C3: 어디서 | D3: 확인할 것 | E3: 해 볼 것 | F3: 이러면 성공 | G3: 결과 ▼ | H3: 메모 (실패·오류·문의일 때) | I3: 사진 (필요할 때 붙여넣기)
A4: 6 | B4: QA시스템관리(시스템 관리) | C4: 시스템 관리 > 사업장 관리 | D4: 사업장 등록·편집·사용 중지 | E4: ① [＋ 사업장 등록] → 사업장명을 비운 채 [등록] ② 관할 부서는 내 부서(보건소), 사업장명 «김유석_QA사업장»으로 [등록] ③ 그 줄의 [편집] → 비고를 적고 [저장] ④ 그 줄의 [사용 중지] → 사유 없이 [사용 중지] → 사유를 적고 [사용 중지] | F4: 빈 칸이면 «사업장명을 입력하세요.» «사용 중지 사유를 입력하세요.»로 막힌다. 등록·저장하면 «사업장이 등록되었습니다.» «사업장이 저장되었습니다.» 사용 중지하면 «사업장이 비활성화되었습니다.»가 뜨고 그 줄에 사유·처리자가 남는다
A5: 7 | B5: QA시스템관리(시스템 관리) | C5: 시스템 관리 > 프리셋 양식 관리 | D5: 양식 편집 | E5: ① 목록의 양식 하나에서 [편집] ② [+ 새 양식] → 양식명을 «김유석_양식»으로 ③ [+ 필드 추가] → [미리보기] → [닫기] ④ [저장] | F5: [편집]하면 «…양식을 불러왔습니다»가 뜬다. 미리보기에 추가한 필드가 보인다. [저장]은 «양식 저장은 양식 관리 연계 후 제공됩니다»가 뜨고 목록의 양식은 그대로다
A6: 8 | B6: QA시스템관리(시스템 관리) | C6: 시스템 관리 > 법령 관리 | D6: 조문 찾기 | E6: ① «자주 찾는 질문» 하나를 누른다 ② 검색창에 «교육 시간» ③ [메뉴 근거 매핑] 탭 → [변경 이력] 탭 ([매핑 재검토 요청]은 누르지 않는다) | F6: 조문 원문과 «쉬운 설명 — 요약 — 법적 효력은 원문에 있습니다» 설명이 보이고 검색 결과가 나온다. 매핑 탭에는 편집·저장 버튼이 없다

Sheet 연계·알림
A1: 시스템 관리 — 연계·알림
A2: 🗂 바꾼 상태·체크는 같은 줄 안에서 원래대로 돌려 둡니다. 준비 목록 창의 [상태 초기화]는 누르지 않습니다.
A3: 번호 | B3: 누구로 | C3: 어디서 | D3: 확인할 것 | E3: 해 볼 것 | F3: 이러면 성공 | G3: 결과 ▼ | H3: 메모 (실패·오류·문의일 때) | I3: 사진 (필요할 때 붙여넣기)
A4: 9 | B4: QA시스템관리(시스템 관리) | C4: 시스템 관리 > 연계 관리 | D4: 외부 자료 준비 상태 | E4: ① [준비 목록 보기] ② 목록 끝쪽에서 «수신 완료»가 아닌 항목 하나를 골라(다른 사람과 겹치지 않게) 지금 상태를 기억하고 «수신 완료»를 누른다 ③ [닫기] → 다시 [준비 목록 보기] ④ 그 항목을 원래 상태로 되돌린다(아무것도 안 눌려 있었으면 맨 앞 칸) | F4: 누르자마자 그 항목에 «수신 완료» 표시가 붙는다. 다시 열어도 그대로다. ④에서 되돌리면 그 항목이 원래 상태로 돌아간다(위쪽 숫자는 다른 사람 작업으로 달라질 수 있다)
A5: 10 | B5: QA시스템관리(시스템 관리) | C5: 시스템 관리 > 알림 관리 | D5: 알림 규칙 보기 | E5: ① 규칙 하나를 열어 채널 칸(화면에 있는 이름 그대로)과 수신자를 본다 ② 바꾸지 않고 닫는다 ③ 아래 발송 이력을 본다 | F5: 규칙마다 채널 켜짐·꺼짐과 수신자가 보인다. 켜는 쪽으로는 바꾸지 않는다(실제 직원에게 발송되고 취소되지 않는다)
A6: 11 | B6: QA시스템관리(시스템 관리) | C6: 관리자 화면 결재 대행 | D6: 공문 반려 | E6: ① 결재 대행 화면에서 교육 파일에서 내가 상신한 «김유석_집합교육» 공문을 찾는다 ② 사유 없이 [반려] ③ 사유를 넣고 [반려] ④ QA박안전5 창에서 그 교육을 새로고침한다 | F6: 사유 없이는 막힌다. 반려하면 교육 잠금이 풀리고 [공문 기안]으로 다시 기안할 수 있다

Sheet _정보
A1: 형식 | B1: QA엑셀 v1.1
A2: 메뉴 | B2: 시스템 관리
A3: 담당자 | B3: 김유석
A4: 파일 코드 | B4: AD
A5: 종류 | B5: 스모크
A6: 생성일 | B6: 2026-09-30
A7: 결과 값 | B7: 성공,실패,오류,보류,확인 불가,문의
A8: 머리 행 | B8: 3
A9: 열 | B9: 번호,누구로,어디서,확인할,해,이러면,결과,메모,사진
