Workbook

Sheet 안내
A1: QA 담양 중대재해 — 공통 · 윤성현
A3: 메뉴 | B3: 공통 (훑어보는 파일)
A4: 담당자 | B4: 윤성현
A5: 내 계정 | B5: QA박안전1 (재난안전과 담당자) · QA하정수1 (내 부서 물순환사업소 담당 공무원)
A6: 이 파일 | B6: 어느 메뉴에도 속하지 않는 화면 맨 위(메뉴·알림·도움말·계정)와 모든 화면에 걸리는 공통 동작을 봅니다. 대부분 QA박안전1 창에서 하고, 권한 차이는 QA하정수1 창과 비교합니다.
A7: 줄 수 | B7: 16줄
A8: 시트 | B8: 메뉴·화면 → 계정·권한 → 공통 동작
A9: 테스트 주소 | B9: https://safety.damyang.go.kr/login
A10: 브라우저
A11: 기기
A12: 시작한 날
A14: 이렇게 하면 됩니다
A15: ① 위 «테스트 주소»에서 받은 아이디·비밀번호로 로그인합니다. 로그인하면 통합 현황 화면으로 갑니다. 5번 틀리면 계정이 잠깁니다 — 담당 개발자에게 풀어 달라고 합니다.
A16: ② 내 계정 두 개를 창 두 개에 따로 로그인해 둡니다 — 일반 창에는 QA박안전1(재난안전과), 시크릿 창(Ctrl + Shift + N · 맥 Cmd + Shift + N)에는 QA하정수1(담당 공무원). 두 창을 나란히 두면 계정을 바꿀 필요가 없습니다.
A17: ③ «누구로» 칸에 적힌 계정의 창에서 «어디서» 메뉴로 가서 «해 볼 것»대로 눌러 봅니다.
A18: ④ «이러면 성공»과 같으면 «결과» 칸에서 성공을, 다르면 실패·오류 등을 고릅니다.
A19: ⑤ 실패·오류·문의면 «메모»에 한 줄 적고, 필요하면 «사진» 칸에 화면 캡처를 붙여넣습니다.
A21: 결과 고르는 법
A22: 결과 | B22: 이럴 때 고르세요
A23: 성공 | B23: «이러면 성공»대로 된다
A24: 실패 | B24: 되긴 하는데 설명과 다르다 — 막혀야 하는데 저장된다, 문구·숫자가 틀리다
A25: 오류 | B25: 화면이 멈추거나 깨진다, 눌러도 아무 일이 없다, 오류 창이 뜬다
A26: 보류 | B26: 앞 단계가 안 돼서 지금은 못 한다 — 메모에 이유
A27: 확인 불가 | B27: 이 환경에서는 볼 수 없다 — 예: 확인할 데이터가 없다
A28: 문의 | B28: 맞는지 헷갈린다 — 메모에 궁금한 점
A30: 사진 붙이는 법
A31: • 윈도우: Win + Shift + S → 영역 선택 → 엑셀에서 그 줄의 «사진» 칸을 누르고 Ctrl + V
A32: • 맥: Cmd + Ctrl + Shift + 4 → 영역 선택 → 엑셀에서 그 줄의 «사진» 칸을 누르고 Cmd + V
A33: • 사진이 크면 모서리를 끌어 줄이세요. 사진은 그 줄 «사진» 칸 위에 두면 됩니다 — 취합할 때 줄 번호로 찾습니다.
A34: • 사진은 떠 있는 그대로 두세요(«셀에 배치»로 넣으면 취합할 때 꺼내지 못합니다).
A36: 누구로 — 내 계정 두 개
A37: • 계정은 두 개뿐입니다. «누구로» 칸에 계정 이름과 권한이 함께 적혀 있습니다. 비밀번호는 따로 받습니다.
A38: 이름 | B38: 권한 | D38: 볼 수 있는 것 | F38: 주로 하는 것
A39: QA박안전1 | B39: 재난안전과 담당자 | D39: 모든 부서 · «내 할일»은 전체 | F39: 전 부서 등록·수정 · 확인 · 상신 · 독촉 — 대부분 이 계정
A40: QA하정수1 | B40: 담당 공무원 (내 부서: 물순환사업소) | D40: 업무 화면은 전 부서, «내 할일»은 나에게 지정된 것만, 위험성평가 부서별 조치표·교육 이수현황은 내 부서만 | F40: 내 부서 일 · 남의 부서 것을 못 건드리는지 확인
A41: QA시스템관리 | B41: 시스템 관리자 (김유석만) | D41: 시스템 관리 메뉴 | F41: 시스템 관리 파일 · 공문 반려(결재 대행)
A43: 같은 서버를 6명이 함께 씁니다
A44: • 내가 만드는 것(교육 · 근로자 · 문서 · 위원 등)은 이름 앞에 내 이름을 붙입니다 — 예: «윤성현_집합교육». 그래야 내 것을 찾기 쉽습니다.
A45: • 다른 사람이 만든 것은 고치거나 지우지 않습니다. QA박안전1 계정에는 남의 것도 보이는데, 정상입니다.
A46: • 건수·이수율 같은 숫자는 다른 사람이 작업하는 동안 바뀔 수 있습니다. 숫자가 안 맞으면 새로고침해서 한 번 더 보고, 그래도 다르면 «실패».
...

Sheet 요약
A1: 진행 상황 — 공통 · 윤성현
A2: 결과를 고르면 저절로 채워집니다. 남은 것 = 아직 결과를 고르지 않은 줄입니다.
A4: 시트 | B4: 전체 | C4: 성공 | D4: 실패 | E4: 오류 | F4: 보류 | G4: 확인 불가 | H4: 문의 | I4: 남은 것 | J4: 진행률
A5: 메뉴·화면 | B5: =COUNTA('메뉴·화면'!$A$4:$A$8) -> 5 | C5: =COUNTIF('메뉴·화면'!$G$4:$G$8,"성공") -> 0 | D5: =COUNTIF('메뉴·화면'!$G$4:$G$8,"실패") -> 0 | E5: =COUNTIF('메뉴·화면'!$G$4:$G$8,"오류") -> 0 | F5: =COUNTIF('메뉴·화면'!$G$4:$G$8,"보류") -> 0 | G5: =COUNTIF('메뉴·화면'!$G$4:$G$8,"확인 불가") -> 0 | H5: =COUNTIF('메뉴·화면'!$G$4:$G$8,"문의") -> 0 | I5: =COUNTBLANK('메뉴·화면'!$G$4:$G$8) -> 5 | J5: =IF(B5=0,0,(B5-I5)/B5) -> 0
A6: 계정·권한 | B6: =COUNTA('계정·권한'!$A$4:$A$7) -> 4 | C6: =COUNTIF('계정·권한'!$G$4:$G$7,"성공") -> 0 | D6: =COUNTIF('계정·권한'!$G$4:$G$7,"실패") -> 0 | E6: =COUNTIF('계정·권한'!$G$4:$G$7,"오류") -> 0 | F6: =COUNTIF('계정·권한'!$G$4:$G$7,"보류") -> 0 | G6: =COUNTIF('계정·권한'!$G$4:$G$7,"확인 불가") -> 0 | H6: =COUNTIF('계정·권한'!$G$4:$G$7,"문의") -> 0 | I6: =COUNTBLANK('계정·권한'!$G$4:$G$7) -> 4 | J6: =IF(B6=0,0,(B6-I6)/B6) -> 0
A7: 공통 동작 | B7: =COUNTA('공통 동작'!$A$4:$A$10) -> 7 | C7: =COUNTIF('공통 동작'!$G$4:$G$10,"성공") -> 0 | D7: =COUNTIF('공통 동작'!$G$4:$G$10,"실패") -> 0 | E7: =COUNTIF('공통 동작'!$G$4:$G$10,"오류") -> 0 | F7: =COUNTIF('공통 동작'!$G$4:$G$10,"보류") -> 0 | G7: =COUNTIF('공통 동작'!$G$4:$G$10,"확인 불가") -> 0 | H7: =COUNTIF('공통 동작'!$G$4:$G$10,"문의") -> 0 | I7: =COUNTBLANK('공통 동작'!$G$4:$G$10) -> 7 | J7: =IF(B7=0,0,(B7-I7)/B7) -> 0
A8: 합계 | B8: =SUM(B5:B7) -> 16 | C8: =SUM(C5:C7) -> 0 | D8: =SUM(D5:D7) -> 0 | E8: =SUM(E5:E7) -> 0 | F8: =SUM(F5:F7) -> 0 | G8: =SUM(G5:G7) -> 0 | H8: =SUM(H5:H7) -> 0 | I8: =SUM(I5:I7) -> 16 | J8: =IF(B8=0,0,(B8-I8)/B8) -> 0

Sheet 메뉴·화면
A1: 공통 — 메뉴·화면
A2: 🗂 QA박안전1 창에서 합니다. 1번만 QA하정수1 창과 비교합니다.
A3: 번호 | B3: 누구로 | C3: 어디서 | D3: 확인할 것 | E3: 해 볼 것 | F3: 이러면 성공 | G3: 결과 ▼ | H3: 메모 (실패·오류·문의일 때) | I3: 사진 (필요할 때 붙여넣기)
A4: 1 | B4: QA박안전1(재난안전과) → QA하정수1(담당 공무원) | C4: 화면 맨 위 메뉴 줄 | D4: 메뉴 개수 | E4: 두 창에서 맨 위 메뉴를 센다 | F4: QA하정수1 창은 10개이고 «시스템 관리»가 없다. QA박안전1 창은 시스템 관리 권한이 있으면 11개(맨 끝 «시스템 관리»), 없으면 10개다
A5: 2 | B5: QA박안전1(재난안전과) | C5: 왼쪽 메뉴 | D5: 왼쪽 메뉴 묶음 제목 | E5: 안전보건교육과 인력·예산의 왼쪽 메뉴를 본다(시스템 관리 권한이 있으면 시스템 관리도) | F5: 묶음 제목(현업근로자 · 관리감독자 · 교육 현황·관리 등)은 눌리지 않고, 지금 화면이 강조돼 있다
A6: 3 | B6: QA박안전1(재난안전과) | C6: 화면 맨 위 [전체메뉴] | D6: 전체메뉴 | E6: [전체메뉴] → 아무 항목이나 누른다 | F6: 모든 메뉴가 한 창에 보이고 누르면 그 화면으로 간다
A7: 4 | B7: QA박안전1(재난안전과) | C7: 화면 맨 위 알림(종) | D7: 알림 | E7: 알림을 몇 개 누르고, «해당 화면 바로 열기 →»도 눌러 본다 | F7: 누를 때마다 내 할일이나 그 업무 화면으로 간다. 도착한 화면 제목 아래 안내가 «이전 버전 화면»이나 «메뉴에서 제외된 화면»으로 시작하면 실패. 알림이 없으면 «확인 불가»
A8: 5 | B8: QA박안전1(재난안전과) | C8: 화면 맨 위 [?] | D8: 도움말 | E8: ① 통합 현황 · 이행 관리 · 문서 목록 화면에서 각각 [?]를 누른다 ② «자주 하는 일»의 [바로가기 →]를 하나씩 눌러 본다 | F8: 지금 화면 설명이 나오고 [바로가기 →]를 누르면 그 화면으로 간다

Sheet 계정·권한
A1: 공통 — 계정·권한
A2: 🗂 QA박안전1 창과 QA하정수1 창을 나란히 두고 합니다. 8·9번은 결재선 창과 결재 상태 창만 열어 보고 [상신]은 누르지 않습니다.
A3: 번호 | B3: 누구로 | C3: 어디서 | D3: 확인할 것 | E3: 해 볼 것 | F3: 이러면 성공 | G3: 결과 ▼ | H3: 메모 (실패·오류·문의일 때) | I3: 사진 (필요할 때 붙여넣기)
A4: 6 | B4: QA박안전1(재난안전과) → QA하정수1(담당 공무원) | C4: 화면 오른쪽 위 이름 | D4: 창마다 내 계정으로 보인다 | E4: ① 두 창의 오른쪽 위 이름을 본다 ② 두 창을 모두 새로고침(F5)한다 | F4: 각 창에 그 창에서 로그인한 계정 이름이 보이고, 새로고침해도 다른 계정으로 바뀌지 않는다
A5: 7 | B5: QA하정수1(담당 공무원) | C5: 여러 화면 (정기·수시 위험성평가 · 이수현황 · 채용시교육 · 내 할일) | D5: 내 부서 것만 보인다 | E5: 다섯 화면을 차례로 열고, 부서 조건이 있으면 펼쳐 본다 | F5: 위험성평가 두 화면 · 채용시교육 · 내 할일에는 내 부서(물순환사업소) 것만 있고 부서 조건에도 다른 부서가 없다. 이수현황의 부서별 요약에는 다른 부서 완료율도 보이지만(정상) [상세]는 내 부서 줄에만 있다
A6: 8 | B6: QA박안전1(재난안전과) | C6: 인력·예산 > 예산 총괄표 | D6: 결재선 조직도 | E6: ① «작성중» 점검표 하나를 열어 [온나라 결재 상신] ② 검토 [조직도]를 연 채 결재 [조직도]를 누른다 ③ 결재 [조직도]를 한 번 더 누른다 ④ 조직도에서 군수·부군수와 재난안전과를 펼쳐 본다 ⑤ [기본값]을 눌러 기본 결재선을 본다 ⑥ [취소]로 닫는다 — [상신]은 누르지 않는다 | F6: 조직도는 한 번에 하나만 열리고 다시 누르면 닫힌다. 군수·부군수도 있다. QA박안전1 본인 옆에는 «기안자», 이미 고른 사람 옆에는 «검토 지정됨»·«결재 지정됨»이 붙고 고를 수 없다. 기본 결재선의 검토·결재 칸에 QA박안전1 본인이 없다(못 찾은 칸은 비어 있다). «작성중» 점검표가 없으면 «확인 불가»
A7: 9 | B7: QA박안전1(재난안전과) | C7: 인력·예산 > 예산 총괄표 | D7: 상신된 문서의 기안자는 바뀌지 않는다 | E7: ① 내가 상신하지 않은 상신된(승인완료) 점검표를 연다 ② 결재 상태 창을 열고 «결재선:» 줄과 이력 표의 «결재 상신» 줄만 본다 ③ [닫기] | F7: «결재선: 기안 ○○»의 ○○이 같은 창 이력 표의 «결재 상신» 처리자와 같고, 내 계정 이름(QA박안전1)으로 바뀌어 있지 않다. 상신된(승인완료) 점검표가 없으면 «확인 불가»

Sheet 공통 동작
A1: 공통 — 공통 동작
A2: 🗂 QA박안전1 창에서 합니다. 12번에서 만드는 것에는 내 이름을 붙이고 끝나면 지웁니다.
A3: 번호 | B3: 누구로 | C3: 어디서 | D3: 확인할 것 | E3: 해 볼 것 | F3: 이러면 성공 | G3: 결과 ▼ | H3: 메모 (실패·오류·문의일 때) | I3: 사진 (필요할 때 붙여넣기)
A4: 10 | B4: QA박안전1(재난안전과) | C4: 등록 창 3곳 이상 | D4: 빈 칸 안내 | E4: 등록 창 3곳(예: 수시 위험성평가 등록 · 협의체 운영 결과 등록 · 의견 등록)에서 필수 칸을 비우고 저장해 본다 → [취소]로 닫는다 | F4: 무엇을 채울지 알려 주고 이미 적은 값은 지워지지 않는다. 빈 채로 저장되면 «실패»
A5: 11 | B5: QA박안전1(재난안전과) | C5: 위험성평가 > 수시 위험성평가 | D5: 취소하면 저장되지 않는다 | E5: ① [＋ 수시평가 등록] → 사유를 골라 등록 창에서 내용을 적고 [취소] → 다시 연다 ② 값을 적은 채 다른 메뉴로 갔다가 돌아온다 | F5: 저장되지 않고 창이 남아 있지 않다(창 두 개가 겹치면 실패)
A6: 12 | B6: QA박안전1(재난안전과) | C6: 안전보건교육 > 교육 현황·관리 > 근로자 명단 관리 | D6: 새로고침·뒤로가기 | E6: ① [＋ 직접 등록]에서 이름 «윤성현_새로고침», 부서는 내 부서(물순환사업소)로 넣고 [등록] ② 새로고침(F5) ③ 브라우저 [뒤로] → [앞으로] ④ 끝나면 내 줄의 [삭제] → 확인 | F6: 오류가 없고 «윤성현_새로고침» 줄이 계속 남아 있다. 삭제하면 그 줄만 사라진다
A7: 13 | B7: QA박안전1(재난안전과) | C7: 여러 화면 | D7: 아직 안 되는 기능 안내 | E7: 파일 이름 누르기 · 양식 내려받기 · PDF 출력 등 3곳을 눌러 본다 | F7: 파일이 실제로 열리거나, 안 되는 기능이면 «…후 제공됩니다»처럼 알려 준다. 아무 일도 없거나, 저장이 안 됐는데 «저장했습니다»가 뜨면 실패
A8: 14 | B8: QA박안전1(재난안전과) | C8: 여러 화면 | D8: 상태 색 | E8: 완료 · 진행중 · 기한초과 · 반려가 보이는 화면 3곳을 비교한다 | F8: 같은 상태는 같은 이름·같은 색이다
A9: 15 | B9: QA박안전1(재난안전과) | C9: 여러 화면 (대시보드 · 정기 위험성평가 · 이수현황 · 문서 목록) | D9: 좁은 화면 | E9: ① 브라우저 창을 좁게(휴대폰 폭까지) 줄인다 ② 왼쪽 위 메뉴 버튼(줄 세 개)을 누른다 | F9: 글자·버튼이 겹치지 않고 화면 전체가 옆으로 밀리지 않는다. 메뉴 버튼을 누르면 왼쪽 메뉴 아래에 «다른 메뉴»가 있다
A10: 16 | B10: QA박안전1(재난안전과) | C10: 모든 메뉴 | D10: 화면에 제작용 말이 없다 | E10: 맨 위 메뉴를 모두 돌며 버튼·안내 문구를 본다 | F10: «데모» · «시연» · «프로토타입» · «더미» · «목업» 같은 말이 없다(있으면 화면과 문구를 메모에)

Sheet _정보
A1: 형식 | B1: QA엑셀 v1.1
A2: 메뉴 | B2: 공통
A3: 담당자 | B3: 윤성현
A4: 파일 코드 | B4: CM
A5: 종류 | B5: 스모크
A6: 생성일 | B6: 2026-09-30
A7: 결과 값 | B7: 성공,실패,오류,보류,확인 불가,문의
A8: 머리 행 | B8: 3
A9: 열 | B9: 번호,누구로,어디서,확인할,해,이러면,결과,메모,사진
