Workbook

Sheet 안내
A1: QA 담양 중대재해 — 위험성평가 · 윤성현
A3: 메뉴 | B3: 위험성평가 (자세히 보는 파일)
A4: 담당자 | B4: 윤성현
A5: 내 계정 | B5: QA박안전1 (재난안전과 담당자) · QA하정수1 (내 부서 물순환사업소 담당 공무원)
A6: 정기평가 진행자 | B6: 이혜린 — 진행자만 하는 줄 10개는 진행자 파일에만 있어서 번호가 건너뜁니다
A7: 이 파일 | B7: 정기 위험성평가 1건을 6명이 함께 진행하고(만들기 → 내 부서 제출·조치 → 재난안전과 확인 → 공문), 수시 위험성평가는 각자 합니다. 개발자에게 받은 계정 두 개(QA박안전1 · QA하정수1)만 씁니다.
A8: 줄 수 | B8: 44줄
A9: 시트 | B9: 1 정기평가 만들기 → 2 설문조사표·보고서 → 3 전달·조치·확인 → 4 공문·결재 → 5 수시평가
A10: 테스트 주소 | B10: https://safety.damyang.go.kr/login
A11: 브라우저
A12: 기기
A13: 시작한 날
A15: 이렇게 하면 됩니다
A16: ① 위 «테스트 주소»에서 받은 아이디·비밀번호로 로그인합니다. 로그인하면 통합 현황 화면으로 갑니다. 5번 틀리면 계정이 잠깁니다 — 담당 개발자에게 풀어 달라고 합니다.
A17: ② 내 계정 두 개를 창 두 개에 따로 로그인해 둡니다 — 일반 창에는 QA박안전1(재난안전과), 시크릿 창(Ctrl + Shift + N · 맥 Cmd + Shift + N)에는 QA하정수1(담당 공무원). 두 창을 나란히 두면 계정을 바꿀 필요가 없습니다.
A18: ③ «누구로» 칸에 적힌 계정의 창에서 «어디서» 메뉴로 가서 «해 볼 것»대로 눌러 봅니다.
A19: ④ «이러면 성공»과 같으면 «결과» 칸에서 성공을, 다르면 실패·오류 등을 고릅니다.
A20: ⑤ 실패·오류·문의면 «메모»에 한 줄 적고, 필요하면 «사진» 칸에 화면 캡처를 붙여넣습니다.
A22: 정기평가는 6명이 함께 — 진행 순서
A23: • 정기평가는 한 해에 1건만 만들 수 있어서 6명이 한 건을 함께 진행합니다. 평가 전체에 한 번만 하는 일(만들기·양식·보고서·전달·공문)은 진행자(이혜린)가 하고, 나머지는 각자 내 부서(물순환사업소) 일을 합니다.
A24: • 대상 부서: 물순환사업소 · 건설과 · 공공시설사업소 · 담양읍 · 보건소 · 문화체육과 · 환경과 (7개). 마지막 부서(환경과)에는 담당 공무원 계정이 없어서 진행자가 대신 처리합니다.
A25: • 아래 신호가 단체방에 올라오면 다음으로 넘어갑니다. 신호를 기다리지 않는 줄은 먼저 해도 됩니다.
A26: 순서 | B26: 누가 | D26: 할 일 | F26: 끝나면 단체방에
A27: 1 | B27: 모두 | D27: 1번 시트 1~6번 (만들기 창은 [취소]로 닫기) | F27: «만들기 전 확인 끝»
A28: 2 | B28: 진행자 | D28: 평가 만들기 | F28: «평가 만듦»
A29: 3 | B29: 진행자 | D29: 설문조사표 양식 올리기 | F29: «양식 올림»
A30: 4 | B30: 모두 | D30: 내 부서 작성본 제출 | F30: «제출 끝»
A31: 5 | B31: 진행자 | D31: 보고서 올리기 | F31: «보고서 올림»
A32: 6 | B32: 모두 | D32: 내 부서 개선조치 적기 | F32: «개선조치 적음»
A33: 7 | B33: 진행자 | D33: 부서로 전달 | F33: «전달함»
A34: 8 | B34: 모두 | D34: 조치 완료 · 확인 · 반려 · 재제출 | F34: «확인 끝»
A35: 9 | B35: 모두 | D35: 결재선 확인 (상신하지 않기) | F35: «결재선 확인 끝»
A36: 10 | B36: 진행자 | D36: 공문 상신 | F36: «상신함»
A37: 11 | B37: 모두 | D37: 상신 뒤 잠김 확인 | F37: «잠김 확인 끝»
A38: 12 | B38: 진행자 | D38: 결재 상태 확인 | F38: «결재 완료 확인»
A39: • 수시평가(5번 시트)는 순서와 상관없이 아무 때나 해도 됩니다.
A41: 결과 고르는 법
A42: 결과 | B42: 이럴 때 고르세요
A43: 성공 | B43: «이러면 성공»대로 된다
A44: 실패 | B44: 되긴 하는데 설명과 다르다 — 막혀야 하는데 저장된다, 문구·숫자가 틀리다
...

Sheet 요약
A1: 진행 상황 — 위험성평가 · 윤성현
A2: 결과를 고르면 저절로 채워집니다. 남은 것 = 아직 결과를 고르지 않은 줄입니다.
A4: 시트 | B4: 전체 | C4: 성공 | D4: 실패 | E4: 오류 | F4: 보류 | G4: 확인 불가 | H4: 문의 | I4: 남은 것 | J4: 진행률
A5: 1 정기평가 만들기 | B5: =COUNTA('1 정기평가 만들기'!$A$4:$A$11) -> 8 | C5: =COUNTIF('1 정기평가 만들기'!$G$4:$G$11,"성공") -> 0 | D5: =COUNTIF('1 정기평가 만들기'!$G$4:$G$11,"실패") -> 0 | E5: =COUNTIF('1 정기평가 만들기'!$G$4:$G$11,"오류") -> 0 | F5: =COUNTIF('1 정기평가 만들기'!$G$4:$G$11,"보류") -> 0 | G5: =COUNTIF('1 정기평가 만들기'!$G$4:$G$11,"확인 불가") -> 0 | H5: =COUNTIF('1 정기평가 만들기'!$G$4:$G$11,"문의") -> 0 | I5: =COUNTBLANK('1 정기평가 만들기'!$G$4:$G$11) -> 8 | J5: =IF(B5=0,0,(B5-I5)/B5) -> 0
A6: 2 설문조사표·보고서 | B6: =COUNTA('2 설문조사표·보고서'!$A$4:$A$9) -> 6 | C6: =COUNTIF('2 설문조사표·보고서'!$G$4:$G$9,"성공") -> 0 | D6: =COUNTIF('2 설문조사표·보고서'!$G$4:$G$9,"실패") -> 0 | E6: =COUNTIF('2 설문조사표·보고서'!$G$4:$G$9,"오류") -> 0 | F6: =COUNTIF('2 설문조사표·보고서'!$G$4:$G$9,"보류") -> 0 | G6: =COUNTIF('2 설문조사표·보고서'!$G$4:$G$9,"확인 불가") -> 0 | H6: =COUNTIF('2 설문조사표·보고서'!$G$4:$G$9,"문의") -> 0 | I6: =COUNTBLANK('2 설문조사표·보고서'!$G$4:$G$9) -> 6 | J6: =IF(B6=0,0,(B6-I6)/B6) -> 0
A7: 3 전달·조치·확인 | B7: =COUNTA('3 전달·조치·확인'!$A$4:$A$16) -> 13 | C7: =COUNTIF('3 전달·조치·확인'!$G$4:$G$16,"성공") -> 0 | D7: =COUNTIF('3 전달·조치·확인'!$G$4:$G$16,"실패") -> 0 | E7: =COUNTIF('3 전달·조치·확인'!$G$4:$G$16,"오류") -> 0 | F7: =COUNTIF('3 전달·조치·확인'!$G$4:$G$16,"보류") -> 0 | G7: =COUNTIF('3 전달·조치·확인'!$G$4:$G$16,"확인 불가") -> 0 | H7: =COUNTIF('3 전달·조치·확인'!$G$4:$G$16,"문의") -> 0 | I7: =COUNTBLANK('3 전달·조치·확인'!$G$4:$G$16) -> 13 | J7: =IF(B7=0,0,(B7-I7)/B7) -> 0
A8: 4 공문·결재 | B8: =COUNTA('4 공문·결재'!$A$4:$A$8) -> 5 | C8: =COUNTIF('4 공문·결재'!$G$4:$G$8,"성공") -> 0 | D8: =COUNTIF('4 공문·결재'!$G$4:$G$8,"실패") -> 0 | E8: =COUNTIF('4 공문·결재'!$G$4:$G$8,"오류") -> 0 | F8: =COUNTIF('4 공문·결재'!$G$4:$G$8,"보류") -> 0 | G8: =COUNTIF('4 공문·결재'!$G$4:$G$8,"확인 불가") -> 0 | H8: =COUNTIF('4 공문·결재'!$G$4:$G$8,"문의") -> 0 | I8: =COUNTBLANK('4 공문·결재'!$G$4:$G$8) -> 5 | J8: =IF(B8=0,0,(B8-I8)/B8) -> 0
A9: 5 수시평가 | B9: =COUNTA('5 수시평가'!$A$4:$A$15) -> 12 | C9: =COUNTIF('5 수시평가'!$G$4:$G$15,"성공") -> 0 | D9: =COUNTIF('5 수시평가'!$G$4:$G$15,"실패") -> 0 | E9: =COUNTIF('5 수시평가'!$G$4:$G$15,"오류") -> 0 | F9: =COUNTIF('5 수시평가'!$G$4:$G$15,"보류") -> 0 | G9: =COUNTIF('5 수시평가'!$G$4:$G$15,"확인 불가") -> 0 | H9: =COUNTIF('5 수시평가'!$G$4:$G$15,"문의") -> 0 | I9: =COUNTBLANK('5 수시평가'!$G$4:$G$15) -> 12 | J9: =IF(B9=0,0,(B9-I9)/B9) -> 0
A10: 합계 | B10: =SUM(B5:B9) -> 44 | C10: =SUM(C5:C9) -> 0 | D10: =SUM(D5:D9) -> 0 | E10: =SUM(E5:E9) -> 0 | F10: =SUM(F5:F9) -> 0 | G10: =SUM(G5:G9) -> 0 | H10: =SUM(H5:H9) -> 0 | I10: =SUM(I5:I9) -> 44 | J10: =IF(B10=0,0,(B10-I10)/B10) -> 0

Sheet 1 정기평가 만들기
A1: 위험성평가 — 1 정기평가 만들기
A2: 🗂 1~6번은 모두 각자 하고, 만들기 창은 [취소]로 닫습니다 — [생성]은 진행자만 누릅니다. 6번까지 끝나면 단체방에 «만들기 전 확인 끝».
A3: 번호 | B3: 누구로 | C3: 어디서 | D3: 확인할 것 | E3: 해 볼 것 | F3: 이러면 성공 | G3: 결과 ▼ | H3: 메모 (실패·오류·문의일 때) | I3: 사진 (필요할 때 붙여넣기)
A4: 1 | B4: QA박안전1(재난안전과) | C4: 위험성평가 > 정기 위험성평가 | D4: 올해 평가가 없을 때 첫 화면 | E4: ① 메뉴로 들어간다 ② 연도가 2026인지 본다 | F4: «2026년 정기 위험성평가가 등록되지 않았습니다»와 [＋ 정기평가 생성] 버튼이 보인다
A5: 2 | B5: QA박안전1(재난안전과) | C5: 위험성평가 > 정기 위험성평가 | D5: 지난해 평가 보기 | E5: ① 연도를 2025로 바꾼다 ② 위 요약 숫자와 아래 표를 비교한다 ③ 다시 2026으로 바꾼다 | F5: 2025년 평가가 보이고 요약 숫자가 표 내용과 맞다. 2025년 자료가 없으면 «확인 불가»
A6: 3 | B6: QA하정수1(담당 공무원) | C6: 위험성평가 > 정기 위험성평가 | D6: 담당 공무원은 만들 수 없다 | E6: QA하정수1 창에서 같은 화면을 본다 | F6: [＋ 정기평가 생성]이 없고, 재난안전과 담당자가 만든다는 안내가 보인다
A7: 4 | B7: QA박안전1(재난안전과) | C7: 위험성평가 > 정기 위험성평가 | D7: 만들기 창 — 대상 부서 고르기 | E7: ① [＋ 정기평가 생성] ② 부서 몇 개를 체크 해제했다가 다시 체크한다 ③ 검색창에 내 부서 이름 일부를 친다 ④ [취소] | F7: 처음엔 모두 체크돼 있고 고른 개수가 바로 바뀐다. 검색해도 체크가 그대로다
A8: 5 | B8: QA박안전1(재난안전과) | C8: 위험성평가 > 정기 위험성평가 | D8: 부서를 하나도 안 고르면 막힌다 | E8: ① [＋ 정기평가 생성] ② 전체 선택을 해제한다 ③ [다음] ④ [취소] | F8: «1개 이상 부서를 선택하세요.»가 뜨고 넘어가지 않는다
A9: 6 | B9: QA박안전1(재난안전과) | C9: 위험성평가 > 정기 위험성평가 | D9: 점검일자가 없으면 막힌다 | E9: ① [＋ 정기평가 생성] ② 내 부서(물순환사업소)가 체크된 채 [다음] ③ 점검일자를 비운 채 [생성] ④ [취소] | F9: «점검일자가 비어있는 부서가 있습니다 (N개)»가 뜨고 만들어지지 않는다
A10: 8 | B10: QA박안전1(재난안전과) | C10: 위험성평가 > 정기 위험성평가 | D10: 새로고침해도 그대로 | E10: «평가 만듦»이 오면 브라우저 새로고침(F5) | F10: «2026년 정기 위험성평가» 제목과 7개 부서·점검일이 보인다. 오른쪽 위에 «정기평가는 연 1회 등록 원칙»이 보인다
A11: 9 | B11: QA박안전1(재난안전과) | C11: 위험성평가 > 정기 위험성평가 | D11: 로그인 남은 시간 | E11: 화면 맨 위에 로그인 남은 시간이 보이는지 본다. 30분이 지나 끊기면 다시 로그인한다 | F11: 남은 시간이 보이고, 30분이 지나면 로그인 화면으로 간다. 다시 로그인하면 이어서 할 수 있다

Sheet 2 설문조사표·보고서
A1: 위험성평가 — 2 설문조사표·보고서
A2: 🗂 진행자가 «양식 올림»을 알리면 시작합니다. 내 부서 제출은 각자 하고, 보고서는 진행자가 올립니다.
A3: 번호 | B3: 누구로 | C3: 어디서 | D3: 확인할 것 | E3: 해 볼 것 | F3: 이러면 성공 | G3: 결과 ▼ | H3: 메모 (실패·오류·문의일 때) | I3: 사진 (필요할 때 붙여넣기)
A4: 11 | B4: QA하정수1(담당 공무원) | C4: 위험성평가 > 정기 위험성평가 | D4: 내 부서가 작성본을 낸다 | E4: «양식 올림»이 오면 ① 내 부서 진행 카드에 공통 양식이 있는지 본다 ② 작성본을 제출한다 ③ 단체방에 «제출 끝» | F4: 제출자(QA하정수1)·제출일이 남고 표의 «제출본» 칸에 바로 보인다. 다른 부서 줄에는 제출 버튼이 없다
A5: 15 | B5: QA하정수1(담당 공무원) → QA박안전1(재난안전과) | C5: 위험성평가 > 정기 위험성평가 | D5: 보고서를 올린 뒤에는 설문조사표를 못 바꾼다 | E5: «보고서 올림»이 오면 ① QA하정수1 창에서 내 부서 제출본 바꾸기를 시도한다 ② QA박안전1 창에서 내 부서 양식 바꾸기를 시도한다 | F5: «보고서가 등록되어 … 더 이상 바꿀 수 없습니다»가 뜨고 파일은 «🔒 열람»으로만 남는다
A6: 16 | B6: QA박안전1(재난안전과) | C6: 위험성평가 > 정기 위험성평가 | D6: 내 부서 개선조치 적기 | E6: 내 부서(물순환사업소) 줄에 유해위험요인·원인·개선조치·담당자(QA하정수1)를 채운 행 3개를 만든다 | F6: 적은 행 3개가 저장된다
A7: 17 | B7: QA박안전1(재난안전과) | C7: 위험성평가 > 정기 위험성평가 | D7: 시설물 칸 3가지 상태 | E7: 16번의 행 3개 중 ① 하나는 시설물을 지정 ② 하나는 [해당 없음] ③ 하나는 그대로 둔다 | F7: «지정 / 해당 없음 / 미지정»이 서로 다르게 보이고 어느 것도 다음 단계를 막지 않는다
A8: 18 | B8: QA박안전1(재난안전과) | C8: 관리대상 > 시설물 위험도 | D8: 시설물에서 넘어와 행 추가 | E8: ① 점수가 있는 시설물의 [근로자 위험성평가 연계] ② 넘어간 화면에서 내 부서의 [＋ 행 추가] ③ 개선조치는 비워 둔다(이 행은 전달되지 않는다) ④ 단체방에 «개선조치 적음» | F8: 위에 «시설물 ○○ 에서 넘어왔습니다» 안내가 있고 새 행에 그 시설물이 채워져 있다
A9: 19 | B9: QA박안전1(재난안전과) | C9: 위험성평가 > 정기 위험성평가 | D9: 여럿이 적어도 내 행이 남는다 | E9: 모두 «개선조치 적음»을 알리면 새로고침 → 내 부서 줄과 다른 부서 줄을 본다 | F9: 16번에 적은 3행이 그대로이고 다른 사람이 적은 부서의 행도 보인다. 내 행이 사라졌거나 다른 값으로 바뀌었으면 «실패»

Sheet 3 전달·조치·확인
A1: 위험성평가 — 3 전달·조치·확인
A2: 🗂 진행자가 «전달함»을 알리면 시작합니다. 내 부서 일은 QA박안전1 창과 QA하정수1 창을 번갈아 씁니다.
A3: 번호 | B3: 누구로 | C3: 어디서 | D3: 확인할 것 | E3: 해 볼 것 | F3: 이러면 성공 | G3: 결과 ▼ | H3: 메모 (실패·오류·문의일 때) | I3: 사진 (필요할 때 붙여넣기)
A4: 23 | B4: QA하정수1(담당 공무원) → QA박안전1(재난안전과) | C4: 위험성평가 > 정기 위험성평가 | D4: 누가 어느 부서를 보나 | E4: «전달함»이 오면 ① QA하정수1 창에서 부서별 조치 표를 본다 ② QA박안전1 창에서 같은 표를 본다 | F4: QA하정수1 계정에는 내 부서 줄만 보이고 다른 부서를 열 수단이 없다. QA박안전1 계정에는 대상 부서가 다 보인다
A5: 24 | B5: QA하정수1(담당 공무원) | C5: 대시보드 > 내 할일 | D5: 조치 완료는 사진·내용·서명이 있어야 | E5: ① 개선조치 하나의 완료 처리를 연다 ② 사진 없이 저장 → 사진만 넣고 저장 → 내용까지 넣고 서명 없이 저장 | F5: 차례로 «개선 후 사진을…» «조치 내용을 입력하세요.» «완료 확인 서명(이름)을…»으로 막힌다. 적은 값은 남아 있다
A6: 25 | B6: QA하정수1(담당 공무원) | C6: 대시보드 > 내 할일 | D6: 조치 완료하기 | E6: 사진·내용·서명을 모두 채워 완료 → 하나 더 완료(3건 중 2건) | F6: 완료되고 «확인 대기»가 붙는다. 내 할일에는 내 부서 건만 있다
A7: 26 | B7: QA박안전1(재난안전과) | C7: 위험성평가 > 정기 위험성평가 | D7: 담당자·기한을 바꿀 땐 사유가 필요 | E7: 내 부서 상세에서 아직 완료하지 않은 1건의 기한을 어제로 바꾼다 ① 사유 없이 저장 ② 사유를 넣고 저장 | F7: 사유 없이는 «변경 사유를 입력하세요.» 저장하면 이력에 «기한 A → B — 사유»가 남고 그 건이 기한 초과로 보인다
A8: 27 | B8: QA박안전1(재난안전과) | C8: 위험성평가 > 정기 위험성평가 | D8: 기한 지난 건 재촉 | E8: 26번 건의 [재촉] | F8: «재촉 알림을 발송했습니다», 이력에 보낸 사람이 QA박안전1 계정으로 남는다. 완료한 건에는 재촉 버튼이 없다
A9: 28 | B9: QA하정수1(담당 공무원) | C9: 위험성평가 > 정기 위험성평가 | D9: 담당 공무원에게는 확인·재촉 버튼이 없다 | E9: QA하정수1 창에서 내 부서 상세를 연다 | F9: 볼 수는 있지만 [재촉]·[확인]·[반려]가 없다
A10: 29 | B10: QA박안전1(재난안전과) | C10: 위험성평가 > 정기 위험성평가 | D10: 완료 확인 — 열람 체크를 해야 확인된다 | E10: ① 내 부서 상세의 확인 대기 카드 하나 ② 체크 없이 [확인] ③ «…열람했습니다»를 체크하고 [확인] | F10: 체크 전에는 [확인]이 눌리지 않는다. 확인하면 «확인 완료»가 된다
A11: 30 | B11: QA박안전1(재난안전과) | C11: 위험성평가 > 정기 위험성평가 | D11: 반려는 사유가 있어야 | E11: 내 부서의 다른 확인 대기 건을 ① 사유 없이 반려 ② 사유를 넣고 반려 | F11: 사유 없이는 «반려 사유를 입력하세요 — …»로 막히고, 반려하면 카드에 사유와 회차가 보인다
A12: 31 | B12: QA하정수1(담당 공무원) | C12: 대시보드 > 내 할일 | D12: 반려된 건을 다시 낸다 | E12: ① 내 할일에 반려 건이 다시 떠 있는지 본다 ② [재제출]로 다시 완료 ③ 26번에서 기한을 바꾼 건도 완료한다 | F12: 반려 건이 할 일에 다시 있고 사유가 보인다. 재제출하면 «확인 대기»로 돌아간다
A13: 32 | B13: QA박안전1(재난안전과) | C13: 위험성평가 > 정기 위험성평가 | D13: 확인이 덜 끝나면 공문을 못 쓴다 | E13: 공문(온나라 이관) 영역을 본다 | F13: «전 건 확인 완료 후 기안할 수 있습니다 (확인 대기 N건 · 반려 M건)»처럼 남은 건수를 알려 준다. 다른 사람 부서의 건도 함께 센다
A14: 33 | B14: QA박안전1(재난안전과) | C14: 위험성평가 > 정기 위험성평가 | D14: 내 부서 확인 마치기 | E14: 내 부서의 확인 대기 건을 모두 확인한다 → 단체방에 «확인 끝» | F14: 내 부서가 완료 부서로 세어진다
A15: 34 | B15: QA박안전1(재난안전과) | C15: 위험성평가 > 정기 위험성평가 | D15: 전 부서 확인이 끝나면 공문을 쓸 수 있다 | E15: 모두 «확인 끝»을 알리면 새로고침 | F15: 모든 부서가 완료(또는 지적사항 없음)이고 공문 영역이 «전 부서 확인 완료 — 공문을 작성해…»로 바뀐다
A16: 35 | B16: QA박안전1(재난안전과) | C16: 위험성평가 > 정기 위험성평가 | D16: 이력 탭 | E16: [이력] 탭을 연다 | F16: 만들기·첨부·전달·재촉·변경·확인·반려가 시간순으로 있고, 누가 했는지 사람마다 다른 계정 이름으로 남아 있다

Sheet 4 공문·결재
A1: 위험성평가 — 4 공문·결재
A2: 🗂 공문은 평가 1건에 하나라 진행자가 올립니다. 36번을 먼저 하고, «상신함»이 오면 38번부터 합니다. 상신하면 바로 «결재완료»(내부 처리)로 끝납니다 — 온나라로 가지 않습니다.
A3: 번호 | B3: 누구로 | C3: 어디서 | D3: 확인할 것 | E3: 해 볼 것 | F3: 이러면 성공 | G3: 결과 ▼ | H3: 메모 (실패·오류·문의일 때) | I3: 사진 (필요할 때 붙여넣기)
A4: 36 | B4: QA박안전1(재난안전과) | C4: 위험성평가 > 정기 위험성평가 | D4: 결재선 — 같은 사람을 두 번 못 넣는다 | E4: ① [공문 기안] ② 결재선의 검토·결재 [조직도]에서 같은 사람을 두 번 고른다 ③ 한 칸을 비운 채 [문서 미리보기 →]로 가서 [온나라로 결재 상신]을 눌러 본다 ④ 상신하지 않고 창을 닫는다 ⑤ 단체방에 «결재선 확인 끝» | F4: 이미 고른 사람과 기안자(QA박안전1)는 흐리게 보이고 고를 수 없다. 칸이 비면 상신이 막히고 이유가 나온다
A5: 38 | B5: QA박안전1(재난안전과) | C5: 위험성평가 > 정기 위험성평가 | D5: 상신 뒤에는 잠긴다 | E5: «상신함»이 오면 ① 내 부서 상세에서 확인한 건을 확인 취소·반려해 본다 ② 단체방에 «잠김 확인 끝» | F5: 할 수 없고 잠긴 이유가 나온다
A6: 39 | B6: QA하정수1(담당 공무원) | C6: 위험성평가 > 정기 위험성평가 | D6: 담당 공무원에게는 공문 버튼이 없다 | E6: QA하정수1 창에서 같은 화면을 본다 | F6: [공문 기안]·[온나라로 결재 상신]이 없다
A7: 41 | B7: QA박안전1(재난안전과) | C7: 위험성평가 > 정기 위험성평가 | D7: 끝난 평가 | E7: «결재 완료 확인»이 오면 새로고침 → [결재 상태]를 연다 | F7: 평가가 끝난 상태로 보이고 결재 상태가 결재완료 · «내부 처리»다
A8: 42 | B8: QA박안전1(재난안전과) | C8: 위험성평가 > 정기 위험성평가 | D8: 지난 평가 둘러보기 | E8: ① 연도를 2025로 바꾼다 ② [문서 보기]·[결재 상태]·부서 상세를 연다 ③ 설문조사표 파일 이름을 누른다 | F8: 창이 잘 열린다. 파일은 열리거나 «…연계 후 제공됩니다» 안내가 뜬다. 2025년 자료가 없으면 «확인 불가»

Sheet 5 수시평가
A1: 위험성평가 — 5 수시평가
A2: 🗂 각자 따로, 순서와 상관없이 해도 됩니다. 수시 위험성평가는 부서가 사유가 생겨 올리고 재난안전과 확인 단계가 없습니다. 다른 사람 것과 구분하려고 내용 앞에 내 이름을 붙입니다.
A3: 번호 | B3: 누구로 | C3: 어디서 | D3: 확인할 것 | E3: 해 볼 것 | F3: 이러면 성공 | G3: 결과 ▼ | H3: 메모 (실패·오류·문의일 때) | I3: 사진 (필요할 때 붙여넣기)
A4: 43 | B4: QA하정수1(담당 공무원) | C4: 위험성평가 > 수시 위험성평가 | D4: 등록은 실시 사유부터 | E4: [＋ 수시평가 등록] | F4: 실시 사유를 먼저 고르게 하고, 부서는 내 부서(물순환사업소)로 고정돼 있다
A5: 44 | B5: QA박안전1(재난안전과) | C5: 위험성평가 > 수시 위험성평가 | D5: 재난안전과 담당자는 부서를 고를 수 있다 | E5: 같은 등록 창을 연다 → [취소] | F5: 조직도로 부서를 고를 수 있다
A6: 45 | B6: QA하정수1(담당 공무원) | C6: 위험성평가 > 수시 위험성평가 | D6: 빈 칸이 있으면 등록되지 않는다 | E6: ① 발생일·내용을 비우고 [등록] ② 채우고 유해위험요인·감소대책을 비우고 [등록] | F6: «부서·사유·발생일·내용을 모두 입력하세요.» / «유해위험요인과 위험성 감소대책을 최소 1건 입력하세요.»로 막힌다
A7: 46 | B7: QA하정수1(담당 공무원) | C7: 위험성평가 > 수시 위험성평가 | D7: 재해 사유면 칸이 더 생긴다 | E7: ① 사유를 «중대산업사고 또는 산업재해 발생»으로 ② 재해 개요·작업 재개 예정일을 비우고 [등록] ③ 사유를 바꿨다가 되돌린다 | F7: 두 칸이 생기고 비우면 막힌다. 사유를 바꿔도 적은 값이 남아 있다
A8: 47 | B8: QA하정수1(담당 공무원) | C8: 위험성평가 > 수시 위험성평가 | D8: 요인 행 추가·삭제 | E8: ① 행을 10개까지 추가하고 한 번 더 ② 1개만 남기고 삭제해 본다 ③ 개선 전 사진을 첨부한다 | F8: «한 번에 최대 10건까지…» «최소 1건은 있어야 합니다…»가 뜬다. 사진은 «개선 전 사진 N건 첨부»
A9: 48 | B9: QA하정수1(담당 공무원) | C9: 위험성평가 > 수시 위험성평가 | D9: 등록하면 개선조치가 생긴다 | E9: 내용 «윤성현_설비변경작업», 요인 2건으로 [등록] → 내 할일 확인 | F9: «수시평가 등록 · 개선조치 2건 생성…»이 뜨고 내 할일에 개선조치 2건이 생긴다
A10: 49 | B10: QA박안전1(재난안전과) | C10: 위험성평가 > 수시 위험성평가 | D10: 안전관리자 검토파일 | E10: 48번의 «윤성현_설비변경작업» 건에서 ① [＋ 검토파일 등록] ② 파일명 비우고 → 검토자 이름 비우고 → 다 채워서 등록 | F10: 빈 칸이면 막히고, 다 채우면 «… 검토완료 처리»와 함께 상태가 «검토 완료»
A11: 50 | B11: QA하정수1(담당 공무원) | C11: 위험성평가 > 수시 위험성평가 | D11: 검토파일은 재난안전과만 | E11: 같은 건을 본다 | F11: [＋ 검토파일 등록]이 없거나, 누르면 «… 재난안전과 담당자가 첨부합니다»로 막힌다
A12: 51 | B12: QA박안전1(재난안전과) | C12: 위험성평가 > 수시 위험성평가 | D12: 검토파일 해제는 한 번 더 묻는다 | E12: [해제] → [취소] → 다시 [해제] → 확인 | F12: 바로 지우지 않고 확인 창이 뜬다. 확인하면 «검토파일 삭제 · 검토완료 해제»
A13: 52 | B13: QA하정수1(담당 공무원) | C13: 위험성평가 > 수시 위험성평가 | D13: 수시평가 개선조치 완료 | E13: [조치 상세]에서 사진·내용·서명을 넣고 완료 | F13: 완료된다(수시평가는 재난안전과 확인 단계가 없다 — 정상)
A14: 53 | B14: QA박안전1(재난안전과) | C14: 위험성평가 > 수시 위험성평가 | D14: 목록 조건 | E14: 연도·실시 사유 조건을 건다 → 목록과 [조치 상세]를 비교 | F14: 조건대로 걸러지고 목록과 상세 내용이 같다. 다른 사람이 올린 건도 보인다(정상)
A15: 54 | B15: QA하정수1(담당 공무원) → QA박안전1(재난안전과) | C15: 위험성평가 > 수시 위험성평가 | D15: 누가 무엇을 보나 | E15: 두 창에서 목록을 본다 | F15: QA하정수1 계정에는 내 부서 건만 보이고 다른 사람이 올린 건은 없다. QA박안전1 계정에는 전부 보인다

Sheet _정보
A1: 형식 | B1: QA엑셀 v1.1
A2: 메뉴 | B2: 위험성평가
A3: 담당자 | B3: 윤성현
A4: 파일 코드 | B4: RA
A5: 종류 | B5: 상세
A6: 생성일 | B6: 2026-09-30
A7: 결과 값 | B7: 성공,실패,오류,보류,확인 불가,문의
A8: 머리 행 | B8: 3
A9: 열 | B9: 번호,누구로,어디서,확인할,해,이러면,결과,메모,사진
