Workbook

Sheet 안내
A1: QA 담양 중대재해 — 대시보드 · 윤성현
A3: 메뉴 | B3: 대시보드 (훑어보는 파일)
A4: 담당자 | B4: 윤성현
A5: 내 계정 | B5: QA박안전1 (재난안전과 담당자) · QA하정수1 (내 부서 물순환사업소 담당 공무원)
A6: 이 파일 | B6: 대시보드의 통합 현황과 내 할일을 봅니다. QA박안전1 · QA하정수1 두 계정 모두 담당자용 첫 화면이라 구성은 같고, 숫자는 각 계정 부서의 것입니다.
A7: 줄 수 | B7: 11줄
A8: 시트 | B8: 통합 현황 → 내 할일
A9: 테스트 주소 | B9: https://safety.damyang.go.kr/login
A10: 브라우저
A11: 기기
A12: 시작한 날
A14: 이렇게 하면 됩니다
A15: ① 위 «테스트 주소»에서 받은 아이디·비밀번호로 로그인합니다. 로그인하면 통합 현황 화면으로 갑니다. 5번 틀리면 계정이 잠깁니다 — 담당 개발자에게 풀어 달라고 합니다.
A16: ② 내 계정 두 개를 창 두 개에 따로 로그인해 둡니다 — 일반 창에는 QA박안전1(재난안전과), 시크릿 창(Ctrl + Shift + N · 맥 Cmd + Shift + N)에는 QA하정수1(담당 공무원). 두 창을 나란히 두면 계정을 바꿀 필요가 없습니다.
A17: ③ «누구로» 칸에 적힌 계정의 창에서 «어디서» 메뉴로 가서 «해 볼 것»대로 눌러 봅니다.
A18: ④ «이러면 성공»과 같으면 «결과» 칸에서 성공을, 다르면 실패·오류 등을 고릅니다.
A19: ⑤ 실패·오류·문의면 «메모»에 한 줄 적고, 필요하면 «사진» 칸에 화면 캡처를 붙여넣습니다.
A21: 결과 고르는 법
A22: 결과 | B22: 이럴 때 고르세요
A23: 성공 | B23: «이러면 성공»대로 된다
A24: 실패 | B24: 되긴 하는데 설명과 다르다 — 막혀야 하는데 저장된다, 문구·숫자가 틀리다
A25: 오류 | B25: 화면이 멈추거나 깨진다, 눌러도 아무 일이 없다, 오류 창이 뜬다
A26: 보류 | B26: 앞 단계가 안 돼서 지금은 못 한다 — 메모에 이유
A27: 확인 불가 | B27: 이 환경에서는 볼 수 없다 — 예: 확인할 데이터가 없다
A28: 문의 | B28: 맞는지 헷갈린다 — 메모에 궁금한 점
A30: 사진 붙이는 법
A31: • 윈도우: Win + Shift + S → 영역 선택 → 엑셀에서 그 줄의 «사진» 칸을 누르고 Ctrl + V
A32: • 맥: Cmd + Ctrl + Shift + 4 → 영역 선택 → 엑셀에서 그 줄의 «사진» 칸을 누르고 Cmd + V
A33: • 사진이 크면 모서리를 끌어 줄이세요. 사진은 그 줄 «사진» 칸 위에 두면 됩니다 — 취합할 때 줄 번호로 찾습니다.
A34: • 사진은 떠 있는 그대로 두세요(«셀에 배치»로 넣으면 취합할 때 꺼내지 못합니다).
A36: 누구로 — 내 계정 두 개
A37: • 계정은 두 개뿐입니다. «누구로» 칸에 계정 이름과 권한이 함께 적혀 있습니다. 비밀번호는 따로 받습니다.
A38: 이름 | B38: 권한 | D38: 볼 수 있는 것 | F38: 주로 하는 것
A39: QA박안전1 | B39: 재난안전과 담당자 | D39: 모든 부서 · «내 할일»은 전체 | F39: 전 부서 등록·수정 · 확인 · 상신 · 독촉 — 대부분 이 계정
A40: QA하정수1 | B40: 담당 공무원 (내 부서: 물순환사업소) | D40: 업무 화면은 전 부서, «내 할일»은 나에게 지정된 것만, 위험성평가 부서별 조치표·교육 이수현황은 내 부서만 | F40: 내 부서 일 · 남의 부서 것을 못 건드리는지 확인
A41: QA시스템관리 | B41: 시스템 관리자 (김유석만) | D41: 시스템 관리 메뉴 | F41: 시스템 관리 파일 · 공문 반려(결재 대행)
A43: 같은 서버를 6명이 함께 씁니다
A44: • 내가 만드는 것(교육 · 근로자 · 문서 · 위원 등)은 이름 앞에 내 이름을 붙입니다 — 예: «윤성현_집합교육». 그래야 내 것을 찾기 쉽습니다.
A45: • 다른 사람이 만든 것은 고치거나 지우지 않습니다. QA박안전1 계정에는 남의 것도 보이는데, 정상입니다.
A46: • 건수·이수율 같은 숫자는 다른 사람이 작업하는 동안 바뀔 수 있습니다. 숫자가 안 맞으면 새로고침해서 한 번 더 보고, 그래도 다르면 «실패».
...

Sheet 요약
A1: 진행 상황 — 대시보드 · 윤성현
A2: 결과를 고르면 저절로 채워집니다. 남은 것 = 아직 결과를 고르지 않은 줄입니다.
A4: 시트 | B4: 전체 | C4: 성공 | D4: 실패 | E4: 오류 | F4: 보류 | G4: 확인 불가 | H4: 문의 | I4: 남은 것 | J4: 진행률
A5: 통합 현황 | B5: =COUNTA('통합 현황'!$A$4:$A$7) -> 4 | C5: =COUNTIF('통합 현황'!$G$4:$G$7,"성공") -> 0 | D5: =COUNTIF('통합 현황'!$G$4:$G$7,"실패") -> 0 | E5: =COUNTIF('통합 현황'!$G$4:$G$7,"오류") -> 0 | F5: =COUNTIF('통합 현황'!$G$4:$G$7,"보류") -> 0 | G5: =COUNTIF('통합 현황'!$G$4:$G$7,"확인 불가") -> 0 | H5: =COUNTIF('통합 현황'!$G$4:$G$7,"문의") -> 0 | I5: =COUNTBLANK('통합 현황'!$G$4:$G$7) -> 4 | J5: =IF(B5=0,0,(B5-I5)/B5) -> 0
A6: 내 할일 | B6: =COUNTA('내 할일'!$A$4:$A$10) -> 7 | C6: =COUNTIF('내 할일'!$G$4:$G$10,"성공") -> 0 | D6: =COUNTIF('내 할일'!$G$4:$G$10,"실패") -> 0 | E6: =COUNTIF('내 할일'!$G$4:$G$10,"오류") -> 0 | F6: =COUNTIF('내 할일'!$G$4:$G$10,"보류") -> 0 | G6: =COUNTIF('내 할일'!$G$4:$G$10,"확인 불가") -> 0 | H6: =COUNTIF('내 할일'!$G$4:$G$10,"문의") -> 0 | I6: =COUNTBLANK('내 할일'!$G$4:$G$10) -> 7 | J6: =IF(B6=0,0,(B6-I6)/B6) -> 0
A7: 합계 | B7: =SUM(B5:B6) -> 11 | C7: =SUM(C5:C6) -> 0 | D7: =SUM(D5:D6) -> 0 | E7: =SUM(E5:E6) -> 0 | F7: =SUM(F5:F6) -> 0 | G7: =SUM(G5:G6) -> 0 | H7: =SUM(H5:H6) -> 0 | I7: =SUM(I5:I6) -> 11 | J7: =IF(B7=0,0,(B7-I7)/B7) -> 0

Sheet 통합 현황
A1: 대시보드 — 통합 현황
A2: 🗂 QA박안전1 창과 QA하정수1 창을 나란히 두고 봅니다. 위 숫자 칸은 각 계정 부서의 개선조치만 셉니다.
A3: 번호 | B3: 누구로 | C3: 어디서 | D3: 확인할 것 | E3: 해 볼 것 | F3: 이러면 성공 | G3: 결과 ▼ | H3: 메모 (실패·오류·문의일 때) | I3: 사진 (필요할 때 붙여넣기)
A4: 1 | B4: QA박안전1(재난안전과) → QA하정수1(담당 공무원) | C4: 대시보드 > 통합 현황 | D4: 계정마다 내 부서 숫자가 보인다 | E4: 두 창에서 통합 현황을 연다 | F4: 두 창 모두 오류 없이 뜬다. 위 숫자 칸 제목이 QA박안전1 창은 «재난안전과 — 내 부서 개선조치», QA하정수1 창은 «물순환사업소 — 내 부서 개선조치»다
A5: 2 | B5: QA하정수1(담당 공무원) | C5: 대시보드 > 통합 현황 | D5: 숫자 칸을 누르면 그 조건의 내 할일로 간다 | E5: ① «기한 초과» 칸을 누른다 ② 뒤로 와서 «오늘 마감» 칸을 누른다 | F5: 내 할일이 그 조건(개선·기한 초과 또는 오늘 마감)으로 걸린 채 열리고, 칸 숫자만큼의 개선조치 카드가 목록에 있다. 목록 건수가 칸 숫자보다 많으면(반려된 개선조치나 발행 업무가 섞일 수 있다) 두 숫자와 더 많은 카드를 메모에 적는다
A6: 3 | B6: QA박안전1(재난안전과) | C6: 대시보드 > 통합 현황 | D6: 시기도래 알림 — 목록·달력 | E6: ① «시기도래 알림»의 [달력 보기] ② [목록]으로 돌아와 한 줄의 [이동] | F6: 달력에는 이번 달 마감일에 빨간 점이 찍힌다(이번 달 마감이 없으면 «이번 달 마감 없음 — 위 목록에서 확인하세요»). [이동]을 누르면 그 업무 화면으로 간다
A7: 4 | B7: QA박안전1(재난안전과) | C7: 대시보드 > 통합 현황 | D7: 눌러도 아무 일 없는 줄이 없다 | E7: «법정 의무 캘린더»의 줄과 «카테고리별 잔여 업무»의 막대를 2~3개씩 눌러 본다(하나 누르고 뒤로) | F7: 누를 때마다 그 업무 화면이나 그 분류로 걸린 내 할일로 간다

Sheet 내 할일
A1: 대시보드 — 내 할일
A2: 🗂 주로 QA박안전1 창에서 합니다. 8번은 QA하정수1 창에서 내 부서 할 일로 합니다 — 재난안전과 할 일은 6명이 함께 보므로 완료 처리하지 않습니다.
A3: 번호 | B3: 누구로 | C3: 어디서 | D3: 확인할 것 | E3: 해 볼 것 | F3: 이러면 성공 | G3: 결과 ▼ | H3: 메모 (실패·오류·문의일 때) | I3: 사진 (필요할 때 붙여넣기)
A4: 5 | B4: QA박안전1(재난안전과) | C4: 대시보드 > 내 할일 | D4: 탭 숫자와 목록 건수 | E4: [마감 할일] · [담당 문서] · [완료한 업무]를 차례로 누른다 | F4: 탭 숫자와 그 탭 목록의 건수(마감 할일 «N건», 담당 문서 «전체 N», 완료한 업무 «N건 완료»)가 같다. 완료한 업무가 0건이면 «아직 완료한 업무가 없습니다.»가 나온다
A5: 6 | B5: QA박안전1(재난안전과) | C5: 대시보드 > 내 할일 | D5: 위 칩으로 거르기 | E5: [마감 할일]에서 위 칩(배정 대기 · 지연 · 이번주 · 전체)을 하나씩 누른다 | F5: 칩을 누르면 그 조건으로 걸리고 [전체]를 누르면 풀린다(칩 [전체]의 숫자는 완료한 것까지 세므로 탭 숫자와 달라도 된다)
A6: 7 | B6: QA박안전1(재난안전과) → QA하정수1(담당 공무원) | C6: 대시보드 > 내 할일 | D6: 다른 부서 보기는 재난안전과만 | E6: ① QA박안전1 창 [마감 할일] 탭에서 제목 줄 오른쪽 부서 칸으로 내 부서(물순환사업소)를 고른다 ② QA하정수1 창에서 같은 화면을 본다 ③ QA박안전1 창의 부서 칸을 재난안전과로 되돌린다 | F6: QA박안전1 창은 제목이 «내 할일 — 물순환사업소»로 바뀌고 «조회 전용» 안내가 뜨며 [마감 할일] 카드에 완료 처리·파일 첨부 버튼이 없다(보기 버튼만). QA하정수1 창에는 부서 칸이 없고 제목이 «내 할일 — 물순환사업소»다. 되돌리면 제목이 «내 할일 — 재난안전과»로 돌아온다
A7: 8 | B7: QA하정수1(담당 공무원) | C7: 대시보드 > 내 할일 | D7: 파일을 올려 끝내는 할 일 | E7: ① [마감 할일]에서 [파일 첨부] 버튼이 있는 내 부서 할 일을 고른다 — 없으면 «우리 부서에 도착 · 담당자 미정» 묶음에서 설명에 «… 필요»가 붙은 할 일의 [내가 맡기]를 먼저 누른다 ② [파일 첨부]를 누르고 파일을 고르기 전에 [첨부 완료]를 본다 ③ 파일을 골라 [첨부 완료] | F7: 파일을 고르기 전에는 [첨부 완료]가 눌리지 않는다. 첨부하면 완료 안내가 뜨고 그 할 일이 [완료한 업무]로 옮겨 간다. [파일 첨부] 할 일이 없으면 «확인 불가»
A8: 9 | B8: QA박안전1(재난안전과) | C8: 대시보드 > 내 할일 | D8: 다른 화면으로 가는 할 일 | E8: ① «…에서 진행» 표시가 붙은 카드 2~3개의 버튼을 누른다(하나 누르고 뒤로) ② 분류가 «결재»인 카드의 버튼 이름을 본다 | F8: 카드에 적힌 화면으로 간다. 결재 카드의 버튼은 «결재하러 가기»가 아니다. 그런 카드가 없으면 «확인 불가»
A9: 10 | B9: QA박안전1(재난안전과) → QA하정수1(담당 공무원) | C9: 대시보드 > 내 할일 | D9: 미분류 문서 카드는 재난안전과에만 | E9: ① QA박안전1 창에서 «문서 원장 미분류 N건 분류 확인» 카드의 [분류하러 가기] ② QA하정수1 창의 내 할일에 같은 카드가 있는지 본다 | F9: 문서 목록이 미분류 조건으로 열리고 건수가 카드의 N과 같다(미분류가 0건이면 [완료한 업무]에 «문서 원장 미분류 없음 — 분류 완료»로 있다). QA하정수1 창에는 이 카드가 없다
A10: 11 | B10: QA박안전1(재난안전과) | C10: 대시보드 > 내 할일 | D10: 새로고침 버튼 | E10: 제목 줄의 [동기화] | F10: «내 할일 목록을 새로고침했습니다.»가 뜨고 «동기화» 옆 시각이 지금 시각으로 바뀐다

Sheet _정보
A1: 형식 | B1: QA엑셀 v1.1
A2: 메뉴 | B2: 대시보드
A3: 담당자 | B3: 윤성현
A4: 파일 코드 | B4: DB
A5: 종류 | B5: 스모크
A6: 생성일 | B6: 2026-09-30
A7: 결과 값 | B7: 성공,실패,오류,보류,확인 불가,문의
A8: 머리 행 | B8: 3
A9: 열 | B9: 번호,누구로,어디서,확인할,해,이러면,결과,메모,사진
