Workbook

Sheet 안내
A1: QA 담양 중대재해 — 안전보건교육 · 윤한빛
A3: 메뉴 | B3: 안전보건교육 (자세히 보는 파일)
A4: 담당자 | B4: 윤한빛
A5: 이 파일 | B5: 근로자 명단 → 교육 등록 → 참석자 등록부 → 교육 종료 → 이수현황 → 공문까지 봅니다. 이수 기록은 참석자를 등록할 때가 아니라 [교육 종료 처리]를 눌러야 생깁니다.
A6: 줄 수 | B6: 58줄
A7: 시트 | B7: 1 근로자 명단 → 2 정기교육(집합) → 3 자체·채용시·기타 → 4 이수현황 → 5 공문·결재 이력 → 6 계정별 차이
A8: 테스트 주소 | B8: (배포 주소를 받으면 채웁니다)
A9: 브라우저
A10: 기기
A11: 시작한 날
A13: 이렇게 하면 됩니다
A14: ① 브라우저로 위 «테스트 주소»를 엽니다. 시트마다 맨 위에 «새 탭에서 시작» 또는 «같은 탭에서 이어서»가 적혀 있습니다.
A15: ② 화면 오른쪽 위 이름을 눌러 «누구로» 칸의 사람으로 바꿉니다.
A16: ③ «어디서» 메뉴로 가서 «해 볼 것»대로 눌러 봅니다.
A17: ④ «이러면 성공»과 같으면 «결과» 칸에서 성공을, 다르면 실패·오류 등을 고릅니다.
A18: ⑤ 실패·오류·문의면 «메모»에 한 줄 적고, 필요하면 «사진» 칸에 화면 캡처를 붙여넣습니다.
A20: 결과 고르는 법
A21: 결과 | B21: 이럴 때 고르세요
A22: 성공 | B22: «이러면 성공»대로 된다
A23: 실패 | B23: 되긴 하는데 설명과 다르다 — 막혀야 하는데 저장된다, 문구·숫자가 틀리다
A24: 오류 | B24: 화면이 멈추거나 깨진다, 눌러도 아무 일이 없다, 오류 창이 뜬다
A25: 보류 | B25: 앞 단계가 안 돼서 지금은 못 한다 — 메모에 이유
A26: 확인 불가 | B26: 이 환경에서는 볼 수 없다 — 예: 확인할 데이터가 없다
A27: 문의 | B27: 맞는지 헷갈린다 — 메모에 궁금한 점
A29: 사진 붙이는 법
A30: • 윈도우: Win + Shift + S → 영역 선택 → 엑셀에서 그 줄의 «사진» 칸을 누르고 Ctrl + V
A31: • 맥: Cmd + Ctrl + Shift + 4 → 영역 선택 → 엑셀에서 그 줄의 «사진» 칸을 누르고 Cmd + V
A32: • 사진이 크면 모서리를 끌어 줄이세요. 사진은 그 줄 «사진» 칸 위에 두면 됩니다 — 취합할 때 줄 번호로 찾습니다.
A33: • 사진은 떠 있는 그대로 두세요(«셀에 배치»로 넣으면 취합할 때 꺼내지 못합니다).
A35: 누구로 — 계정 바꾸는 법
A36: • 화면 오른쪽 위 이름을 누르면 사람 목록이 나옵니다. «누구로» 칸의 이름을 누르면 바뀝니다.
A37: 이름 | B37: 누구 | E37: 주로 하는 것
A38: 박안전 | B38: 재난안전과 담당자 | E38: 대부분 이 계정 — 등록·확인·공문
A39: 하정수 | B39: 물순환사업소 담당자 | E39: 자기 부서 일만 한다
A40: 정환경 | B40: 환경과 담당자 | E40: 남의 부서 것을 못 건드리는지 볼 때
A41: 오순환 | B41: 물순환사업소장 | E41: 자기 부서를 보고 재촉한다
A42: 김중대 | B42: 중대재해팀장 | E42: 공문 결재선(검토)을 볼 때
A43: 홍길동 | B43: 재난안전과장 | E43: 보기만 한다 — 등록 버튼이 없는 게 정상
A44: 김담양 | B44: 군수 | E44: 보기만 한다
A46: 알아 두면 좋은 것 (결함이 아닙니다)
...

Sheet 요약
A1: 진행 상황 — 안전보건교육 · 윤한빛
A2: 결과를 고르면 저절로 채워집니다. 남은 것 = 아직 결과를 고르지 않은 줄입니다.
A4: 시트 | B4: 전체 | C4: 성공 | D4: 실패 | E4: 오류 | F4: 보류 | G4: 확인 불가 | H4: 문의 | I4: 남은 것 | J4: 진행률
A5: 1 근로자 명단 | B5: =COUNTA('1 근로자 명단'!$A$4:$A$12) -> 9 | C5: =COUNTIF('1 근로자 명단'!$G$4:$G$12,"성공") -> 0 | D5: =COUNTIF('1 근로자 명단'!$G$4:$G$12,"실패") -> 0 | E5: =COUNTIF('1 근로자 명단'!$G$4:$G$12,"오류") -> 0 | F5: =COUNTIF('1 근로자 명단'!$G$4:$G$12,"보류") -> 0 | G5: =COUNTIF('1 근로자 명단'!$G$4:$G$12,"확인 불가") -> 0 | H5: =COUNTIF('1 근로자 명단'!$G$4:$G$12,"문의") -> 0 | I5: =COUNTBLANK('1 근로자 명단'!$G$4:$G$12) -> 9 | J5: =IF(B5=0,0,(B5-I5)/B5) -> 0
A6: 2 정기교육(집합) | B6: =COUNTA('2 정기교육(집합)'!$A$4:$A$18) -> 15 | C6: =COUNTIF('2 정기교육(집합)'!$G$4:$G$18,"성공") -> 0 | D6: =COUNTIF('2 정기교육(집합)'!$G$4:$G$18,"실패") -> 0 | E6: =COUNTIF('2 정기교육(집합)'!$G$4:$G$18,"오류") -> 0 | F6: =COUNTIF('2 정기교육(집합)'!$G$4:$G$18,"보류") -> 0 | G6: =COUNTIF('2 정기교육(집합)'!$G$4:$G$18,"확인 불가") -> 0 | H6: =COUNTIF('2 정기교육(집합)'!$G$4:$G$18,"문의") -> 0 | I6: =COUNTBLANK('2 정기교육(집합)'!$G$4:$G$18) -> 15 | J6: =IF(B6=0,0,(B6-I6)/B6) -> 0
A7: 3 자체·채용시·기타 | B7: =COUNTA('3 자체·채용시·기타'!$A$4:$A$17) -> 14 | C7: =COUNTIF('3 자체·채용시·기타'!$G$4:$G$17,"성공") -> 0 | D7: =COUNTIF('3 자체·채용시·기타'!$G$4:$G$17,"실패") -> 0 | E7: =COUNTIF('3 자체·채용시·기타'!$G$4:$G$17,"오류") -> 0 | F7: =COUNTIF('3 자체·채용시·기타'!$G$4:$G$17,"보류") -> 0 | G7: =COUNTIF('3 자체·채용시·기타'!$G$4:$G$17,"확인 불가") -> 0 | H7: =COUNTIF('3 자체·채용시·기타'!$G$4:$G$17,"문의") -> 0 | I7: =COUNTBLANK('3 자체·채용시·기타'!$G$4:$G$17) -> 14 | J7: =IF(B7=0,0,(B7-I7)/B7) -> 0
A8: 4 이수현황 | B8: =COUNTA('4 이수현황'!$A$4:$A$10) -> 7 | C8: =COUNTIF('4 이수현황'!$G$4:$G$10,"성공") -> 0 | D8: =COUNTIF('4 이수현황'!$G$4:$G$10,"실패") -> 0 | E8: =COUNTIF('4 이수현황'!$G$4:$G$10,"오류") -> 0 | F8: =COUNTIF('4 이수현황'!$G$4:$G$10,"보류") -> 0 | G8: =COUNTIF('4 이수현황'!$G$4:$G$10,"확인 불가") -> 0 | H8: =COUNTIF('4 이수현황'!$G$4:$G$10,"문의") -> 0 | I8: =COUNTBLANK('4 이수현황'!$G$4:$G$10) -> 7 | J8: =IF(B8=0,0,(B8-I8)/B8) -> 0
A9: 5 공문·결재 이력 | B9: =COUNTA('5 공문·결재 이력'!$A$4:$A$11) -> 8 | C9: =COUNTIF('5 공문·결재 이력'!$G$4:$G$11,"성공") -> 0 | D9: =COUNTIF('5 공문·결재 이력'!$G$4:$G$11,"실패") -> 0 | E9: =COUNTIF('5 공문·결재 이력'!$G$4:$G$11,"오류") -> 0 | F9: =COUNTIF('5 공문·결재 이력'!$G$4:$G$11,"보류") -> 0 | G9: =COUNTIF('5 공문·결재 이력'!$G$4:$G$11,"확인 불가") -> 0 | H9: =COUNTIF('5 공문·결재 이력'!$G$4:$G$11,"문의") -> 0 | I9: =COUNTBLANK('5 공문·결재 이력'!$G$4:$G$11) -> 8 | J9: =IF(B9=0,0,(B9-I9)/B9) -> 0
A10: 6 계정별 차이 | B10: =COUNTA('6 계정별 차이'!$A$4:$A$8) -> 5 | C10: =COUNTIF('6 계정별 차이'!$G$4:$G$8,"성공") -> 0 | D10: =COUNTIF('6 계정별 차이'!$G$4:$G$8,"실패") -> 0 | E10: =COUNTIF('6 계정별 차이'!$G$4:$G$8,"오류") -> 0 | F10: =COUNTIF('6 계정별 차이'!$G$4:$G$8,"보류") -> 0 | G10: =COUNTIF('6 계정별 차이'!$G$4:$G$8,"확인 불가") -> 0 | H10: =COUNTIF('6 계정별 차이'!$G$4:$G$8,"문의") -> 0 | I10: =COUNTBLANK('6 계정별 차이'!$G$4:$G$8) -> 5 | J10: =IF(B10=0,0,(B10-I10)/B10) -> 0
A11: 합계 | B11: =SUM(B5:B10) -> 58 | C11: =SUM(C5:C10) -> 0 | D11: =SUM(D5:D10) -> 0 | E11: =SUM(E5:E10) -> 0 | F11: =SUM(F5:F10) -> 0 | G11: =SUM(G5:G10) -> 0 | H11: =SUM(H5:H10) -> 0 | I11: =SUM(I5:I10) -> 58 | J11: =IF(B11=0,0,(B11-I11)/B11) -> 0

Sheet 1 근로자 명단
A1: 안전보건교육 — 1 근로자 명단
A2: 🗂 새 탭에서 시작하세요. 1~5번 시트는 이 탭 하나에서 이어서 합니다.
A3: 번호 | B3: 누구로 | C3: 어디서 | D3: 확인할 것 | E3: 해 볼 것 | F3: 이러면 성공 | G3: 결과 ▼ | H3: 메모 (실패·오류·문의일 때) | I3: 사진 (필요할 때 붙여넣기)
A4: 1 | B4: 박안전 | C4: 안전보건교육 > 근로자 명단 관리 | D4: 목록 조건 걸기 | E4: 검색·부서·구분·고용형태 조건을 하나씩 건다 → [필터 초기화] | F4: 조건마다 건수가 바뀌고 초기화하면 전체로 돌아온다
A5: 2 | B5: 박안전 | C5: 안전보건교육 > 근로자 명단 관리 | D5: 근로자 등록 | E5: [＋ 직접 등록] → 이름 QA_근로자01 · 부서 물순환사업소 · 구분 근로자 · 계약직 · 채용일 2026-07-01 · 계약기간 6 → [등록] | F5: «QA_근로자01 근로자 등록 완료»가 뜨고 목록에 보인다
A6: 3 | B6: 박안전 | C6: 안전보건교육 > 근로자 명단 관리 | D6: 빈 칸이면 등록되지 않는다 | E6: 이름 비움 / 채용일 비움 / 계약직인데 계약기간 비움 — 각각 [등록] | F6: 무엇을 넣으라고 알려 주고 등록되지 않는다(«등록 완료»가 뜨면 실패)
A7: 4 | B7: 박안전 | C7: 안전보건교육 > 근로자 명단 관리 | D7: 관리감독자 지정일 넣기 | E7: 관리감독자 줄의 [지정일 등록] → 비우고 저장 → 내일 날짜로 저장 → 2026-07-01 로 저장 | F7: 빈 칸·미래 날짜는 막히고 과거 날짜는 «관리감독자 지정일을 저장했습니다.»
A8: 5 | B8: 하정수 | C8: 안전보건교육 > 근로자 명단 관리 | D8: 지정일은 재난안전과만 넣는다 | E8: ① 관리감독자 줄을 본다 ② 등록 창에서 구분을 관리감독자로 골라 등록한다 | F8: [지정일 등록]이 없고, 관리감독자 등록은 «…재난안전과 담당자에게 요청하세요»로 막힌다
A9: 6 | B9: 하정수 | C9: 안전보건교육 > 근로자 명단 관리 | D9: 부서 담당자의 등록 창 | E9: [＋ 직접 등록]을 연다 | F9: 부서 칸이 물순환사업소로 고정돼 있다
A10: 7 | B10: 박안전 | C10: 안전보건교육 > 근로자 명단 관리 | D10: 이름만 고치기 | E10: QA_근로자01 [수정] → 이름만 바꿔 저장 → 다시 원래대로 | F10: «근로자 정보 저장» — 손대지 않은 계약기간 때문에 막히지 않는다
A11: 8 | B11: 박안전 | C11: 안전보건교육 > 근로자 명단 관리 | D11: 삭제는 한 번 더 묻는다 | E11: 한 명을 더 등록 → 그 사람 [삭제] → 확인 | F11: 확인 창을 거친 뒤 «근로자를 명단에서 제외했습니다.»
A12: 9 | B12: 하정수 | C12: 안전보건교육 > 근로자 명단 관리 | D12: 엑셀 업로드 | E12: [📥 엑셀 업로드] → [업로드] | F12: 창에 «목업» 같은 말이 없고 «예시 계약직 근로자 4명»을 알려 준 뒤 목록이 4명 늘어난다

Sheet 2 정기교육(집합)
A1: 안전보건교육 — 2 정기교육(집합)
A2: 🗂 앞 시트와 같은 탭에서 이어서 하세요. 재난안전과가 집합교육을 만들고 → 부서가 참석자를 내고 → 재난안전과가 종료합니다.
A3: 번호 | B3: 누구로 | C3: 어디서 | D3: 확인할 것 | E3: 해 볼 것 | F3: 이러면 성공 | G3: 결과 ▼ | H3: 메모 (실패·오류·문의일 때) | I3: 사진 (필요할 때 붙여넣기)
A4: 10 | B4: 박안전 | C4: 안전보건교육 > 현업근로자 > 정기교육 | D4: 탭 바꾸기 | E4: [집합교육] ↔ [자체교육(부서)]를 바꾸고 조건을 몇 개 건다 | F4: 오류 없이 바뀌고 조건대로 걸러진다
A5: 11 | B5: 하정수 → 홍길동 | C5: 안전보건교육 > 현업근로자 > 정기교육 | D5: 집합교육은 재난안전과만 만든다 | E5: 집합교육 탭을 본다 | F5: 하정수에게 [＋ 집합교육 등록]이 없고 «…재난안전과 담당자가 등록합니다»가 보인다. 홍길동은 조회 전용
A6: 12 | B6: 박안전 | C6: 안전보건교육 > 현업근로자 > 정기교육 | D6: 집합교육 등록 | E6: [＋ 집합교육 등록] → 빈 채로 [등록] → 내용 QA_정기교육_집합 · 2026-07-20 14:00~16:00 · 강사 · 장소 → [등록] | F6: 빈 채로는 «교육 내용을 입력하세요.» 등록하면 카드가 생기고 교육시간이 2h로 계산된다
A7: 13 | B7: 박안전 | C7: 안전보건교육 > 현업근로자 > 정기교육 | D7: 여러 날 교육 | E7: 등록 창에서 ① 날짜를 5개까지 추가하고 한 번 더 ② 한 날의 끝 시각을 시작보다 이르게 ③ 고쳐서 2일짜리로 등록 | F7: «최대 5일까지» 안내가 뜨고 끝이 시작보다 이르면 막힌다. 카드에 «…외 1일», 시간은 두 날의 합
A8: 14 | B8: 박안전 | C8: 안전보건교육 > 현업근로자 > 정기교육 | D8: 집합교육 첨부 칸 | E8: 등록 창의 첨부 영역을 본다 | F8: «참석자 명단 · 교육 자료» 두 칸이 있고 교육 사진 칸은 없다
A9: 15 | B9: 박안전 | C9: 안전보건교육 > 현업근로자 > 정기교육 | D9: 기존 교육을 그대로 저장 | E9: «2026년 8월 정기 안전보건교육» [수정] → 아무것도 안 바꾸고 [저장] | F9: 끝 시각 17:00이 채워져 있고 «교육 정보를 저장했습니다 · 교육시간 3h»가 뜬다(저장이 막히면 실패)
A10: 16 | B10: 하정수 | C10: 안전보건교육 > 현업근로자 > 정기교육 | D10: 참석자 등록부 내기 | E10: 위 12번 교육 상세 → [＋ 참석자 등록부 등록] → ① 아무도 안 고르고 ② 2명 고르고 서명파일 없이 ③ 서명파일을 넣고 참석시간 3 → 2로 고쳐 [신청 완료] | F10: 빈 것마다 막히고, 마지막에 «물순환사업소 · 2명 신청 완료». 부서는 물순환사업소로 고정
A11: 17 | B11: 하정수 | C11: 안전보건교육 > 현업근로자 > 정기교육 | D11: 같은 부서는 두 번 못 낸다 | E11: 같은 교육에 다시 등록부를 낸다 | F11: «…이미 등록된 부서입니다 — 신청 취소 후 다시 등록하세요.»
A12: 18 | B12: 정환경 | C12: 안전보건교육 > 현업근로자 > 정기교육 | D12: 다른 부서 담당자 | E12: 같은 교육 상세 → 환경과로 1명 신청 → 물순환사업소 줄을 본다 | F12: 환경과로 신청된다. 물순환사업소 줄에는 [등록 취소]가 없다
A13: 19 | B13: 하정수 | C13: 안전보건교육 > 현업근로자 > 정기교육 | D13: 등록 취소하고 다시 내기 | E13: 자기 부서 줄 [등록 취소] → 확인 → 다시 2명 신청 | F13: «신청 내역과 서명파일이 삭제됩니다»를 확인한 뒤 줄어들고, 다시 신청된다
A14: 20 | B14: 박안전 | C14: 안전보건교육 > 현업근로자 > 정기교육 | D14: 교육 종료 처리 | E14: 위 12번 교육 상세 → [교육 종료 처리] → 확인 | F14: 창이 신청 부서·인원을 알려 주고 «교육 종료 · N명 카운트 완료», 상태가 완료로 바뀐다
A15: 21 | B15: 하정수 → 홍길동 | C15: 안전보건교육 > 현업근로자 > 정기교육 | D15: 종료 처리는 재난안전과만 | E15: 진행 중인 다른 집합교육 상세를 본다 | F15: [교육 종료 처리]가 없다
... A18: 24 | B18: 박안전 | C18: 안전보건교육 > 현업근로자 > 정기교육 | D18: 삭제는 지울 건수를 알려 준다 | E18: 집합교육을 하나 더 만들고 → 그 교육 [삭제] → 확인 창을 본다 | F18: 확인 창이 지워질 신청·이수기록 건수를 알려 주고 지운다

Sheet 3 자체·채용시·기타
A1: 안전보건교육 — 3 자체·채용시·기타
A2: 🗂 앞 시트와 같은 탭에서 이어서 하세요.
A3: 번호 | B3: 누구로 | C3: 어디서 | D3: 확인할 것 | E3: 해 볼 것 | F3: 이러면 성공 | G3: 결과 ▼ | H3: 메모 (실패·오류·문의일 때) | I3: 사진 (필요할 때 붙여넣기)
A4: 25 | B4: 하정수 | C4: 안전보건교육 > 현업근로자 > 정기교육 | D4: 자체교육 등록 | E4: [자체교육(부서)] → [＋ 자체교육 등록·진행] → 대상자 없이 → 내용 없이 → 다 채워서(QA_정기교육_자체, 대상자 2명, 증빙) 저장 | F4: 빈 칸이면 막히고 저장하면 목록에 생긴다. 부서는 물순환사업소로 고정
A5: 26 | B5: 하정수 | C5: 안전보건교육 > 현업근로자 > 정기교육 | D5: 자체교육 첨부 칸 | E5: 등록 창의 첨부 영역을 본다 | F5: «교육일지 및 교육사진 등» 한 칸이다
A6: 27 | B6: 박안전 | C6: 안전보건교육 > 현업근로자 > 채용시교육 | D6: 탭과 새 근로자 | E6: [전체] · [미이수] · [이수] 탭을 본다 | F6: 탭이 셋이고(«교육 건» 탭 없음) QA_근로자01이 미이수에 있다
A7: 28 | B7: 박안전 | C7: 안전보건교육 > 현업근로자 > 채용시교육 | D7: 필요 시간 | E7: 목록의 필요시간을 본다 | F7: 고용형태·계약기간대로 1h · 4h · 8h이고 상태가 미이수 · 정상 이수 · 지연 이수 · 판정 불가로 나뉜다
A8: 29 | B8: 박안전 | C8: 안전보건교육 > 현업근로자 > 채용시교육 | D8: 채용시 교육 추가 | E8: [＋ 채용시 교육 추가] → 대상자 없이 → QA_근로자01만 고르고 증빙 없이 → 증빙 넣고 [교육기록 등록] | F8: 빈 칸이면 막히고, 등록하면 «1명 교육기록 등록…» 후 이수 탭으로 옮겨 간다
A9: 30 | B9: 박안전 | C9: 안전보건교육 > 현업근로자 > 채용시교육 | D9: 여러 명 한 번에 | E9: 미이수 2명 체크 → [선택 교육기록 등록] → 교육일 없이 → 증빙 없이 → 채워서 | F9: 빈 칸이면 막히고, 등록하면 «2명 소급 교육기록 등록…»
A10: 31 | B10: 박안전 | C10: 안전보건교육 > 현업근로자 > 채용시교육 | D10: 이수 수정·되돌리기 | E10: 29번 이수자 [이수 수정] → 날짜 바꿔 저장 → 다시 [이수 수정] → [이수 기록 삭제] → [이수 취소] | F10: «이수일을 수정했습니다 — 날짜», 삭제하면 «이수기록 N건 회수 · 미이수로 되돌렸습니다»
A11: 32 | B11: 하정수 | C11: 안전보건교육 > 현업근로자 > 채용시교육 | D11: 자기 부서만 보인다 | E11: 목록과 부서 조건을 본다 | F11: 물순환사업소 사람만 보이고 부서 조건에도 물순환사업소만 있다
A12: 33 | B12: 박안전 | C12: 안전보건교육 > 관리감독자 > 채용시교육 | D12: 지정일이 없으면 판정하지 않는다 | E12: 목록을 본다 | F12: 지정일 없는 사람은 «판정 불가»이고 미이수·이수 어느 탭에도 없다. «전체 = 미이수 + 이수 + 판정 불가» 안내가 있고, 4번에서 지정일을 넣은 사람만 판정된다
A13: 34 | B13: 박안전 | C13: 안전보건교육 > 현업근로자 > 기타 교육 | D13: 기타 교육 등록 | E13: [＋ 기타 교육 등록·진행] → 빈 채로 [진행 처리] → 유형 «작업내용 변경 시» → 대상자 없이 → 다 채우고 시간 0.5 | F13: 빈 칸이면 막힌다. 유형을 고르면 법정 최소 시간과 근거가 보이고, 모자라도 등록되며 «법정 최소 미달 N명»이 뜬다
A14: 35 | B14: 박안전 | C14: 안전보건교육 > 현업근로자 > 기타 교육 | D14: 특별교육 대상 작업 | E14: 유형 «특별교육» → 대상 작업 없이 진행 → 두 개 고르기 → «기타 — 법령 매핑 대기»를 내용 없이 진행 | F14: 대상 작업이 없으면 막히고 여러 개 고를 수 있다. «기타»는 내용을 적어야 저장된다
A15: 36 | B15: 박안전 | C15: 안전보건교육 > 관리감독자 > 기타 교육 | D15: 관리감독자 유형은 다르다 | E15: 등록 창의 유형 목록을 현업근로자 쪽과 비교한다 | F15: «건설업 기초»가 없고 작업내용 변경 2h · 특별교육 16h 한 가지 기준이다
... A17: 38 | B17: 박안전 | C17: 안전보건교육 > 관리감독자 > 정기교육 | D17: 관리감독자 정기교육 | E17: 등록 창의 대상자 목록을 본다 | F17: 관리감독자만 대상자로 나온다

Sheet 4 이수현황
A1: 안전보건교육 — 4 이수현황
A2: 🗂 앞 시트와 같은 탭에서 이어서 하세요. 2·3번 시트에서 끝낸 교육이 여기 모입니다.
A3: 번호 | B3: 누구로 | C3: 어디서 | D3: 확인할 것 | E3: 해 볼 것 | F3: 이러면 성공 | G3: 결과 ▼ | H3: 메모 (실패·오류·문의일 때) | I3: 사진 (필요할 때 붙여넣기)
A4: 39 | B4: 박안전 | C4: 안전보건교육 > 이수현황 | D4: 부서별 요약과 상세 | E4: 물순환사업소 줄 [상세] | F4: 대상·완료 인원과 완료율이 상세 목록과 맞다
A5: 40 | B5: 박안전 | C5: 안전보건교육 > 이수현황 | D5: 대상 없는 부서 | E5: 대상이 0명인 부서를 찾는다 | F5: 0%가 아니라 «대상 없음»으로 보인다(그런 부서가 없으면 «확인 불가»)
A6: 41 | B6: 박안전 | C6: 안전보건교육 > 이수현황 | D6: 시간 계산 | E6: 집합(20번)과 자체(25번)를 모두 들은 사람의 필요·인정·미달을 본다 | F6: 인정 = 집합 + 자체, 미달 = 필요 − 인정이고 음수가 없다
A7: 42 | B7: 박안전 | C7: 안전보건교육 > 이수현황 | D7: 여러 조건 | E7: 부서·구분·고용형태·이수 상태를 함께 건다 → [필터 초기화] | F7: 조건대로 걸러지고 초기화하면 전체로 돌아온다
A8: 43 | B8: 하정수 | C8: 안전보건교육 > 이수현황 | D8: 남의 부서 상세는 못 본다 | E8: 부서별 요약을 본다 | F8: 자기 부서 줄에만 [상세]가 있고 다른 줄은 «—»다(버튼이 있는데 누르면 거절되면 실패)
A9: 44 | B9: 박안전 | C9: 안전보건교육 > 이수현황 | D9: 독촉 | E9: 체크 없이 [일괄 독촉] → 2명 체크 → [일괄 독촉 (2)] → [독촉 발송] → [📜 독촉 이력] | F9: 체크가 없으면 막힌다. 발송하면 «…2명 독촉 알림 기록 완료 (실제 문자·메일 미발송)» 후 이력에 남는다
A10: 45 | B10: 박안전 | C10: 안전보건교육 > 이수현황 | D10: 이수 확인서 | E10: 완료한 사람의 확인서 [발급] | F10: 보고서·제증명 화면이 그 사람으로 채워져 열린다

Sheet 5 공문·결재 이력
A1: 안전보건교육 — 5 공문·결재 이력
A2: 🗂 앞 시트와 같은 탭에서 이어서 하세요. 교육 공문은 결재 결과를 받지 않습니다 — 상태는 «결재중» 하나입니다.
A3: 번호 | B3: 누구로 | C3: 어디서 | D3: 확인할 것 | E3: 해 볼 것 | F3: 이러면 성공 | G3: 결과 ▼ | H3: 메모 (실패·오류·문의일 때) | I3: 사진 (필요할 때 붙여넣기)
A4: 46 | B4: 박안전 | C4: 안전보건교육 > 현업근로자 > 정기교육 | D4: 끝난 교육만 공문을 쓴다 | E4: 진행 중인 교육과 20번(종료) 교육의 [공문 기안]을 본다 | F4: 진행 중인 교육은 «교육 종료 처리 후에 기안할 수 있습니다.», 종료된 교육은 기안된다
A5: 47 | B5: 박안전 | C5: 안전보건교육 > 현업근로자 > 정기교육 | D5: 공문 쓰기 → 미리보기 → 상신 | E5: 20번 교육 [공문 기안] → 제목을 지우고 미리보기 → 본문 없이 미리보기 → 본문 쓰기(칩 사용)·붙임 고르기 → [문서 미리보기 →] → [온나라로 결재 상신] → [상신] | F5: 제목·본문이 없으면 막힌다. 기안 화면에 상신 버튼이 없고 붙임은 올려 둔 파일에서만 고른다. 상신하면 문서번호가 붙고 «결재중»
A6: 48 | B6: 박안전 | C6: 안전보건교육 > 현업근로자 > 정기교육 | D6: 결재선 | E6: 검토·결재에 같은 사람을 넣어 본다 → 기안자 본인을 넣어 본다 → 검토 칸을 비우고 상신해 본다 | F6: 고를 수 없게 흐리게 보이고, 칸이 비면 상신이 막힌다
A7: 49 | B7: 박안전 | C7: 안전보건교육 > 현업근로자 > 정기교육 | D7: 상신 뒤에는 잠긴다 | E7: 그 교육 [수정]·[삭제] → 상세의 [등록 취소] | F7: 셋 다 잠겨 있다(등록 취소까지 잠겨야 성공)
A8: 50 | B8: 박안전 | C8: 안전보건교육 > 현업근로자 > 정기교육 | D8: 잠금 안내 문구 | E8: 49번에서 뜬 안내를 읽는다 | F8: 잠긴 이유(결재중)를 말하고, 이 시스템에서 할 수 없는 일(«반려 후 다시 시도»)을 권하지 않는다
A9: 51 | B9: 하정수 → 홍길동 | C9: 안전보건교육 > 현업근로자 > 정기교육 | D9: 공문은 교육을 등록한 부서가 쓴다 | E9: 하정수: 25번 자체교육과 재난안전과 집합교육의 [공문 기안]을 본다 / 홍길동: 같은 화면 | F9: 하정수는 자기 부서 교육만 기안하고 나머지는 누가 기안하는지 안내된다. 홍길동에게는 기안 버튼이 없다
A10: 52 | B10: 박안전 | C10: 안전보건교육 > 현업근로자 > 채용시교육 | D10: 채용시교육 공문 | E10: 이수 줄에서 공문으로 가는 연결을 본다 | F10: 그 사람이 들은 교육 건의 [공문 기안]으로 간다
A11: 53 | B11: 박안전 | C11: 안전보건교육 > 결재 이력 | D11: 결재 이력 | E11: 목록 → 조건 → 문서를 연다 | F11: 47번 공문이 문서번호와 함께 있고 열린다. 승인·반려 버튼은 없고 «온나라에서 문서번호로 확인» 안내가 있다

Sheet 6 계정별 차이
A1: 안전보건교육 — 6 계정별 차이
A2: 🗂 5번 시트까지 쓰던 탭에서 계정만 바꿔 가며 보세요. 58번(단계별 안내)만 새 탭에서 합니다.
A3: 번호 | B3: 누구로 | C3: 어디서 | D3: 확인할 것 | E3: 해 볼 것 | F3: 이러면 성공 | G3: 결과 ▼ | H3: 메모 (실패·오류·문의일 때) | I3: 사진 (필요할 때 붙여넣기)
A4: 54 | B4: 김담양 | C4: 안전보건교육 (9개 화면 전부) | D4: 군수는 보기만 | E4: 교육 메뉴 9개를 차례로 연다 | F4: 등록·수정·삭제·종료·공문 버튼이 하나도 없고 화면 오류가 없다
A5: 55 | B5: 홍길동 | C5: 안전보건교육 (현업근로자 3개 화면) | D5: 과장은 보기만 | E5: 정기교육·채용시교육·기타 교육을 연다 | F5: 등록·종료·공문 버튼이 없고 조회 전용 안내가 보인다
A6: 56 | B6: 하정수 | C6: 안전보건교육 (등록 창) | D6: 부서 칸 고정 | E6: 자체교육·기타 교육·채용시 교육 추가 창을 차례로 연다 | F6: 부서가 물순환사업소로 고정돼 있다
A7: 57 | B7: 하정수 | C7: 대시보드 > 내 할일 | D7: 교육 할 일 카드 | E7: «…참석자 등록부 등록 필요» 카드를 누른다 | F7: 목록이 아니라 그 교육의 상세로 바로 간다
A8: 58 | B8: 박안전 | C8: 안전보건교육 > 현업근로자 > 정기교육 | D8: 단계별 안내 | E8: 새 탭 → «단계별 안내 시작» → 끝까지 따라간다 | F8: 단계마다 눌러야 할 버튼을 짚고 처리하면 다음 단계로 넘어간다

Sheet _정보
A1: 형식 | B1: QA엑셀 v1.1
A2: 메뉴 | B2: 안전보건교육
A3: 담당자 | B3: 윤한빛
A4: 파일 코드 | B4: ED
A5: 종류 | B5: 상세
A6: 생성일 | B6: 2026-09-28
A7: 결과 값 | B7: 성공,실패,오류,보류,확인 불가,문의
A8: 머리 행 | B8: 3
A9: 열 | B9: 번호,누구로,어디서,확인할,해,이러면,결과,메모,사진
